Workbook

Sheet ReadMe
A1: ACRME aligned placement what-if
A2: Mock planning workbook. Figures are synthetic. Nothing here is live Azure state.
A4: What you do
A5: 1. On Request, set Geography and Customer ID. Enter up to 8 SKU lines (SKU and VM count).
A6: 2. Prod region is the normal input (PLC-001). Type a region id, including a Restricted region when the customer named it.
A7: 3. Leave Prod region blank only when Geography-only selection is an approved exception (PLC-002). Set that flag to Y.
A8: 4. Set DR offered to N to record DR_NOT_OFFERED for this customer (DR-014).
A9: 5. Read Calculations for the formulas behind region selection and the availability gates.
A10: 6. Read Allocation. If the placement is READY or READY_WITH_RISK, Post_Allocation and Quota_After show the estate after that placement.
A12: How a region is chosen
A13: Order is Prod, then CVAL, then DR. A region that fails a hard gate is not scored.
A14: US (3-region): Prod, CVAL, and DR are three different Standard regions, unless that geography's co-host flag is Y.
... A53: Per-AZ capacity reservation groups (only crg-…-reg). Zone rebalancing beyond the even-share target on Allocation. Associated-but-deallocated VMs. A multi-customer MAX-not-SUM DR index. STALE_STATE and VALIDATION_REQUIRED (this file is the snapshot). A persisted seed store — Allocation displays the seed, it does not write one.

Sheet Calculations
A1: How region selection and availability checks are calculated
A2: This sheet is the formula guide for the workbook. Yellow is not used here. Column D repeats the current request so the numbers move when Request or Policy changes. Score_Prod, Score_CVAL, and Score_DR are where each region is judged. Allocation copies rank 1.
A4: This request
A5: Geography | B5: =Request!B4
A6: Model | B6: =Request!B9 | D6: From Policy. Co-host does not change this text.
A7: Co-host DR with CVAL | B7: =Request!B11 | D7: Y forces DR onto the CVAL region when the model is not cross-geo.
A8: DR offered | B8: =Request!B8 | D8: N records NOT_OFFERED and adds no DR cores.
A9: Bootstrap fraction | B9: =Policy!B15 | D9: DR need = ROUND(line cores × this, 0).
A10: HC-2 multiplier | B10: =Policy!B13 | D10: Reserved-free must cover multiplier × need.
A11: HC-3 quota floor | B11: =Policy!B14 | D11: Cores that must remain after the line is placed.
A12: α risk threshold | B12: =Policy!B12 | D12: Eligible and below this α is READY_WITH_RISK.
A13: Weight sum | B13: =Policy!B9 | D13: Must be 1.00 or the run is POLICY_BLOCKED.
A15: Environment | B15: Region chosen | C15: Placement score | D15: Readiness
A16: =Allocation!A9 | B16: =Allocation!D9&" ("&Allocation!C9&")" | C16: =Allocation!E9 | D16: =Allocation!F9
A17: =Allocation!A10 | B17: =Allocation!D10&" ("&Allocation!C10&")" | C17: =Allocation!E10 | D17: =Allocation!F10
A18: =Allocation!A11 | B18: =Allocation!D11&" ("&Allocation!C11&")" | C18: =Allocation!E11 | D18: =Allocation!F11
A20: Order is Prod, then CVAL, then DR. CVAL is scored only after Prod is a real region. DR is scored only after CVAL is a real region and DR is offered. A region that is not a candidate, or that fails a gate, does not receive a placement score.
A22: 1. What each SKU line needs
A23: Request rows 13–20. A line is active only when both the SKU and the VM count are filled. Duplicate SKUs make the run POLICY_BLOCKED. Blank rows are ignored: they contribute 1 to every MIN, so they cannot fail a region or pull a score down.
A24: Quantity | B24: Formula | C24: Prod and CVAL | D24: DR
A25: Cores | B25: VM count × vCPU from SKU_Catalogue | C25: Full cores | D25: Full cores are still stored; the gate uses the bootstrap
A26: Need | B26: Cores the environment must cover | C26: Cores | D26: ROUND(cores × bootstrap, 0)
A27: Reserved | B27: Capacity_Reservations reserved quantity for that region, environment, and SKU | C27: Prod row | D27: DR row
A28: Reserved-free | B28: Reserved − allocated, on that same row | C28: Must cover the need | D28: Must cover the bootstrap need
A30: 2. Availability numbers on Line_Check
A31: Line_Check has one row per catalogue region. Each active SKU line adds reserved-free, reserved, and quota columns. The score sheets read those columns. Group availability for a line is the minimum of reserved-free and the quota number for that environment.
A32: Number | B32: How it is calculated | C32: Used by | D32: Fails when
A33: Family available | B33: Quota_Groups Available for this region and this VM family. One cell covers Prod, NonProd, and DR. | C33: Part of quota available | D33: The family cell cannot take the line
A34: Regional vCPU available | B34: Quota_Groups column P on the region's Eadsv5 row. That is the total regional vCPU cap (QUA-002). | C34: Part of quota available | D34: The regional total is tighter than the family cell
A35: Quota available | B35: MIN(family available, regional vCPU available). | C35: HC-3, and Meets-all for Prod and DR | D35: The lesser of the two caps is short
A36: NonProd headroom | B36: Family limit − Prod earmark − DR earmark − NonProd used. Earmarks are reserved cores, so CVAL cannot spend Prod or DR quota (HC-7). | C36: HC-7, and Meets-all for CVAL | D36: Headroom after the earmarks is short
A38: 3. Which regions are allowed to compete
A39: Candidate = 1 on the score sheet (column J) before any capacity check. Candidate = 0 is not scored.
A40: Environment | B40: Who is a candidate | C40: Named Prod region | D40: Restricted regions
A41: Prod | B41: If Request Prod region is blank and the geography-only exception is Y: every Standard region in the geography. | C41: If a Prod region id is entered: only that region, and it must sit in the requested geography. | D41: A Restricted region competes for Prod only when Request names it.
A42: CVAL | B42: Standard regions in the geography other than Prod. Cross-geo (Middle East): the Prod region itself, on a separate reservation. | C42: Follows the Prod winner. It does not re-read the Prod region box. | D42: Never a CVAL candidate.
A43: DR | B43: 3-region: a Standard region that is neither Prod nor CVAL. 2-region, or co-host = Y: the CVAL region only. Cross-geo: Standard regions in the DR scope (Europe). | C43: Requires DR offered = Y and a real CVAL winner. | D43: Never a DR candidate.
A45: 4. Availability gates
A46: Every active line must pass. One short SKU fails the region. PASS or N/A is a pass. Eligible (column T) = 1 only when Candidate = 1 and columns K through S all pass. The same column letters are used on Score_Prod, Score_CVAL, and Score_DR.
A47: Column | B47: Gate | C47: Rule | D47: Where it applies
...

Sheet Request
A1: Deployment request
A2: Yellow cells are the only inputs. One row per SKU. Both SKU and VM count are required for a line to count.
A4: Geography | B4: US | C4: US, EU, Australia, Asia Pacific, or Middle East
A5: Customer ID | B5: CUST-1008
A6: Prod region id (blank = do not auto-pick) | C6: PLC-001. Restricted ids are allowed here: eastus2, northeurope, westeurope.
A7: Geography-only exception approved (Y/N) | B7: Y | C7: PLC-002. Must be Y when Prod region is blank. Ignored when a Prod region is named.
A8: DR offered (Y/N) | B8: Y | C8: N writes DR_NOT_OFFERED and does not reserve DR cores.
A9: Distribution model | B9: =IF(B4="","",VLOOKUP(B4,Policy!D5:F9,2,FALSE))
A10: DR scope geography | B10: =IF(B4="","",VLOOKUP(B4,Policy!D5:F9,3,FALSE))
A11: Co-host DR with CVAL | B11: =IF(B4="","",VLOOKUP(B4,Policy!D5:G9,4,FALSE)) | C11: From Policy column G. Y does not change B9. Cross-geo ignores it.
A12: SKU | B12: VM count | C12: vCPU / VM | D12: Line cores | E12: Quota family | F12: Active | G12: Duplicate
A13: Standard_E32ads_v5 | B13: 4 | C13: =IF(A13="","",VLOOKUP(A13,SKU_Catalogue!A$5:C$12,2,FALSE)) | D13: =IF(OR(A13="",NOT(ISNUMBER(B13)),B13<=0),"",B13*C13) | E13: =IF(A13="","",VLOOKUP(A13,SKU_Catalogue!A$5:C$12,3,FALSE)) | F13: =IF(AND(A13<>"",ISNUMBER(B13),B13>0),1,0) | G13: =IF(A13="",0,IF(COUNTIF($A$13:$A$20,A13)>1,1,0))
A14: Standard_D8as_v5 | B14: 2 | C14: =IF(A14="","",VLOOKUP(A14,SKU_Catalogue!A$5:C$12,2,FALSE)) | D14: =IF(OR(A14="",NOT(ISNUMBER(B14)),B14<=0),"",B14*C14) | E14: =IF(A14="","",VLOOKUP(A14,SKU_Catalogue!A$5:C$12,3,FALSE)) | F14: =IF(AND(A14<>"",ISNUMBER(B14),B14>0),1,0) | G14: =IF(A14="",0,IF(COUNTIF($A$13:$A$20,A14)>1,1,0))
C15: =IF(A15="","",VLOOKUP(A15,SKU_Catalogue!A$5:C$12,2,FALSE)) | D15: =IF(OR(A15="",NOT(ISNUMBER(B15)),B15<=0),"",B15*C15) | E15: =IF(A15="","",VLOOKUP(A15,SKU_Catalogue!A$5:C$12,3,FALSE)) | F15: =IF(AND(A15<>"",ISNUMBER(B15),B15>0),1,0) | G15: =IF(A15="",0,IF(COUNTIF($A$13:$A$20,A15)>1,1,0))
C16: =IF(A16="","",VLOOKUP(A16,SKU_Catalogue!A$5:C$12,2,FALSE)) | D16: =IF(OR(A16="",NOT(ISNUMBER(B16)),B16<=0),"",B16*C16) | E16: =IF(A16="","",VLOOKUP(A16,SKU_Catalogue!A$5:C$12,3,FALSE)) | F16: =IF(AND(A16<>"",ISNUMBER(B16),B16>0),1,0) | G16: =IF(A16="",0,IF(COUNTIF($A$13:$A$20,A16)>1,1,0))
C17: =IF(A17="","",VLOOKUP(A17,SKU_Catalogue!A$5:C$12,2,FALSE)) | D17: =IF(OR(A17="",NOT(ISNUMBER(B17)),B17<=0),"",B17*C17) | E17: =IF(A17="","",VLOOKUP(A17,SKU_Catalogue!A$5:C$12,3,FALSE)) | F17: =IF(AND(A17<>"",ISNUMBER(B17),B17>0),1,0) | G17: =IF(A17="",0,IF(COUNTIF($A$13:$A$20,A17)>1,1,0))
C18: =IF(A18="","",VLOOKUP(A18,SKU_Catalogue!A$5:C$12,2,FALSE)) | D18: =IF(OR(A18="",NOT(ISNUMBER(B18)),B18<=0),"",B18*C18) | E18: =IF(A18="","",VLOOKUP(A18,SKU_Catalogue!A$5:C$12,3,FALSE)) | F18: =IF(AND(A18<>"",ISNUMBER(B18),B18>0),1,0) | G18: =IF(A18="",0,IF(COUNTIF($A$13:$A$20,A18)>1,1,0))
C19: =IF(A19="","",VLOOKUP(A19,SKU_Catalogue!A$5:C$12,2,FALSE)) | D19: =IF(OR(A19="",NOT(ISNUMBER(B19)),B19<=0),"",B19*C19) | E19: =IF(A19="","",VLOOKUP(A19,SKU_Catalogue!A$5:C$12,3,FALSE)) | F19: =IF(AND(A19<>"",ISNUMBER(B19),B19>0),1,0) | G19: =IF(A19="",0,IF(COUNTIF($A$13:$A$20,A19)>1,1,0))
C20: =IF(A20="","",VLOOKUP(A20,SKU_Catalogue!A$5:C$12,2,FALSE)) | D20: =IF(OR(A20="",NOT(ISNUMBER(B20)),B20<=0),"",B20*C20) | E20: =IF(A20="","",VLOOKUP(A20,SKU_Catalogue!A$5:C$12,3,FALSE)) | F20: =IF(AND(A20<>"",ISNUMBER(B20),B20>0),1,0) | G20: =IF(A20="",0,IF(COUNTIF($A$13:$A$20,A20)>1,1,0))
A22: Active SKU lines | B22: =SUM(F13:F20)
A23: Total requested cores | B23: =SUM(D13:D20)
A24: SKU uniqueness | B24: =IF(SUM(G13:G20)>0,"DUPLICATE SKU","OK")
A25: DR bootstrap cores (all lines) | B25: =IF(B8<>"Y",0,ROUND(B23*Policy!B15,0))
A27: Prod path | B27: =IF(B22=0,"Enter at least one SKU line",IF(Policy!B10<>"OK","Weights must sum to 1",IF(B24<>"OK","Remove duplicate SKUs",IF(B6<>"","Validate the named Prod region",IF(B7="Y","Exception path: score Standard regions in this geography","Blocked: name a Prod region or approve the geography exception")))))

Sheet Policy
A1: Placement policy
A2: Yellow cells are inputs. The score is invalid unless the five weights sum to 1.00.
D3: Geography model (REG-003)
A4: α capacity headroom | B4: 0.3 | D4: Geography | E4: Model | F4: DR scope | G4: Co-host DR with CVAL
A5: β quota headroom | B5: 0.2 | D5: US | E5: 3-region | F5: US | G5: N
A6: γ distribution fairness | B6: 0.25 | D6: EU | E6: 2-region | F6: EU | G6: Y
A7: δ DR readiness | B7: 0.15 | D7: Australia | E7: 2-region | F7: Australia | G7: Y
A8: ε zone diversity | B8: 0.1 | D8: Asia Pacific | E8: 2-region | F8: Asia Pacific | G8: Y
A9: Weight sum | B9: =SUM(B4:B8) | D9: Middle East | E9: cross-geo | F9: EU | G9: N
A10: Weight check | B10: =IF(ABS(B9-1)<0.001,"OK","INVALID")
D11: Middle East DR scope is EU. CVAL co-locates with Prod. The co-host column does not apply to cross-geo: DR stays in Europe.
A12: Risk threshold (α below this is READY_WITH_RISK) | B12: 0.1 | D12: Co-host Y places DR on the CVAL region without changing the Model column. HC-6 still runs only for a 2-region model. Other hard gates still apply to that DR region.
A13: HC-2 capacity-floor multiplier | B13: 1
A14: HC-3 minimum quota left after the placement (cores) | B14: 20
A15: DR bootstrap fraction of requested cores (DR-007) | B15: 0.1
A16: Policy version | B16: v2.4-aligned-mock
A17: total_customers source | B17: Live geography count (PLC-012); γ = 1 when zero
A18: δ DR divides the region's coverage ratio by the bootstrap fraction in B15, then clamps to 1.
A19: HC-2 reference multiplier in the hard-constraint note is 2. B13 ships at 1 so the sample request fits the mock estate.

Sheet Region_Catalogue
A1: In-scope region catalogue — baseline v2.4 Section 6
A2: Class and model are the baseline, not the earlier what-if promotion of Restricted regions.
A4: Region | B4: Region id | C4: Geography | D4: AZ | E4: Model | F4: DR scope | G4: Class | H4: Customers | I4: DR coverage | J4: Note
A5: West US 3 | B5: westus3 | C5: US | D5: 3 | E5: 3-region | F5: US | G5: Standard | H5: 40 | I5: 0.5 | J5: Synthetic estate
A6: Central US | B6: centralus | C6: US | D6: 3 | E6: 3-region | F6: US | G6: Standard | H6: 25 | I6: 0.45 | J6: Synthetic estate
A7: Canada Central | B7: canadacentral | C7: US | D7: 3 | E7: 3-region | F7: US | G7: Standard | H7: 12 | I7: 0.6 | J7: Synthetic — region is in the catalogue but not in the local usage extracts
A8: East US 2 | B8: eastus2 | C8: US | D8: 3 | E8: 3-region | F8: US | G8: Restricted | H8: 18 | I8: 0.4 | J8: Restricted — explicit Prod region only (Section 6)
A9: Switzerland North | B9: switzerlandnorth | C9: EU | D9: 3 | E9: 2-region | F9: EU | G9: Standard | H9: 22 | I9: 0.5 | J9: Synthetic estate
A10: Sweden Central | B10: swedencentral | C10: EU | D10: 3 | E10: 2-region | F10: EU | G10: Standard | H10: 15 | I10: 0.58 | J10: Synthetic estate
A11: North Europe | B11: northeurope | C11: EU | D11: 3 | E11: 2-region | F11: EU | G11: Restricted | H11: 10 | I11: 0.35 | J11: Restricted — explicit Prod region only
A12: West Europe | B12: westeurope | C12: EU | D12: 3 | E12: 2-region | F12: EU | G12: Restricted | H12: 20 | I12: 0.42 | J12: Restricted — explicit Prod region only
A13: Australia East | B13: australiaeast | C13: Australia | D13: 3 | E13: 2-region | F13: Australia | G13: Standard | H13: 14 | I13: 0.48 | J13: Synthetic estate
A14: Australia Southeast | B14: australiasoutheast | C14: Australia | D14: 2 | E14: 2-region | F14: Australia | G14: Standard | H14: 8 | I14: 0.52 | J14: 2 availability zones — ε = 2/3
A15: East Asia | B15: eastasia | C15: Asia Pacific | D15: 3 | E15: 2-region | F15: Asia Pacific | G15: Standard | H15: 11 | I15: 0.44 | J15: Synthetic estate. Japan East is not in the catalogue.
A16: Southeast Asia | B16: southeastasia | C16: Asia Pacific | D16: 3 | E16: 2-region | F16: Asia Pacific | G16: Standard | H16: 16 | I16: 0.5 | J16: Synthetic estate
... A18: UAE North | B18: uaenorth | C18: Middle East | D18: 3 | E18: cross-geo | F18: EU | G18: Standard | H18: 6 | I18: 0 | J18: Synthetic. Local DR is 0 — DR is placed in Europe (DR-020).

Sheet SKU_Catalogue
A1: Managed SKU catalogue
A2: Family names follow the Azure VM size (Eadsv5, Eadsv6, Dadsv5, Dasv5). Eight SKUs, several per family, so quota is shared.
A4: SKU | B4: vCPU / VM | C4: Quota family | D4: Zonal reservation | E4: Note
A5: Standard_E32ads_v5 | B5: 32 | C5: Eadsv5 | D5: Yes | E5: Seed-matrix member. Count starts from the mock estate, not from zero.
A6: Standard_E64ads_v5 | B6: 64 | C6: Eadsv5 | D6: Yes | E6: Seed-matrix member. Count starts from the mock estate, not from zero.
A7: Standard_E16ads_v5 | B7: 16 | C7: Eadsv5 | D7: Yes | E7: Seed-matrix member. Count starts from the mock estate, not from zero.
A8: Standard_E32ads_v6 | B8: 32 | C8: Eadsv6 | D8: Yes | E8: Seed-matrix member. Count starts from the mock estate, not from zero.
A9: Standard_D8ads_v5 | B9: 8 | C9: Dadsv5 | D9: Yes | E9: Seed-matrix member. Count starts from the mock estate, not from zero.
A10: Standard_D16ads_v5 | B10: 16 | C10: Dadsv5 | D10: Yes | E10: Seed-matrix member. Count starts from the mock estate, not from zero.
A11: Standard_D8as_v5 | B11: 8 | C11: Dasv5 | D11: Yes | E11: Seed-matrix member. Count starts from the mock estate, not from zero.
A12: Standard_D16as_v5 | B12: 16 | C12: Dasv5 | D12: Yes | E12: Seed-matrix member. Count starts from the mock estate, not from zero.

Sheet Capacity_Reservations
A1: Mock capacity reservations — one row per region, environment, and SKU
A2: Yellow Allocated and Buffer cells are the mock estate. Reserved = Allocated + Buffer (CAP-003). Reserved-free = Buffer. CRG names are regional (crg-…-reg); per-AZ groups are not in this file. Middle East DR rows are zero because that DR lives in Europe.
A4: Region | B4: Region id | C4: Geography | D4: Environment | E4: SKU | F4: Family | G4: vCPU | H4: CRG | I4: Allocated | J4: Buffer | K4: Reserved | L4: Reserved-free | M4: Class | N4: Note
A5: West US 3 | B5: westus3 | C5: US | D5: Prod | E5: Standard_E32ads_v5 | F5: Eadsv5 | G5: 32 | H5: crg-pr-wus3-reg | I5: 600 | J5: 200 | K5: =I5+J5 | L5: =K5-I5 | M5: Standard | N5: Synthetic estate
A6: West US 3 | B6: westus3 | C6: US | D6: Prod | E6: Standard_E64ads_v5 | F6: Eadsv5 | G6: 64 | H6: crg-pr-wus3-reg | I6: 1200 | J6: 400 | K6: =I6+J6 | L6: =K6-I6 | M6: Standard | N6: Synthetic estate
A7: West US 3 | B7: westus3 | C7: US | D7: Prod | E7: Standard_E16ads_v5 | F7: Eadsv5 | G7: 16 | H7: crg-pr-wus3-reg | I7: 300 | J7: 100 | K7: =I7+J7 | L7: =K7-I7 | M7: Standard | N7: Synthetic estate
A8: West US 3 | B8: westus3 | C8: US | D8: Prod | E8: Standard_E32ads_v6 | F8: Eadsv6 | G8: 32 | H8: crg-pr-wus3-reg | I8: 600 | J8: 200 | K8: =I8+J8 | L8: =K8-I8 | M8: Standard | N8: Synthetic estate
A9: West US 3 | B9: westus3 | C9: US | D9: Prod | E9: Standard_D8ads_v5 | F9: Dadsv5 | G9: 8 | H9: crg-pr-wus3-reg | I9: 150 | J9: 50 | K9: =I9+J9 | L9: =K9-I9 | M9: Standard | N9: Synthetic estate
A10: West US 3 | B10: westus3 | C10: US | D10: Prod | E10: Standard_D16ads_v5 | F10: Dadsv5 | G10: 16 | H10: crg-pr-wus3-reg | I10: 300 | J10: 100 | K10: =I10+J10 | L10: =K10-I10 | M10: Standard | N10: Synthetic estate
A11: West US 3 | B11: westus3 | C11: US | D11: Prod | E11: Standard_D8as_v5 | F11: Dasv5 | G11: 8 | H11: crg-pr-wus3-reg | I11: 150 | J11: 50 | K11: =I11+J11 | L11: =K11-I11 | M11: Standard | N11: Synthetic estate
A12: West US 3 | B12: westus3 | C12: US | D12: Prod | E12: Standard_D16as_v5 | F12: Dasv5 | G12: 16 | H12: crg-pr-wus3-reg | I12: 300 | J12: 100 | K12: =I12+J12 | L12: =K12-I12 | M12: Standard | N12: Synthetic estate
A13: West US 3 | B13: westus3 | C13: US | D13: NonProd | E13: Standard_E32ads_v5 | F13: Eadsv5 | G13: 32 | H13: crg-np-wus3-reg | I13: 400 | J13: 520 | K13: =I13+J13 | L13: =K13-I13 | M13: Standard | N13: Synthetic estate
A14: West US 3 | B14: westus3 | C14: US | D14: NonProd | E14: Standard_E64ads_v5 | F14: Eadsv5 | G14: 64 | H14: crg-np-wus3-reg | I14: 800 | J14: 1040 | K14: =I14+J14 | L14: =K14-I14 | M14: Standard | N14: Synthetic estate
A15: West US 3 | B15: westus3 | C15: US | D15: NonProd | E15: Standard_E16ads_v5 | F15: Eadsv5 | G15: 16 | H15: crg-np-wus3-reg | I15: 200 | J15: 260 | K15: =I15+J15 | L15: =K15-I15 | M15: Standard | N15: Synthetic estate
A16: West US 3 | B16: westus3 | C16: US | D16: NonProd | E16: Standard_E32ads_v6 | F16: Eadsv6 | G16: 32 | H16: crg-np-wus3-reg | I16: 400 | J16: 520 | K16: =I16+J16 | L16: =K16-I16 | M16: Standard | N16: Synthetic estate
... A340: UAE North | B340: uaenorth | C340: Middle East | D340: DR | E340: Standard_D16as_v5 | F340: Dasv5 | G340: 16 | H340: crg-dr-uaen-reg | I340: 0 | J340: 0 | K340: =I340+J340 | L340: =K340-I340 | M340: Standard | N340: Synthetic. Local DR is 0 — DR is placed in Europe (DR-020).

Sheet Quota_Groups
A1: Mock quota — family cells plus the regional vCPU cap
A2: Family rows are the QUA-004 accounting cell (Prod, NonProd, and DR together). Yellow Limit is synthetic. Used sums Allocated on Capacity_Reservations. Prod earmark and DR earmark are the reserved cores of those environments, so CVAL cannot spend them (HC-7). Columns N–P are the total regional vCPU cap (QUA-002), filled on the Eadsv5 row of each region. HC-3 uses the lesser of family available and that regional available. The group limit is not what a deployment checks; these numbers stand in for subscription quota after transfer.
A4: Quota group | B4: Region | C4: Region id | D4: Geography | E4: Family | F4: Limit | G4: Used | H4: Available | I4: Prod earmark | J4: DR earmark | K4: NonProd used | L4: Allocatable to NonProd | M4: NonProd headroom | N4: Regional vCPU limit | O4: Regional vCPU used | P4: Regional vCPU available
A5: qg-wus3-Eadsv5 | B5: West US 3 | C5: westus3 | D5: US | E5: Eadsv5 | F5: 8780 | G5: =SUMIFS(Capacity_Reservations!$I$5:$I$340,Capacity_Reservations!$B$5:$B$340,C5,Capacity_Reservations!$F$5:$F$340,E5) | H5: =F5-G5 | I5: =SUMIFS(Capacity_Reservations!$K$5:$K$340,Capacity_Reservations!$B$5:$B$340,C5,Capacity_Reservations!$D$5:$D$340,"Prod",Capacity_Reservations!$F$5:$F$340,E5) | J5: =SUMIFS(Capacity_Reservations!$K$5:$K$340,Capacity_Reservations!$B$5:$B$340,C5,Capacity_Reservations!$D$5:$D$340,"DR",Capacity_Reservations!$F$5:$F$340,E5) | K5: =SUMIFS(Capacity_Reservations!$I$5:$I$340,Capacity_Reservations!$B$5:$B$340,C5,Capacity_Reservations!$D$5:$D$340,"NonProd",Capacity_Reservations!$F$5:$F$340,E5) | L5: =MAX(0,F5-I5-J5) | M5: =L5-K5 | N5: 50000 | O5: =SUMIFS(Capacity_Reservations!$I$5:$I$340,Capacity_Reservations!$B$5:$B$340,C5) | P5: =N5-O5
A6: qg-wus3-Eadsv6 | B6: West US 3 | C6: westus3 | D6: US | E6: Eadsv6 | F6: 6080 | G6: =SUMIFS(Capacity_Reservations!$I$5:$I$340,Capacity_Reservations!$B$5:$B$340,C6,Capacity_Reservations!$F$5:$F$340,E6) | H6: =F6-G6 | I6: =SUMIFS(Capacity_Reservations!$K$5:$K$340,Capacity_Reservations!$B$5:$B$340,C6,Capacity_Reservations!$D$5:$D$340,"Prod",Capacity_Reservations!$F$5:$F$340,E6) | J6: =SUMIFS(Capacity_Reservations!$K$5:$K$340,Capacity_Reservations!$B$5:$B$340,C6,Capacity_Reservations!$D$5:$D$340,"DR",Capacity_Reservations!$F$5:$F$340,E6) | K6: =SUMIFS(Capacity_Reservations!$I$5:$I$340,Capacity_Reservations!$B$5:$B$340,C6,Capacity_Reservations!$D$5:$D$340,"NonProd",Capacity_Reservations!$F$5:$F$340,E6) | L6: =MAX(0,F6-I6-J6) | M6: =L6-K6
A7: qg-wus3-Dadsv5 | B7: West US 3 | C7: westus3 | D7: US | E7: Dadsv5 | F7: 5810 | G7: =SUMIFS(Capacity_Reservations!$I$5:$I$340,Capacity_Reservations!$B$5:$B$340,C7,Capacity_Reservations!$F$5:$F$340,E7) | H7: =F7-G7 | I7: =SUMIFS(Capacity_Reservations!$K$5:$K$340,Capacity_Reservations!$B$5:$B$340,C7,Capacity_Reservations!$D$5:$D$340,"Prod",Capacity_Reservations!$F$5:$F$340,E7) | J7: =SUMIFS(Capacity_Reservations!$K$5:$K$340,Capacity_Reservations!$B$5:$B$340,C7,Capacity_Reservations!$D$5:$D$340,"DR",Capacity_Reservations!$F$5:$F$340,E7) | K7: =SUMIFS(Capacity_Reservations!$I$5:$I$340,Capacity_Reservations!$B$5:$B$340,C7,Capacity_Reservations!$D$5:$D$340,"NonProd",Capacity_Reservations!$F$5:$F$340,E7) | L7: =MAX(0,F7-I7-J7) | M7: =L7-K7
A8: qg-wus3-Dasv5 | B8: West US 3 | C8: westus3 | D8: US | E8: Dasv5 | F8: 5810 | G8: =SUMIFS(Capacity_Reservations!$I$5:$I$340,Capacity_Reservations!$B$5:$B$340,C8,Capacity_Reservations!$F$5:$F$340,E8) | H8: =F8-G8 | I8: =SUMIFS(Capacity_Reservations!$K$5:$K$340,Capacity_Reservations!$B$5:$B$340,C8,Capacity_Reservations!$D$5:$D$340,"Prod",Capacity_Reservations!$F$5:$F$340,E8) | J8: =SUMIFS(Capacity_Reservations!$K$5:$K$340,Capacity_Reservations!$B$5:$B$340,C8,Capacity_Reservations!$D$5:$D$340,"DR",Capacity_Reservations!$F$5:$F$340,E8) | K8: =SUMIFS(Capacity_Reservations!$I$5:$I$340,Capacity_Reservations!$B$5:$B$340,C8,Capacity_Reservations!$D$5:$D$340,"NonProd",Capacity_Reservations!$F$5:$F$340,E8) | L8: =MAX(0,F8-I8-J8) | M8: =L8-K8
A9: qg-cus-Eadsv5 | B9: Central US | C9: centralus | D9: US | E9: Eadsv5 | F9: 9060 | G9: =SUMIFS(Capacity_Reservations!$I$5:$I$340,Capacity_Reservations!$B$5:$B$340,C9,Capacity_Reservations!$F$5:$F$340,E9) | H9: =F9-G9 | I9: =SUMIFS(Capacity_Reservations!$K$5:$K$340,Capacity_Reservations!$B$5:$B$340,C9,Capacity_Reservations!$D$5:$D$340,"Prod",Capacity_Reservations!$F$5:$F$340,E9) | J9: =SUMIFS(Capacity_Reservations!$K$5:$K$340,Capacity_Reservations!$B$5:$B$340,C9,Capacity_Reservations!$D$5:$D$340,"DR",Capacity_Reservations!$F$5:$F$340,E9) | K9: =SUMIFS(Capacity_Reservations!$I$5:$I$340,Capacity_Reservations!$B$5:$B$340,C9,Capacity_Reservations!$D$5:$D$340,"NonProd",Capacity_Reservations!$F$5:$F$340,E9) | L9: =MAX(0,F9-I9-J9) | M9: =L9-K9 | N9: 50000 | O9: =SUMIFS(Capacity_Reservations!$I$5:$I$340,Capacity_Reservations!$B$5:$B$340,C9) | P9: =N9-O9
A10: qg-cus-Eadsv6 | B10: Central US | C10: centralus | D10: US | E10: Eadsv6 | F10: 6160 | G10: =SUMIFS(Capacity_Reservations!$I$5:$I$340,Capacity_Reservations!$B$5:$B$340,C10,Capacity_Reservations!$F$5:$F$340,E10) | H10: =F10-G10 | I10: =SUMIFS(Capacity_Reservations!$K$5:$K$340,Capacity_Reservations!$B$5:$B$340,C10,Capacity_Reservations!$D$5:$D$340,"Prod",Capacity_Reservations!$F$5:$F$340,E10) | J10: =SUMIFS(Capacity_Reservations!$K$5:$K$340,Capacity_Reservations!$B$5:$B$340,C10,Capacity_Reservations!$D$5:$D$340,"DR",Capacity_Reservations!$F$5:$F$340,E10) | K10: =SUMIFS(Capacity_Reservations!$I$5:$I$340,Capacity_Reservations!$B$5:$B$340,C10,Capacity_Reservations!$D$5:$D$340,"NonProd",Capacity_Reservations!$F$5:$F$340,E10) | L10: =MAX(0,F10-I10-J10) | M10: =L10-K10
A11: qg-cus-Dadsv5 | B11: Central US | C11: centralus | D11: US | E11: Dadsv5 | F11: 5870 | G11: =SUMIFS(Capacity_Reservations!$I$5:$I$340,Capacity_Reservations!$B$5:$B$340,C11,Capacity_Reservations!$F$5:$F$340,E11) | H11: =F11-G11 | I11: =SUMIFS(Capacity_Reservations!$K$5:$K$340,Capacity_Reservations!$B$5:$B$340,C11,Capacity_Reservations!$D$5:$D$340,"Prod",Capacity_Reservations!$F$5:$F$340,E11) | J11: =SUMIFS(Capacity_Reservations!$K$5:$K$340,Capacity_Reservations!$B$5:$B$340,C11,Capacity_Reservations!$D$5:$D$340,"DR",Capacity_Reservations!$F$5:$F$340,E11) | K11: =SUMIFS(Capacity_Reservations!$I$5:$I$340,Capacity_Reservations!$B$5:$B$340,C11,Capacity_Reservations!$D$5:$D$340,"NonProd",Capacity_Reservations!$F$5:$F$340,E11) | L11: =MAX(0,F11-I11-J11) | M11: =L11-K11
A12: qg-cus-Dasv5 | B12: Central US | C12: centralus | D12: US | E12: Dasv5 | F12: 5870 | G12: =SUMIFS(Capacity_Reservations!$I$5:$I$340,Capacity_Reservations!$B$5:$B$340,C12,Capacity_Reservations!$F$5:$F$340,E12) | H12: =F12-G12 | I12: =SUMIFS(Capacity_Reservations!$K$5:$K$340,Capacity_Reservations!$B$5:$B$340,C12,Capacity_Reservations!$D$5:$D$340,"Prod",Capacity_Reservations!$F$5:$F$340,E12) | J12: =SUMIFS(Capacity_Reservations!$K$5:$K$340,Capacity_Reservations!$B$5:$B$340,C12,Capacity_Reservations!$D$5:$D$340,"DR",Capacity_Reservations!$F$5:$F$340,E12) | K12: =SUMIFS(Capacity_Reservations!$I$5:$I$340,Capacity_Reservations!$B$5:$B$340,C12,Capacity_Reservations!$D$5:$D$340,"NonProd",Capacity_Reservations!$F$5:$F$340,E12) | L12: =MAX(0,F12-I12-J12) | M12: =L12-K12
A13: qg-cac-Eadsv5 | B13: Canada Central | C13: canadacentral | D13: US | E13: Eadsv5 | F13: 7940 | G13: =SUMIFS(Capacity_Reservations!$I$5:$I$340,Capacity_Reservations!$B$5:$B$340,C13,Capacity_Reservations!$F$5:$F$340,E13) | H13: =F13-G13 | I13: =SUMIFS(Capacity_Reservations!$K$5:$K$340,Capacity_Reservations!$B$5:$B$340,C13,Capacity_Reservations!$D$5:$D$340,"Prod",Capacity_Reservations!$F$5:$F$340,E13) | J13: =SUMIFS(Capacity_Reservations!$K$5:$K$340,Capacity_Reservations!$B$5:$B$340,C13,Capacity_Reservations!$D$5:$D$340,"DR",Capacity_Reservations!$F$5:$F$340,E13) | K13: =SUMIFS(Capacity_Reservations!$I$5:$I$340,Capacity_Reservations!$B$5:$B$340,C13,Capacity_Reservations!$D$5:$D$340,"NonProd",Capacity_Reservations!$F$5:$F$340,E13) | L13: =MAX(0,F13-I13-J13) | M13: =L13-K13 | N13: 50000 | O13: =SUMIFS(Capacity_Reservations!$I$5:$I$340,Capacity_Reservations!$B$5:$B$340,C13) | P13: =N13-O13
A14: qg-cac-Eadsv6 | B14: Canada Central | C14: canadacentral | D14: US | E14: Eadsv6 | F14: 5840 | G14: =SUMIFS(Capacity_Reservations!$I$5:$I$340,Capacity_Reservations!$B$5:$B$340,C14,Capacity_Reservations!$F$5:$F$340,E14) | H14: =F14-G14 | I14: =SUMIFS(Capacity_Reservations!$K$5:$K$340,Capacity_Reservations!$B$5:$B$340,C14,Capacity_Reservations!$D$5:$D$340,"Prod",Capacity_Reservations!$F$5:$F$340,E14) | J14: =SUMIFS(Capacity_Reservations!$K$5:$K$340,Capacity_Reservations!$B$5:$B$340,C14,Capacity_Reservations!$D$5:$D$340,"DR",Capacity_Reservations!$F$5:$F$340,E14) | K14: =SUMIFS(Capacity_Reservations!$I$5:$I$340,Capacity_Reservations!$B$5:$B$340,C14,Capacity_Reservations!$D$5:$D$340,"NonProd",Capacity_Reservations!$F$5:$F$340,E14) | L14: =MAX(0,F14-I14-J14) | M14: =L14-K14
A15: qg-cac-Dadsv5 | B15: Canada Central | C15: canadacentral | D15: US | E15: Dadsv5 | F15: 5630 | G15: =SUMIFS(Capacity_Reservations!$I$5:$I$340,Capacity_Reservations!$B$5:$B$340,C15,Capacity_Reservations!$F$5:$F$340,E15) | H15: =F15-G15 | I15: =SUMIFS(Capacity_Reservations!$K$5:$K$340,Capacity_Reservations!$B$5:$B$340,C15,Capacity_Reservations!$D$5:$D$340,"Prod",Capacity_Reservations!$F$5:$F$340,E15) | J15: =SUMIFS(Capacity_Reservations!$K$5:$K$340,Capacity_Reservations!$B$5:$B$340,C15,Capacity_Reservations!$D$5:$D$340,"DR",Capacity_Reservations!$F$5:$F$340,E15) | K15: =SUMIFS(Capacity_Reservations!$I$5:$I$340,Capacity_Reservations!$B$5:$B$340,C15,Capacity_Reservations!$D$5:$D$340,"NonProd",Capacity_Reservations!$F$5:$F$340,E15) | L15: =MAX(0,F15-I15-J15) | M15: =L15-K15
A16: qg-cac-Dasv5 | B16: Canada Central | C16: canadacentral | D16: US | E16: Dasv5 | F16: 5630 | G16: =SUMIFS(Capacity_Reservations!$I$5:$I$340,Capacity_Reservations!$B$5:$B$340,C16,Capacity_Reservations!$F$5:$F$340,E16) | H16: =F16-G16 | I16: =SUMIFS(Capacity_Reservations!$K$5:$K$340,Capacity_Reservations!$B$5:$B$340,C16,Capacity_Reservations!$D$5:$D$340,"Prod",Capacity_Reservations!$F$5:$F$340,E16) | J16: =SUMIFS(Capacity_Reservations!$K$5:$K$340,Capacity_Reservations!$B$5:$B$340,C16,Capacity_Reservations!$D$5:$D$340,"DR",Capacity_Reservations!$F$5:$F$340,E16) | K16: =SUMIFS(Capacity_Reservations!$I$5:$I$340,Capacity_Reservations!$B$5:$B$340,C16,Capacity_Reservations!$D$5:$D$340,"NonProd",Capacity_Reservations!$F$5:$F$340,E16) | L16: =MAX(0,F16-I16-J16) | M16: =L16-K16
A17: qg-eus2-Eadsv5 | B17: East US 2 | C17: eastus2 | D17: US | E17: Eadsv5 | F17: 8745 | G17: =SUMIFS(Capacity_Reservations!$I$5:$I$340,Capacity_Reservations!$B$5:$B$340,C17,Capacity_Reservations!$F$5:$F$340,E17) | H17: =F17-G17 | I17: =SUMIFS(Capacity_Reservations!$K$5:$K$340,Capacity_Reservations!$B$5:$B$340,C17,Capacity_Reservations!$D$5:$D$340,"Prod",Capacity_Reservations!$F$5:$F$340,E17) | J17: =SUMIFS(Capacity_Reservations!$K$5:$K$340,Capacity_Reservations!$B$5:$B$340,C17,Capacity_Reservations!$D$5:$D$340,"DR",Capacity_Reservations!$F$5:$F$340,E17) | K17: =SUMIFS(Capacity_Reservations!$I$5:$I$340,Capacity_Reservations!$B$5:$B$340,C17,Capacity_Reservations!$D$5:$D$340,"NonProd",Capacity_Reservations!$F$5:$F$340,E17) | L17: =MAX(0,F17-I17-J17) | M17: =L17-K17 | N17: 50000 | O17: =SUMIFS(Capacity_Reservations!$I$5:$I$340,Capacity_Reservations!$B$5:$B$340,C17) | P17: =N17-O17
A18: qg-eus2-Eadsv6 | B18: East US 2 | C18: eastus2 | D18: US | E18: Eadsv6 | F18: 6070 | G18: =SUMIFS(Capacity_Reservations!$I$5:$I$340,Capacity_Reservations!$B$5:$B$340,C18,Capacity_Reservations!$F$5:$F$340,E18) | H18: =F18-G18 | I18: =SUMIFS(Capacity_Reservations!$K$5:$K$340,Capacity_Reservations!$B$5:$B$340,C18,Capacity_Reservations!$D$5:$D$340,"Prod",Capacity_Reservations!$F$5:$F$340,E18) | J18: =SUMIFS(Capacity_Reservations!$K$5:$K$340,Capacity_Reservations!$B$5:$B$340,C18,Capacity_Reservations!$D$5:$D$340,"DR",Capacity_Reservations!$F$5:$F$340,E18) | K18: =SUMIFS(Capacity_Reservations!$I$5:$I$340,Capacity_Reservations!$B$5:$B$340,C18,Capacity_Reservations!$D$5:$D$340,"NonProd",Capacity_Reservations!$F$5:$F$340,E18) | L18: =MAX(0,F18-I18-J18) | M18: =L18-K18
A19: qg-eus2-Dadsv5 | B19: East US 2 | C19: eastus2 | D19: US | E19: Dadsv5 | F19: 5803 | G19: =SUMIFS(Capacity_Reservations!$I$5:$I$340,Capacity_Reservations!$B$5:$B$340,C19,Capacity_Reservations!$F$5:$F$340,E19) | H19: =F19-G19 | I19: =SUMIFS(Capacity_Reservations!$K$5:$K$340,Capacity_Reservations!$B$5:$B$340,C19,Capacity_Reservations!$D$5:$D$340,"Prod",Capacity_Reservations!$F$5:$F$340,E19) | J19: =SUMIFS(Capacity_Reservations!$K$5:$K$340,Capacity_Reservations!$B$5:$B$340,C19,Capacity_Reservations!$D$5:$D$340,"DR",Capacity_Reservations!$F$5:$F$340,E19) | K19: =SUMIFS(Capacity_Reservations!$I$5:$I$340,Capacity_Reservations!$B$5:$B$340,C19,Capacity_Reservations!$D$5:$D$340,"NonProd",Capacity_Reservations!$F$5:$F$340,E19) | L19: =MAX(0,F19-I19-J19) | M19: =L19-K19
A20: qg-eus2-Dasv5 | B20: East US 2 | C20: eastus2 | D20: US | E20: Dasv5 | F20: 5803 | G20: =SUMIFS(Capacity_Reservations!$I$5:$I$340,Capacity_Reservations!$B$5:$B$340,C20,Capacity_Reservations!$F$5:$F$340,E20) | H20: =F20-G20 | I20: =SUMIFS(Capacity_Reservations!$K$5:$K$340,Capacity_Reservations!$B$5:$B$340,C20,Capacity_Reservations!$D$5:$D$340,"Prod",Capacity_Reservations!$F$5:$F$340,E20) | J20: =SUMIFS(Capacity_Reservations!$K$5:$K$340,Capacity_Reservations!$B$5:$B$340,C20,Capacity_Reservations!$D$5:$D$340,"DR",Capacity_Reservations!$F$5:$F$340,E20) | K20: =SUMIFS(Capacity_Reservations!$I$5:$I$340,Capacity_Reservations!$B$5:$B$340,C20,Capacity_Reservations!$D$5:$D$340,"NonProd",Capacity_Reservations!$F$5:$F$340,E20) | L20: =MAX(0,F20-I20-J20) | M20: =L20-K20
A21: qg-chn-Eadsv5 | B21: Switzerland North | C21: switzerlandnorth | D21: EU | E21: Eadsv5 | F21: 7905 | G21: =SUMIFS(Capacity_Reservations!$I$5:$I$340,Capacity_Reservations!$B$5:$B$340,C21,Capacity_Reservations!$F$5:$F$340,E21) | H21: =F21-G21 | I21: =SUMIFS(Capacity_Reservations!$K$5:$K$340,Capacity_Reservations!$B$5:$B$340,C21,Capacity_Reservations!$D$5:$D$340,"Prod",Capacity_Reservations!$F$5:$F$340,E21) | J21: =SUMIFS(Capacity_Reservations!$K$5:$K$340,Capacity_Reservations!$B$5:$B$340,C21,Capacity_Reservations!$D$5:$D$340,"DR",Capacity_Reservations!$F$5:$F$340,E21) | K21: =SUMIFS(Capacity_Reservations!$I$5:$I$340,Capacity_Reservations!$B$5:$B$340,C21,Capacity_Reservations!$D$5:$D$340,"NonProd",Capacity_Reservations!$F$5:$F$340,E21) | L21: =MAX(0,F21-I21-J21) | M21: =L21-K21 | N21: 50000 | O21: =SUMIFS(Capacity_Reservations!$I$5:$I$340,Capacity_Reservations!$B$5:$B$340,C21) | P21: =N21-O21
A22: qg-chn-Eadsv6 | B22: Switzerland North | C22: switzerlandnorth | D22: EU | E22: Eadsv6 | F22: 5830 | G22: =SUMIFS(Capacity_Reservations!$I$5:$I$340,Capacity_Reservations!$B$5:$B$340,C22,Capacity_Reservations!$F$5:$F$340,E22) | H22: =F22-G22 | I22: =SUMIFS(Capacity_Reservations!$K$5:$K$340,Capacity_Reservations!$B$5:$B$340,C22,Capacity_Reservations!$D$5:$D$340,"Prod",Capacity_Reservations!$F$5:$F$340,E22) | J22: =SUMIFS(Capacity_Reservations!$K$5:$K$340,Capacity_Reservations!$B$5:$B$340,C22,Capacity_Reservations!$D$5:$D$340,"DR",Capacity_Reservations!$F$5:$F$340,E22) | K22: =SUMIFS(Capacity_Reservations!$I$5:$I$340,Capacity_Reservations!$B$5:$B$340,C22,Capacity_Reservations!$D$5:$D$340,"NonProd",Capacity_Reservations!$F$5:$F$340,E22) | L22: =MAX(0,F22-I22-J22) | M22: =L22-K22
A23: qg-chn-Dadsv5 | B23: Switzerland North | C23: switzerlandnorth | D23: EU | E23: Dadsv5 | F23: 5622 | G23: =SUMIFS(Capacity_Reservations!$I$5:$I$340,Capacity_Reservations!$B$5:$B$340,C23,Capacity_Reservations!$F$5:$F$340,E23) | H23: =F23-G23 | I23: =SUMIFS(Capacity_Reservations!$K$5:$K$340,Capacity_Reservations!$B$5:$B$340,C23,Capacity_Reservations!$D$5:$D$340,"Prod",Capacity_Reservations!$F$5:$F$340,E23) | J23: =SUMIFS(Capacity_Reservations!$K$5:$K$340,Capacity_Reservations!$B$5:$B$340,C23,Capacity_Reservations!$D$5:$D$340,"DR",Capacity_Reservations!$F$5:$F$340,E23) | K23: =SUMIFS(Capacity_Reservations!$I$5:$I$340,Capacity_Reservations!$B$5:$B$340,C23,Capacity_Reservations!$D$5:$D$340,"NonProd",Capacity_Reservations!$F$5:$F$340,E23) | L23: =MAX(0,F23-I23-J23) | M23: =L23-K23
A24: qg-chn-Dasv5 | B24: Switzerland North | C24: switzerlandnorth | D24: EU | E24: Dasv5 | F24: 5622 | G24: =SUMIFS(Capacity_Reservations!$I$5:$I$340,Capacity_Reservations!$B$5:$B$340,C24,Capacity_Reservations!$F$5:$F$340,E24) | H24: =F24-G24 | I24: =SUMIFS(Capacity_Reservations!$K$5:$K$340,Capacity_Reservations!$B$5:$B$340,C24,Capacity_Reservations!$D$5:$D$340,"Prod",Capacity_Reservations!$F$5:$F$340,E24) | J24: =SUMIFS(Capacity_Reservations!$K$5:$K$340,Capacity_Reservations!$B$5:$B$340,C24,Capacity_Reservations!$D$5:$D$340,"DR",Capacity_Reservations!$F$5:$F$340,E24) | K24: =SUMIFS(Capacity_Reservations!$I$5:$I$340,Capacity_Reservations!$B$5:$B$340,C24,Capacity_Reservations!$D$5:$D$340,"NonProd",Capacity_Reservations!$F$5:$F$340,E24) | L24: =MAX(0,F24-I24-J24) | M24: =L24-K24
A25: qg-sec-Eadsv5 | B25: Sweden Central | C25: swedencentral | D25: EU | E25: Eadsv5 | F25: 7450 | G25: =SUMIFS(Capacity_Reservations!$I$5:$I$340,Capacity_Reservations!$B$5:$B$340,C25,Capacity_Reservations!$F$5:$F$340,E25) | H25: =F25-G25 | I25: =SUMIFS(Capacity_Reservations!$K$5:$K$340,Capacity_Reservations!$B$5:$B$340,C25,Capacity_Reservations!$D$5:$D$340,"Prod",Capacity_Reservations!$F$5:$F$340,E25) | J25: =SUMIFS(Capacity_Reservations!$K$5:$K$340,Capacity_Reservations!$B$5:$B$340,C25,Capacity_Reservations!$D$5:$D$340,"DR",Capacity_Reservations!$F$5:$F$340,E25) | K25: =SUMIFS(Capacity_Reservations!$I$5:$I$340,Capacity_Reservations!$B$5:$B$340,C25,Capacity_Reservations!$D$5:$D$340,"NonProd",Capacity_Reservations!$F$5:$F$340,E25) | L25: =MAX(0,F25-I25-J25) | M25: =L25-K25 | N25: 50000 | O25: =SUMIFS(Capacity_Reservations!$I$5:$I$340,Capacity_Reservations!$B$5:$B$340,C25) | P25: =N25-O25
A26: qg-sec-Eadsv6 | B26: Sweden Central | C26: swedencentral | D26: EU | E26: Eadsv6 | F26: 5700 | G26: =SUMIFS(Capacity_Reservations!$I$5:$I$340,Capacity_Reservations!$B$5:$B$340,C26,Capacity_Reservations!$F$5:$F$340,E26) | H26: =F26-G26 | I26: =SUMIFS(Capacity_Reservations!$K$5:$K$340,Capacity_Reservations!$B$5:$B$340,C26,Capacity_Reservations!$D$5:$D$340,"Prod",Capacity_Reservations!$F$5:$F$340,E26) | J26: =SUMIFS(Capacity_Reservations!$K$5:$K$340,Capacity_Reservations!$B$5:$B$340,C26,Capacity_Reservations!$D$5:$D$340,"DR",Capacity_Reservations!$F$5:$F$340,E26) | K26: =SUMIFS(Capacity_Reservations!$I$5:$I$340,Capacity_Reservations!$B$5:$B$340,C26,Capacity_Reservations!$D$5:$D$340,"NonProd",Capacity_Reservations!$F$5:$F$340,E26) | L26: =MAX(0,F26-I26-J26) | M26: =L26-K26
A27: qg-sec-Dadsv5 | B27: Sweden Central | C27: swedencentral | D27: EU | E27: Dadsv5 | F27: 5525 | G27: =SUMIFS(Capacity_Reservations!$I$5:$I$340,Capacity_Reservations!$B$5:$B$340,C27,Capacity_Reservations!$F$5:$F$340,E27) | H27: =F27-G27 | I27: =SUMIFS(Capacity_Reservations!$K$5:$K$340,Capacity_Reservations!$B$5:$B$340,C27,Capacity_Reservations!$D$5:$D$340,"Prod",Capacity_Reservations!$F$5:$F$340,E27) | J27: =SUMIFS(Capacity_Reservations!$K$5:$K$340,Capacity_Reservations!$B$5:$B$340,C27,Capacity_Reservations!$D$5:$D$340,"DR",Capacity_Reservations!$F$5:$F$340,E27) | K27: =SUMIFS(Capacity_Reservations!$I$5:$I$340,Capacity_Reservations!$B$5:$B$340,C27,Capacity_Reservations!$D$5:$D$340,"NonProd",Capacity_Reservations!$F$5:$F$340,E27) | L27: =MAX(0,F27-I27-J27) | M27: =L27-K27
A28: qg-sec-Dasv5 | B28: Sweden Central | C28: swedencentral | D28: EU | E28: Dasv5 | F28: 5525 | G28: =SUMIFS(Capacity_Reservations!$I$5:$I$340,Capacity_Reservations!$B$5:$B$340,C28,Capacity_Reservations!$F$5:$F$340,E28) | H28: =F28-G28 | I28: =SUMIFS(Capacity_Reservations!$K$5:$K$340,Capacity_Reservations!$B$5:$B$340,C28,Capacity_Reservations!$D$5:$D$340,"Prod",Capacity_Reservations!$F$5:$F$340,E28) | J28: =SUMIFS(Capacity_Reservations!$K$5:$K$340,Capacity_Reservations!$B$5:$B$340,C28,Capacity_Reservations!$D$5:$D$340,"DR",Capacity_Reservations!$F$5:$F$340,E28) | K28: =SUMIFS(Capacity_Reservations!$I$5:$I$340,Capacity_Reservations!$B$5:$B$340,C28,Capacity_Reservations!$D$5:$D$340,"NonProd",Capacity_Reservations!$F$5:$F$340,E28) | L28: =MAX(0,F28-I28-J28) | M28: =L28-K28
A29: qg-neu-Eadsv5 | B29: North Europe | C29: northeurope | D29: EU | E29: Eadsv5 | F29: 7135 | G29: =SUMIFS(Capacity_Reservations!$I$5:$I$340,Capacity_Reservations!$B$5:$B$340,C29,Capacity_Reservations!$F$5:$F$340,E29) | H29: =F29-G29 | I29: =SUMIFS(Capacity_Reservations!$K$5:$K$340,Capacity_Reservations!$B$5:$B$340,C29,Capacity_Reservations!$D$5:$D$340,"Prod",Capacity_Reservations!$F$5:$F$340,E29) | J29: =SUMIFS(Capacity_Reservations!$K$5:$K$340,Capacity_Reservations!$B$5:$B$340,C29,Capacity_Reservations!$D$5:$D$340,"DR",Capacity_Reservations!$F$5:$F$340,E29) | K29: =SUMIFS(Capacity_Reservations!$I$5:$I$340,Capacity_Reservations!$B$5:$B$340,C29,Capacity_Reservations!$D$5:$D$340,"NonProd",Capacity_Reservations!$F$5:$F$340,E29) | L29: =MAX(0,F29-I29-J29) | M29: =L29-K29 | N29: 50000 | O29: =SUMIFS(Capacity_Reservations!$I$5:$I$340,Capacity_Reservations!$B$5:$B$340,C29) | P29: =N29-O29
A30: qg-neu-Eadsv6 | B30: North Europe | C30: northeurope | D30: EU | E30: Eadsv6 | F30: 5610 | G30: =SUMIFS(Capacity_Reservations!$I$5:$I$340,Capacity_Reservations!$B$5:$B$340,C30,Capacity_Reservations!$F$5:$F$340,E30) | H30: =F30-G30 | I30: =SUMIFS(Capacity_Reservations!$K$5:$K$340,Capacity_Reservations!$B$5:$B$340,C30,Capacity_Reservations!$D$5:$D$340,"Prod",Capacity_Reservations!$F$5:$F$340,E30) | J30: =SUMIFS(Capacity_Reservations!$K$5:$K$340,Capacity_Reservations!$B$5:$B$340,C30,Capacity_Reservations!$D$5:$D$340,"DR",Capacity_Reservations!$F$5:$F$340,E30) | K30: =SUMIFS(Capacity_Reservations!$I$5:$I$340,Capacity_Reservations!$B$5:$B$340,C30,Capacity_Reservations!$D$5:$D$340,"NonProd",Capacity_Reservations!$F$5:$F$340,E30) | L30: =MAX(0,F30-I30-J30) | M30: =L30-K30
A31: qg-neu-Dadsv5 | B31: North Europe | C31: northeurope | D31: EU | E31: Dadsv5 | F31: 5458 | G31: =SUMIFS(Capacity_Reservations!$I$5:$I$340,Capacity_Reservations!$B$5:$B$340,C31,Capacity_Reservations!$F$5:$F$340,E31) | H31: =F31-G31 | I31: =SUMIFS(Capacity_Reservations!$K$5:$K$340,Capacity_Reservations!$B$5:$B$340,C31,Capacity_Reservations!$D$5:$D$340,"Prod",Capacity_Reservations!$F$5:$F$340,E31) | J31: =SUMIFS(Capacity_Reservations!$K$5:$K$340,Capacity_Reservations!$B$5:$B$340,C31,Capacity_Reservations!$D$5:$D$340,"DR",Capacity_Reservations!$F$5:$F$340,E31) | K31: =SUMIFS(Capacity_Reservations!$I$5:$I$340,Capacity_Reservations!$B$5:$B$340,C31,Capacity_Reservations!$D$5:$D$340,"NonProd",Capacity_Reservations!$F$5:$F$340,E31) | L31: =MAX(0,F31-I31-J31) | M31: =L31-K31
A32: qg-neu-Dasv5 | B32: North Europe | C32: northeurope | D32: EU | E32: Dasv5 | F32: 5458 | G32: =SUMIFS(Capacity_Reservations!$I$5:$I$340,Capacity_Reservations!$B$5:$B$340,C32,Capacity_Reservations!$F$5:$F$340,E32) | H32: =F32-G32 | I32: =SUMIFS(Capacity_Reservations!$K$5:$K$340,Capacity_Reservations!$B$5:$B$340,C32,Capacity_Reservations!$D$5:$D$340,"Prod",Capacity_Reservations!$F$5:$F$340,E32) | J32: =SUMIFS(Capacity_Reservations!$K$5:$K$340,Capacity_Reservations!$B$5:$B$340,C32,Capacity_Reservations!$D$5:$D$340,"DR",Capacity_Reservations!$F$5:$F$340,E32) | K32: =SUMIFS(Capacity_Reservations!$I$5:$I$340,Capacity_Reservations!$B$5:$B$340,C32,Capacity_Reservations!$D$5:$D$340,"NonProd",Capacity_Reservations!$F$5:$F$340,E32) | L32: =MAX(0,F32-I32-J32) | M32: =L32-K32
A33: qg-weu-Eadsv5 | B33: West Europe | C33: westeurope | D33: EU | E33: Eadsv5 | F33: 7506 | G33: =SUMIFS(Capacity_Reservations!$I$5:$I$340,Capacity_Reservations!$B$5:$B$340,C33,Capacity_Reservations!$F$5:$F$340,E33) | H33: =F33-G33 | I33: =SUMIFS(Capacity_Reservations!$K$5:$K$340,Capacity_Reservations!$B$5:$B$340,C33,Capacity_Reservations!$D$5:$D$340,"Prod",Capacity_Reservations!$F$5:$F$340,E33) | J33: =SUMIFS(Capacity_Reservations!$K$5:$K$340,Capacity_Reservations!$B$5:$B$340,C33,Capacity_Reservations!$D$5:$D$340,"DR",Capacity_Reservations!$F$5:$F$340,E33) | K33: =SUMIFS(Capacity_Reservations!$I$5:$I$340,Capacity_Reservations!$B$5:$B$340,C33,Capacity_Reservations!$D$5:$D$340,"NonProd",Capacity_Reservations!$F$5:$F$340,E33) | L33: =MAX(0,F33-I33-J33) | M33: =L33-K33 | N33: 50000 | O33: =SUMIFS(Capacity_Reservations!$I$5:$I$340,Capacity_Reservations!$B$5:$B$340,C33) | P33: =N33-O33
A34: qg-weu-Eadsv6 | B34: West Europe | C34: westeurope | D34: EU | E34: Eadsv6 | F34: 5716 | G34: =SUMIFS(Capacity_Reservations!$I$5:$I$340,Capacity_Reservations!$B$5:$B$340,C34,Capacity_Reservations!$F$5:$F$340,E34) | H34: =F34-G34 | I34: =SUMIFS(Capacity_Reservations!$K$5:$K$340,Capacity_Reservations!$B$5:$B$340,C34,Capacity_Reservations!$D$5:$D$340,"Prod",Capacity_Reservations!$F$5:$F$340,E34) | J34: =SUMIFS(Capacity_Reservations!$K$5:$K$340,Capacity_Reservations!$B$5:$B$340,C34,Capacity_Reservations!$D$5:$D$340,"DR",Capacity_Reservations!$F$5:$F$340,E34) | K34: =SUMIFS(Capacity_Reservations!$I$5:$I$340,Capacity_Reservations!$B$5:$B$340,C34,Capacity_Reservations!$D$5:$D$340,"NonProd",Capacity_Reservations!$F$5:$F$340,E34) | L34: =MAX(0,F34-I34-J34) | M34: =L34-K34
A35: qg-weu-Dadsv5 | B35: West Europe | C35: westeurope | D35: EU | E35: Dadsv5 | F35: 5537 | G35: =SUMIFS(Capacity_Reservations!$I$5:$I$340,Capacity_Reservations!$B$5:$B$340,C35,Capacity_Reservations!$F$5:$F$340,E35) | H35: =F35-G35 | I35: =SUMIFS(Capacity_Reservations!$K$5:$K$340,Capacity_Reservations!$B$5:$B$340,C35,Capacity_Reservations!$D$5:$D$340,"Prod",Capacity_Reservations!$F$5:$F$340,E35) | J35: =SUMIFS(Capacity_Reservations!$K$5:$K$340,Capacity_Reservations!$B$5:$B$340,C35,Capacity_Reservations!$D$5:$D$340,"DR",Capacity_Reservations!$F$5:$F$340,E35) | K35: =SUMIFS(Capacity_Reservations!$I$5:$I$340,Capacity_Reservations!$B$5:$B$340,C35,Capacity_Reservations!$D$5:$D$340,"NonProd",Capacity_Reservations!$F$5:$F$340,E35) | L35: =MAX(0,F35-I35-J35) | M35: =L35-K35
A36: qg-weu-Dasv5 | B36: West Europe | C36: westeurope | D36: EU | E36: Dasv5 | F36: 5537 | G36: =SUMIFS(Capacity_Reservations!$I$5:$I$340,Capacity_Reservations!$B$5:$B$340,C36,Capacity_Reservations!$F$5:$F$340,E36) | H36: =F36-G36 | I36: =SUMIFS(Capacity_Reservations!$K$5:$K$340,Capacity_Reservations!$B$5:$B$340,C36,Capacity_Reservations!$D$5:$D$340,"Prod",Capacity_Reservations!$F$5:$F$340,E36) | J36: =SUMIFS(Capacity_Reservations!$K$5:$K$340,Capacity_Reservations!$B$5:$B$340,C36,Capacity_Reservations!$D$5:$D$340,"DR",Capacity_Reservations!$F$5:$F$340,E36) | K36: =SUMIFS(Capacity_Reservations!$I$5:$I$340,Capacity_Reservations!$B$5:$B$340,C36,Capacity_Reservations!$D$5:$D$340,"NonProd",Capacity_Reservations!$F$5:$F$340,E36) | L36: =MAX(0,F36-I36-J36) | M36: =L36-K36
A37: qg-aue-Eadsv5 | B37: Australia East | C37: australiaeast | D37: Australia | E37: Eadsv5 | F37: 6764 | G37: =SUMIFS(Capacity_Reservations!$I$5:$I$340,Capacity_Reservations!$B$5:$B$340,C37,Capacity_Reservations!$F$5:$F$340,E37) | H37: =F37-G37 | I37: =SUMIFS(Capacity_Reservations!$K$5:$K$340,Capacity_Reservations!$B$5:$B$340,C37,Capacity_Reservations!$D$5:$D$340,"Prod",Capacity_Reservations!$F$5:$F$340,E37) | J37: =SUMIFS(Capacity_Reservations!$K$5:$K$340,Capacity_Reservations!$B$5:$B$340,C37,Capacity_Reservations!$D$5:$D$340,"DR",Capacity_Reservations!$F$5:$F$340,E37) | K37: =SUMIFS(Capacity_Reservations!$I$5:$I$340,Capacity_Reservations!$B$5:$B$340,C37,Capacity_Reservations!$D$5:$D$340,"NonProd",Capacity_Reservations!$F$5:$F$340,E37) | L37: =MAX(0,F37-I37-J37) | M37: =L37-K37 | N37: 50000 | O37: =SUMIFS(Capacity_Reservations!$I$5:$I$340,Capacity_Reservations!$B$5:$B$340,C37) | P37: =N37-O37
A38: qg-aue-Eadsv6 | B38: Australia East | C38: australiaeast | D38: Australia | E38: Eadsv6 | F38: 5504 | G38: =SUMIFS(Capacity_Reservations!$I$5:$I$340,Capacity_Reservations!$B$5:$B$340,C38,Capacity_Reservations!$F$5:$F$340,E38) | H38: =F38-G38 | I38: =SUMIFS(Capacity_Reservations!$K$5:$K$340,Capacity_Reservations!$B$5:$B$340,C38,Capacity_Reservations!$D$5:$D$340,"Prod",Capacity_Reservations!$F$5:$F$340,E38) | J38: =SUMIFS(Capacity_Reservations!$K$5:$K$340,Capacity_Reservations!$B$5:$B$340,C38,Capacity_Reservations!$D$5:$D$340,"DR",Capacity_Reservations!$F$5:$F$340,E38) | K38: =SUMIFS(Capacity_Reservations!$I$5:$I$340,Capacity_Reservations!$B$5:$B$340,C38,Capacity_Reservations!$D$5:$D$340,"NonProd",Capacity_Reservations!$F$5:$F$340,E38) | L38: =MAX(0,F38-I38-J38) | M38: =L38-K38
A39: qg-aue-Dadsv5 | B39: Australia East | C39: australiaeast | D39: Australia | E39: Dadsv5 | F39: 5378 | G39: =SUMIFS(Capacity_Reservations!$I$5:$I$340,Capacity_Reservations!$B$5:$B$340,C39,Capacity_Reservations!$F$5:$F$340,E39) | H39: =F39-G39 | I39: =SUMIFS(Capacity_Reservations!$K$5:$K$340,Capacity_Reservations!$B$5:$B$340,C39,Capacity_Reservations!$D$5:$D$340,"Prod",Capacity_Reservations!$F$5:$F$340,E39) | J39: =SUMIFS(Capacity_Reservations!$K$5:$K$340,Capacity_Reservations!$B$5:$B$340,C39,Capacity_Reservations!$D$5:$D$340,"DR",Capacity_Reservations!$F$5:$F$340,E39) | K39: =SUMIFS(Capacity_Reservations!$I$5:$I$340,Capacity_Reservations!$B$5:$B$340,C39,Capacity_Reservations!$D$5:$D$340,"NonProd",Capacity_Reservations!$F$5:$F$340,E39) | L39: =MAX(0,F39-I39-J39) | M39: =L39-K39
A40: qg-aue-Dasv5 | B40: Australia East | C40: australiaeast | D40: Australia | E40: Dasv5 | F40: 5378 | G40: =SUMIFS(Capacity_Reservations!$I$5:$I$340,Capacity_Reservations!$B$5:$B$340,C40,Capacity_Reservations!$F$5:$F$340,E40) | H40: =F40-G40 | I40: =SUMIFS(Capacity_Reservations!$K$5:$K$340,Capacity_Reservations!$B$5:$B$340,C40,Capacity_Reservations!$D$5:$D$340,"Prod",Capacity_Reservations!$F$5:$F$340,E40) | J40: =SUMIFS(Capacity_Reservations!$K$5:$K$340,Capacity_Reservations!$B$5:$B$340,C40,Capacity_Reservations!$D$5:$D$340,"DR",Capacity_Reservations!$F$5:$F$340,E40) | K40: =SUMIFS(Capacity_Reservations!$I$5:$I$340,Capacity_Reservations!$B$5:$B$340,C40,Capacity_Reservations!$D$5:$D$340,"NonProd",Capacity_Reservations!$F$5:$F$340,E40) | L40: =MAX(0,F40-I40-J40) | M40: =L40-K40
A41: qg-aus-Eadsv5 | B41: Australia Southeast | C41: australiasoutheast | D41: Australia | E41: Eadsv5 | F41: 6330 | G41: =SUMIFS(Capacity_Reservations!$I$5:$I$340,Capacity_Reservations!$B$5:$B$340,C41,Capacity_Reservations!$F$5:$F$340,E41) | H41: =F41-G41 | I41: =SUMIFS(Capacity_Reservations!$K$5:$K$340,Capacity_Reservations!$B$5:$B$340,C41,Capacity_Reservations!$D$5:$D$340,"Prod",Capacity_Reservations!$F$5:$F$340,E41) | J41: =SUMIFS(Capacity_Reservations!$K$5:$K$340,Capacity_Reservations!$B$5:$B$340,C41,Capacity_Reservations!$D$5:$D$340,"DR",Capacity_Reservations!$F$5:$F$340,E41) | K41: =SUMIFS(Capacity_Reservations!$I$5:$I$340,Capacity_Reservations!$B$5:$B$340,C41,Capacity_Reservations!$D$5:$D$340,"NonProd",Capacity_Reservations!$F$5:$F$340,E41) | L41: =MAX(0,F41-I41-J41) | M41: =L41-K41 | N41: 50000 | O41: =SUMIFS(Capacity_Reservations!$I$5:$I$340,Capacity_Reservations!$B$5:$B$340,C41) | P41: =N41-O41
...

Sheet Line_Check
A1: Per-region, per-SKU line calculations
A2: Formulas only. Score sheets read this grid. Inactive request lines contribute a neutral 1 to every MIN.
A4: Region | B4: Region id | C4: Geography | D4: Class | E4: Model | F4: DR scope | G4: AZ | H4: Customers | I4: DR coverage | J4: L1 Active | K4: L1 Cores | L4: L1 Family | M4: L1 Prod free | N4: L1 Prod reserved | O4: L1 NP free | P4: L1 NP reserved | Q4: L1 DR free | R4: L1 DR reserved | S4: L1 Quota avail | T4: L1 Quota limit | U4: L1 NP headroom | V4: L2 Active | W4: L2 Cores | X4: L2 Family | Y4: L2 Prod free | Z4: L2 Prod reserved | AA4: L2 NP free | AB4: L2 NP reserved | AC4: L2 DR free | AD4: L2 DR reserved | AE4: L2 Quota avail | AF4: L2 Quota limit | AG4: L2 NP headroom | AH4: L3 Active | AI4: L3 Cores | AJ4: L3 Family | AK4: L3 Prod free | AL4: L3 Prod reserved | AM4: L3 NP free | AN4: L3 NP reserved | AO4: L3 DR free | AP4: L3 DR reserved | AQ4: L3 Quota avail | AR4: L3 Quota limit | AS4: L3 NP headroom | AT4: L4 Active | AU4: L4 Cores | AV4: L4 Family | AW4: L4 Prod free | AX4: L4 Prod reserved | AY4: L4 NP free | AZ4: L4 NP reserved | BA4: L4 DR free | BB4: L4 DR reserved | BC4: L4 Quota avail | BD4: L4 Quota limit | BE4: L4 NP headroom | BF4: L5 Active | BG4: L5 Cores | BH4: L5 Family | BI4: L5 Prod free | BJ4: L5 Prod reserved | BK4: L5 NP free | BL4: L5 NP reserved | BM4: L5 DR free | BN4: L5 DR reserved | BO4: L5 Quota avail | BP4: L5 Quota limit | BQ4: L5 NP headroom | BR4: L6 Active | BS4: L6 Cores | BT4: L6 Family | BU4: L6 Prod free | BV4: L6 Prod reserved | BW4: L6 NP free | BX4: L6 NP reserved | BY4: L6 DR free | BZ4: L6 DR reserved | CA4: L6 Quota avail | CB4: L6 Quota limit | CC4: L6 NP headroom | CD4: L7 Active | CE4: L7 Cores | CF4: L7 Family | CG4: L7 Prod free | CH4: L7 Prod reserved | CI4: L7 NP free | CJ4: L7 NP reserved | CK4: L7 DR free | CL4: L7 DR reserved | CM4: L7 Quota avail | CN4: L7 Quota limit | CO4: L7 NP headroom | CP4: L8 Active | CQ4: L8 Cores | CR4: L8 Family | CS4: L8 Prod free | CT4: L8 Prod reserved | CU4: L8 NP free | CV4: L8 NP reserved | CW4: L8 DR free | CX4: L8 DR reserved | CY4: L8 Quota avail | CZ4: L8 Quota limit | DA4: L8 NP headroom
