Workbook

Sheet ReadMe
A1: ACRME SKU-LEVEL PLACEMENT WHAT-IF — PHASE 2 (Multi-SKU deployment scoring)
A3: WHAT THIS IS
A4: A DIFFERENT what-if from the region-selection model (Phase 1). That model scores capacity/quota as ONE blended number per region.
A5: This model scores placement at SKU grain for a MULTI-SKU deployment: enter up to 8 SKU lines (SKU + VM count each).
A6: A candidate region is Eligible only when EVERY active SKU line has GROUP AVAIL >= Line Cores (Meets-All = 1).
A7: Score components are aggregated across lines using MIN (bottleneck-SKU drives the score).
A9: HOW TO USE
A10: 1. Open the Request sheet. Fill yellow cells:
A11: - B4: Geography (US or EU). B5: Customer ID.
A12: - Rows 8-15: For each SKU line, select SKU (col B dropdown) and enter VM count (col C).
A13: - vCPU/inst (col D), Line Cores (col E), and Quota Family (col F) are derived automatically.
A14: - Leave a row blank (B and C empty) to deactivate that line. At least 1 active line required.
... A42: - SKU->family map is naming-derived; a canonical Azure family table would replace it.

Sheet Request
A1: REQUEST — Customer placement request (edit yellow cells)
A2: Phase 2 evaluates up to 8 SKU lines per deployment. Enter each SKU and VM count; ALL lines must be satisfiable in a candidate region for it to be Eligible.
A4: Geography | B4: US | C4: US or EU (candidate regions filtered to this)
A5: Customer ID | B5: CUST-0042
A7: Line # | B7: SKU | C7: VM Count | D7: vCPU / inst | E7: Line Cores | F7: Quota Family | G7: Notes
A8: 1 | B8: Standard_E32ads_v5 | C8: 4 | D8: =IFERROR(IF(B8="","",VLOOKUP(B8,SKU_Catalogue!$A:$B,2,FALSE)),"") | E8: =IFERROR(IF(OR(B8="",C8=""),"",C8*D8),"") | F8: =IFERROR(IF(B8="","",VLOOKUP(B8,SKU_Family_Map!$A:$B,2,FALSE)),"")
A9: 2 | B9: Standard_D8as_v5 | C9: 2 | D9: =IFERROR(IF(B9="","",VLOOKUP(B9,SKU_Catalogue!$A:$B,2,FALSE)),"") | E9: =IFERROR(IF(OR(B9="",C9=""),"",C9*D9),"") | F9: =IFERROR(IF(B9="","",VLOOKUP(B9,SKU_Family_Map!$A:$B,2,FALSE)),"")
A10: 3 | D10: =IFERROR(IF(B10="","",VLOOKUP(B10,SKU_Catalogue!$A:$B,2,FALSE)),"") | E10: =IFERROR(IF(OR(B10="",C10=""),"",C10*D10),"") | F10: =IFERROR(IF(B10="","",VLOOKUP(B10,SKU_Family_Map!$A:$B,2,FALSE)),"")
A11: 4 | D11: =IFERROR(IF(B11="","",VLOOKUP(B11,SKU_Catalogue!$A:$B,2,FALSE)),"") | E11: =IFERROR(IF(OR(B11="",C11=""),"",C11*D11),"") | F11: =IFERROR(IF(B11="","",VLOOKUP(B11,SKU_Family_Map!$A:$B,2,FALSE)),"")
A12: 5 | D12: =IFERROR(IF(B12="","",VLOOKUP(B12,SKU_Catalogue!$A:$B,2,FALSE)),"") | E12: =IFERROR(IF(OR(B12="",C12=""),"",C12*D12),"") | F12: =IFERROR(IF(B12="","",VLOOKUP(B12,SKU_Family_Map!$A:$B,2,FALSE)),"")
A13: 6 | D13: =IFERROR(IF(B13="","",VLOOKUP(B13,SKU_Catalogue!$A:$B,2,FALSE)),"") | E13: =IFERROR(IF(OR(B13="",C13=""),"",C13*D13),"") | F13: =IFERROR(IF(B13="","",VLOOKUP(B13,SKU_Family_Map!$A:$B,2,FALSE)),"")
A14: 7 | D14: =IFERROR(IF(B14="","",VLOOKUP(B14,SKU_Catalogue!$A:$B,2,FALSE)),"") | E14: =IFERROR(IF(OR(B14="",C14=""),"",C14*D14),"") | F14: =IFERROR(IF(B14="","",VLOOKUP(B14,SKU_Family_Map!$A:$B,2,FALSE)),"")
A15: 8 | D15: =IFERROR(IF(B15="","",VLOOKUP(B15,SKU_Catalogue!$A:$B,2,FALSE)),"") | E15: =IFERROR(IF(OR(B15="",C15=""),"",C15*D15),"") | F15: =IFERROR(IF(B15="","",VLOOKUP(B15,SKU_Family_Map!$A:$B,2,FALSE)),"")
A17: Active lines (SKU + VM both filled) | B17: =COUNTIFS(B8:B15,"<>",C8:C15,"<>")
A18: Total requested cores (all active lines) | B18: =SUMPRODUCT(IFERROR(E8:E15*1,0))
A19: ★ A region is Eligible only when every active line can be satisfied (Meets-All = 1).

Sheet Policy
A1: POLICY — Placement-score weights & thresholds (edit yellow cells)
A3: Score weights (must sum to 1.00)
A4: w_alpha (availability fit: group_avail vs requested) | B4: 0.5
A5: w_beta (family quota headroom ratio) | B5: 0.3
A6: w_epsilon (buffer safety: reserved-free vs reserved) | B6: 0.2
A7: Sum of weights (check = 1.00) | B7: =B4+B5+B6
A9: Thresholds
A10: risk_threshold (READY_WITH_RISK if alpha < this value; 0.10 = keep ≥10% buffer) | B10: 0.1
A11: min_buffer_floor (cores; buffer must stay >= this after placement) | B11: 8

Sheet SKU_Family_Map
A1: SKU -> QUOTA FAMILY MAP (drives all lookups)
A2: Capacity is reserved per SKU; quota is granted per family. Many SKUs -> one family.
A3: SKU | B3: Quota Family
A4: Standard_E32ads_v5 | B4: Eadsv5
A5: Standard_E64ads_v5 | B5: Eadsv5
A6: Standard_E16ads_v5 | B6: Eadsv5
A7: Standard_E32ads_v6 | B7: Eadsv6
A8: Standard_D8ads_v5 | B8: Dadsv5
A9: Standard_D16ads_v5 | B9: Dadsv5
A10: Standard_D8as_v5 | B10: Dasv5
A11: Standard_D16as_v5 | B11: Dasv5

Sheet SKU_Catalogue
A1: SKU CATALOGUE (managed seed-matrix view, CAP-022)
A3: SKU | B3: vCPU/inst | C3: Quota Family | D3: Zonal? (CAP-020) | E3: Eligible? | F3: Notes
A4: Standard_E32ads_v5 | B4: 32 | C4: Eadsv5 | D4: Yes | E4: Yes | F4: Dadsv5/eadsv5/dasv5 general-purpose & memory-optimised
A5: Standard_E64ads_v5 | B5: 64 | C5: Eadsv5 | D5: Yes | E5: Yes | F5: Dadsv5/eadsv5/dasv5 general-purpose & memory-optimised
A6: Standard_E16ads_v5 | B6: 16 | C6: Eadsv5 | D6: Yes | E6: Yes | F6: Dadsv5/eadsv5/dasv5 general-purpose & memory-optimised
A7: Standard_E32ads_v6 | B7: 32 | C7: Eadsv6 | D7: Yes | E7: Yes | F7: Dadsv5/eadsv5/dasv5 general-purpose & memory-optimised
A8: Standard_D8ads_v5 | B8: 8 | C8: Dadsv5 | D8: Yes | E8: Yes | F8: Dadsv5/eadsv5/dasv5 general-purpose & memory-optimised
A9: Standard_D16ads_v5 | B9: 16 | C9: Dadsv5 | D9: Yes | E9: Yes | F9: Dadsv5/eadsv5/dasv5 general-purpose & memory-optimised
A10: Standard_D8as_v5 | B10: 8 | C10: Dasv5 | D10: Yes | E10: Yes | F10: Dadsv5/eadsv5/dasv5 general-purpose & memory-optimised
A11: Standard_D16as_v5 | B11: 16 | C11: Dasv5 | D11: Yes | E11: Yes | F11: Dadsv5/eadsv5/dasv5 general-purpose & memory-optimised

Sheet Capacity_By_SKU
A1: CAPACITY BY SKU — reservations at Region x Environment x SKU (CAP-023)
A2: Reservation plane. GROUP AVAIL (col M) = MIN(reserved-free, family quota-available) is the placeable headroom for one SKU.
A3: NOTE: CRG modelled at REGIONAL scope (crg-...-reg). Per-AZ CRGs (crg-...-az1, CAP-023/CAP-011) are the next increment. Allocated is derived from real usage; Canada Central is a flagged mock; DR = 30% of Prod (ENV-005 bootstrap).
A4: Region | B4: Geography | C4: Environment | D4: SKU | E4: Family | F4: CRG (CAP-023) | G4: vCPU/inst | H4: Allocated | I4: Buffer | J4: Reserved | K4: Reserved-Free | L4: Family Quota-Avail | M4: GROUP AVAIL (MIN) | N4: Binding Constraint | O4: Readiness (RDY-002) | P4: Notes
A5: West US 3 | B5: US | C5: Prod | D5: Standard_E32ads_v5 | E5: =VLOOKUP(D5,SKU_Family_Map!$A:$B,2,FALSE) | F5: crg-pr-wus3-reg | G5: 32 | H5: 0 | I5: 8 | J5: =H5+I5 | K5: =J5-H5 | L5: =SUMIFS(Quota_Groups!$G:$G,Quota_Groups!$B:$B,A5,Quota_Groups!$D:$D,E5) | M5: =MIN(K5,L5) | N5: =IF(K5<=L5,"CAPACITY","QUOTA") | O5: =IF(K5<=0,"RESERVATION_DEFICIT",IF(L5<=0,"QUOTA_DEFICIT",IF(M5<I5*0.5,"READY_WITH_RISK","READY")))
A6: West US 3 | B6: US | C6: Prod | D6: Standard_E64ads_v5 | E6: =VLOOKUP(D6,SKU_Family_Map!$A:$B,2,FALSE) | F6: crg-pr-wus3-reg | G6: 64 | H6: 0 | I6: 8 | J6: =H6+I6 | K6: =J6-H6 | L6: =SUMIFS(Quota_Groups!$G:$G,Quota_Groups!$B:$B,A6,Quota_Groups!$D:$D,E6) | M6: =MIN(K6,L6) | N6: =IF(K6<=L6,"CAPACITY","QUOTA") | O6: =IF(K6<=0,"RESERVATION_DEFICIT",IF(L6<=0,"QUOTA_DEFICIT",IF(M6<I6*0.5,"READY_WITH_RISK","READY")))
A7: West US 3 | B7: US | C7: Prod | D7: Standard_E16ads_v5 | E7: =VLOOKUP(D7,SKU_Family_Map!$A:$B,2,FALSE) | F7: crg-pr-wus3-reg | G7: 16 | H7: 0 | I7: 8 | J7: =H7+I7 | K7: =J7-H7 | L7: =SUMIFS(Quota_Groups!$G:$G,Quota_Groups!$B:$B,A7,Quota_Groups!$D:$D,E7) | M7: =MIN(K7,L7) | N7: =IF(K7<=L7,"CAPACITY","QUOTA") | O7: =IF(K7<=0,"RESERVATION_DEFICIT",IF(L7<=0,"QUOTA_DEFICIT",IF(M7<I7*0.5,"READY_WITH_RISK","READY")))
A8: West US 3 | B8: US | C8: Prod | D8: Standard_E32ads_v6 | E8: =VLOOKUP(D8,SKU_Family_Map!$A:$B,2,FALSE) | F8: crg-pr-wus3-reg | G8: 32 | H8: 0 | I8: 8 | J8: =H8+I8 | K8: =J8-H8 | L8: =SUMIFS(Quota_Groups!$G:$G,Quota_Groups!$B:$B,A8,Quota_Groups!$D:$D,E8) | M8: =MIN(K8,L8) | N8: =IF(K8<=L8,"CAPACITY","QUOTA") | O8: =IF(K8<=0,"RESERVATION_DEFICIT",IF(L8<=0,"QUOTA_DEFICIT",IF(M8<I8*0.5,"READY_WITH_RISK","READY")))
A9: West US 3 | B9: US | C9: Prod | D9: Standard_D8ads_v5 | E9: =VLOOKUP(D9,SKU_Family_Map!$A:$B,2,FALSE) | F9: crg-pr-wus3-reg | G9: 8 | H9: 0 | I9: 8 | J9: =H9+I9 | K9: =J9-H9 | L9: =SUMIFS(Quota_Groups!$G:$G,Quota_Groups!$B:$B,A9,Quota_Groups!$D:$D,E9) | M9: =MIN(K9,L9) | N9: =IF(K9<=L9,"CAPACITY","QUOTA") | O9: =IF(K9<=0,"RESERVATION_DEFICIT",IF(L9<=0,"QUOTA_DEFICIT",IF(M9<I9*0.5,"READY_WITH_RISK","READY")))
A10: West US 3 | B10: US | C10: Prod | D10: Standard_D16ads_v5 | E10: =VLOOKUP(D10,SKU_Family_Map!$A:$B,2,FALSE) | F10: crg-pr-wus3-reg | G10: 16 | H10: 0 | I10: 8 | J10: =H10+I10 | K10: =J10-H10 | L10: =SUMIFS(Quota_Groups!$G:$G,Quota_Groups!$B:$B,A10,Quota_Groups!$D:$D,E10) | M10: =MIN(K10,L10) | N10: =IF(K10<=L10,"CAPACITY","QUOTA") | O10: =IF(K10<=0,"RESERVATION_DEFICIT",IF(L10<=0,"QUOTA_DEFICIT",IF(M10<I10*0.5,"READY_WITH_RISK","READY")))
A11: West US 3 | B11: US | C11: Prod | D11: Standard_D8as_v5 | E11: =VLOOKUP(D11,SKU_Family_Map!$A:$B,2,FALSE) | F11: crg-pr-wus3-reg | G11: 8 | H11: 0 | I11: 8 | J11: =H11+I11 | K11: =J11-H11 | L11: =SUMIFS(Quota_Groups!$G:$G,Quota_Groups!$B:$B,A11,Quota_Groups!$D:$D,E11) | M11: =MIN(K11,L11) | N11: =IF(K11<=L11,"CAPACITY","QUOTA") | O11: =IF(K11<=0,"RESERVATION_DEFICIT",IF(L11<=0,"QUOTA_DEFICIT",IF(M11<I11*0.5,"READY_WITH_RISK","READY")))
A12: West US 3 | B12: US | C12: Prod | D12: Standard_D16as_v5 | E12: =VLOOKUP(D12,SKU_Family_Map!$A:$B,2,FALSE) | F12: crg-pr-wus3-reg | G12: 16 | H12: 0 | I12: 8 | J12: =H12+I12 | K12: =J12-H12 | L12: =SUMIFS(Quota_Groups!$G:$G,Quota_Groups!$B:$B,A12,Quota_Groups!$D:$D,E12) | M12: =MIN(K12,L12) | N12: =IF(K12<=L12,"CAPACITY","QUOTA") | O12: =IF(K12<=0,"RESERVATION_DEFICIT",IF(L12<=0,"QUOTA_DEFICIT",IF(M12<I12*0.5,"READY_WITH_RISK","READY")))
A13: West US 3 | B13: US | C13: NonProd | D13: Standard_E32ads_v5 | E13: =VLOOKUP(D13,SKU_Family_Map!$A:$B,2,FALSE) | F13: crg-np-wus3-reg | G13: 32 | H13: 0 | I13: 8 | J13: =H13+I13 | K13: =J13-H13 | L13: =SUMIFS(Quota_Groups!$G:$G,Quota_Groups!$B:$B,A13,Quota_Groups!$D:$D,E13) | M13: =MIN(K13,L13) | N13: =IF(K13<=L13,"CAPACITY","QUOTA") | O13: =IF(K13<=0,"RESERVATION_DEFICIT",IF(L13<=0,"QUOTA_DEFICIT",IF(M13<I13*0.5,"READY_WITH_RISK","READY")))
A14: West US 3 | B14: US | C14: NonProd | D14: Standard_E64ads_v5 | E14: =VLOOKUP(D14,SKU_Family_Map!$A:$B,2,FALSE) | F14: crg-np-wus3-reg | G14: 64 | H14: 0 | I14: 8 | J14: =H14+I14 | K14: =J14-H14 | L14: =SUMIFS(Quota_Groups!$G:$G,Quota_Groups!$B:$B,A14,Quota_Groups!$D:$D,E14) | M14: =MIN(K14,L14) | N14: =IF(K14<=L14,"CAPACITY","QUOTA") | O14: =IF(K14<=0,"RESERVATION_DEFICIT",IF(L14<=0,"QUOTA_DEFICIT",IF(M14<I14*0.5,"READY_WITH_RISK","READY")))
A15: West US 3 | B15: US | C15: NonProd | D15: Standard_E16ads_v5 | E15: =VLOOKUP(D15,SKU_Family_Map!$A:$B,2,FALSE) | F15: crg-np-wus3-reg | G15: 16 | H15: 0 | I15: 8 | J15: =H15+I15 | K15: =J15-H15 | L15: =SUMIFS(Quota_Groups!$G:$G,Quota_Groups!$B:$B,A15,Quota_Groups!$D:$D,E15) | M15: =MIN(K15,L15) | N15: =IF(K15<=L15,"CAPACITY","QUOTA") | O15: =IF(K15<=0,"RESERVATION_DEFICIT",IF(L15<=0,"QUOTA_DEFICIT",IF(M15<I15*0.5,"READY_WITH_RISK","READY")))
A16: West US 3 | B16: US | C16: NonProd | D16: Standard_E32ads_v6 | E16: =VLOOKUP(D16,SKU_Family_Map!$A:$B,2,FALSE) | F16: crg-np-wus3-reg | G16: 32 | H16: 0 | I16: 8 | J16: =H16+I16 | K16: =J16-H16 | L16: =SUMIFS(Quota_Groups!$G:$G,Quota_Groups!$B:$B,A16,Quota_Groups!$D:$D,E16) | M16: =MIN(K16,L16) | N16: =IF(K16<=L16,"CAPACITY","QUOTA") | O16: =IF(K16<=0,"RESERVATION_DEFICIT",IF(L16<=0,"QUOTA_DEFICIT",IF(M16<I16*0.5,"READY_WITH_RISK","READY")))
... A52: Central US | B52: US | C52: DR | D52: Standard_D16as_v5 | E52: =VLOOKUP(D52,SKU_Family_Map!$A:$B,2,FALSE) | F52: crg-dr-cus-reg | G52: 16 | H52: 1306 | I52: 157 | J52: =H52+I52 | K52: =J52-H52 | L52: =SUMIFS(Quota_Groups!$G:$G,Quota_Groups!$B:$B,A52,Quota_Groups!$D:$D,E52) | M52: =MIN(K52,L52) | N52: =IF(K52<=L52,"CAPACITY","QUOTA") | O52: =IF(K52<=0,"RESERVATION_DEFICIT",IF(L52<=0,"QUOTA_DEFICIT",IF(M52<I52*0.5,"READY_WITH_RISK","READY")))
A53: Canada Central | B53: US | C53: Prod | D53: Standard_E32ads_v5 | E53: =VLOOKUP(D53,SKU_Family_Map!$A:$B,2,FALSE) | F53: crg-pr-cac-reg | G53: 32 | H53: 949 | I53: 114 | J53: =H53+I53 | K53: =J53-H53 | L53: =SUMIFS(Quota_Groups!$G:$G,Quota_Groups!$B:$B,A53,Quota_Groups!$D:$D,E53) | M53: =MIN(K53,L53) | N53: =IF(K53<=L53,"CAPACITY","QUOTA") | O53: =IF(K53<=0,"RESERVATION_DEFICIT",IF(L53<=0,"QUOTA_DEFICIT",IF(M53<I53*0.5,"READY_WITH_RISK","READY"))) | P53: mock
A54: Canada Central | B54: US | C54: Prod | D54: Standard_E64ads_v5 | E54: =VLOOKUP(D54,SKU_Family_Map!$A:$B,2,FALSE) | F54: crg-pr-cac-reg | G54: 64 | H54: 1781 | I54: 214 | J54: =H54+I54 | K54: =J54-H54 | L54: =SUMIFS(Quota_Groups!$G:$G,Quota_Groups!$B:$B,A54,Quota_Groups!$D:$D,E54) | M54: =MIN(K54,L54) | N54: =IF(K54<=L54,"CAPACITY","QUOTA") | O54: =IF(K54<=0,"RESERVATION_DEFICIT",IF(L54<=0,"QUOTA_DEFICIT",IF(M54<I54*0.5,"READY_WITH_RISK","READY"))) | P54: mock
A55: Canada Central | B55: US | C55: Prod | D55: Standard_E16ads_v5 | E55: =VLOOKUP(D55,SKU_Family_Map!$A:$B,2,FALSE) | F55: crg-pr-cac-reg | G55: 16 | H55: 1208 | I55: 145 | J55: =H55+I55 | K55: =J55-H55 | L55: =SUMIFS(Quota_Groups!$G:$G,Quota_Groups!$B:$B,A55,Quota_Groups!$D:$D,E55) | M55: =MIN(K55,L55) | N55: =IF(K55<=L55,"CAPACITY","QUOTA") | O55: =IF(K55<=0,"RESERVATION_DEFICIT",IF(L55<=0,"QUOTA_DEFICIT",IF(M55<I55*0.5,"READY_WITH_RISK","READY"))) | P55: mock
A56: Canada Central | B56: US | C56: Prod | D56: Standard_E32ads_v6 | E56: =VLOOKUP(D56,SKU_Family_Map!$A:$B,2,FALSE) | F56: crg-pr-cac-reg | G56: 32 | H56: 3925 | I56: 471 | J56: =H56+I56 | K56: =J56-H56 | L56: =SUMIFS(Quota_Groups!$G:$G,Quota_Groups!$B:$B,A56,Quota_Groups!$D:$D,E56) | M56: =MIN(K56,L56) | N56: =IF(K56<=L56,"CAPACITY","QUOTA") | O56: =IF(K56<=0,"RESERVATION_DEFICIT",IF(L56<=0,"QUOTA_DEFICIT",IF(M56<I56*0.5,"READY_WITH_RISK","READY"))) | P56: mock
A57: Canada Central | B57: US | C57: Prod | D57: Standard_D8ads_v5 | E57: =VLOOKUP(D57,SKU_Family_Map!$A:$B,2,FALSE) | F57: crg-pr-cac-reg | G57: 8 | H57: 1891 | I57: 227 | J57: =H57+I57 | K57: =J57-H57 | L57: =SUMIFS(Quota_Groups!$G:$G,Quota_Groups!$B:$B,A57,Quota_Groups!$D:$D,E57) | M57: =MIN(K57,L57) | N57: =IF(K57<=L57,"CAPACITY","QUOTA") | O57: =IF(K57<=0,"RESERVATION_DEFICIT",IF(L57<=0,"QUOTA_DEFICIT",IF(M57<I57*0.5,"READY_WITH_RISK","READY"))) | P57: mock
A58: Canada Central | B58: US | C58: Prod | D58: Standard_D16ads_v5 | E58: =VLOOKUP(D58,SKU_Family_Map!$A:$B,2,FALSE) | F58: crg-pr-cac-reg | G58: 16 | H58: 1144 | I58: 137 | J58: =H58+I58 | K58: =J58-H58 | L58: =SUMIFS(Quota_Groups!$G:$G,Quota_Groups!$B:$B,A58,Quota_Groups!$D:$D,E58) | M58: =MIN(K58,L58) | N58: =IF(K58<=L58,"CAPACITY","QUOTA") | O58: =IF(K58<=0,"RESERVATION_DEFICIT",IF(L58<=0,"QUOTA_DEFICIT",IF(M58<I58*0.5,"READY_WITH_RISK","READY"))) | P58: mock
A59: Canada Central | B59: US | C59: Prod | D59: Standard_D8as_v5 | E59: =VLOOKUP(D59,SKU_Family_Map!$A:$B,2,FALSE) | F59: crg-pr-cac-reg | G59: 8 | H59: 2507 | I59: 301 | J59: =H59+I59 | K59: =J59-H59 | L59: =SUMIFS(Quota_Groups!$G:$G,Quota_Groups!$B:$B,A59,Quota_Groups!$D:$D,E59) | M59: =MIN(K59,L59) | N59: =IF(K59<=L59,"CAPACITY","QUOTA") | O59: =IF(K59<=0,"RESERVATION_DEFICIT",IF(L59<=0,"QUOTA_DEFICIT",IF(M59<I59*0.5,"READY_WITH_RISK","READY"))) | P59: mock
A60: Canada Central | B60: US | C60: Prod | D60: Standard_D16as_v5 | E60: =VLOOKUP(D60,SKU_Family_Map!$A:$B,2,FALSE) | F60: crg-pr-cac-reg | G60: 16 | H60: 1624 | I60: 195 | J60: =H60+I60 | K60: =J60-H60 | L60: =SUMIFS(Quota_Groups!$G:$G,Quota_Groups!$B:$B,A60,Quota_Groups!$D:$D,E60) | M60: =MIN(K60,L60) | N60: =IF(K60<=L60,"CAPACITY","QUOTA") | O60: =IF(K60<=0,"RESERVATION_DEFICIT",IF(L60<=0,"QUOTA_DEFICIT",IF(M60<I60*0.5,"READY_WITH_RISK","READY"))) | P60: mock
A61: Canada Central | B61: US | C61: NonProd | D61: Standard_E32ads_v5 | E61: =VLOOKUP(D61,SKU_Family_Map!$A:$B,2,FALSE) | F61: crg-np-cac-reg | G61: 32 | H61: 14245 | I61: 1709 | J61: =H61+I61 | K61: =J61-H61 | L61: =SUMIFS(Quota_Groups!$G:$G,Quota_Groups!$B:$B,A61,Quota_Groups!$D:$D,E61) | M61: =MIN(K61,L61) | N61: =IF(K61<=L61,"CAPACITY","QUOTA") | O61: =IF(K61<=0,"RESERVATION_DEFICIT",IF(L61<=0,"QUOTA_DEFICIT",IF(M61<I61*0.5,"READY_WITH_RISK","READY"))) | P61: mock
A62: Canada Central | B62: US | C62: NonProd | D62: Standard_E64ads_v5 | E62: =VLOOKUP(D62,SKU_Family_Map!$A:$B,2,FALSE) | F62: crg-np-cac-reg | G62: 64 | H62: 8832 | I62: 1060 | J62: =H62+I62 | K62: =J62-H62 | L62: =SUMIFS(Quota_Groups!$G:$G,Quota_Groups!$B:$B,A62,Quota_Groups!$D:$D,E62) | M62: =MIN(K62,L62) | N62: =IF(K62<=L62,"CAPACITY","QUOTA") | O62: =IF(K62<=0,"RESERVATION_DEFICIT",IF(L62<=0,"QUOTA_DEFICIT",IF(M62<I62*0.5,"READY_WITH_RISK","READY"))) | P62: mock
A63: Canada Central | B63: US | C63: NonProd | D63: Standard_E16ads_v5 | E63: =VLOOKUP(D63,SKU_Family_Map!$A:$B,2,FALSE) | F63: crg-np-cac-reg | G63: 16 | H63: 3059 | I63: 367 | J63: =H63+I63 | K63: =J63-H63 | L63: =SUMIFS(Quota_Groups!$G:$G,Quota_Groups!$B:$B,A63,Quota_Groups!$D:$D,E63) | M63: =MIN(K63,L63) | N63: =IF(K63<=L63,"CAPACITY","QUOTA") | O63: =IF(K63<=0,"RESERVATION_DEFICIT",IF(L63<=0,"QUOTA_DEFICIT",IF(M63<I63*0.5,"READY_WITH_RISK","READY"))) | P63: mock
A64: Canada Central | B64: US | C64: NonProd | D64: Standard_E32ads_v6 | E64: =VLOOKUP(D64,SKU_Family_Map!$A:$B,2,FALSE) | F64: crg-np-cac-reg | G64: 32 | H64: 2987 | I64: 358 | J64: =H64+I64 | K64: =J64-H64 | L64: =SUMIFS(Quota_Groups!$G:$G,Quota_Groups!$B:$B,A64,Quota_Groups!$D:$D,E64) | M64: =MIN(K64,L64) | N64: =IF(K64<=L64,"CAPACITY","QUOTA") | O64: =IF(K64<=0,"RESERVATION_DEFICIT",IF(L64<=0,"QUOTA_DEFICIT",IF(M64<I64*0.5,"READY_WITH_RISK","READY"))) | P64: mock
... A76: Canada Central | B76: US | C76: DR | D76: Standard_D16as_v5 | E76: =VLOOKUP(D76,SKU_Family_Map!$A:$B,2,FALSE) | F76: crg-dr-cac-reg | G76: 16 | H76: 487 | I76: 58 | J76: =H76+I76 | K76: =J76-H76 | L76: =SUMIFS(Quota_Groups!$G:$G,Quota_Groups!$B:$B,A76,Quota_Groups!$D:$D,E76) | M76: =MIN(K76,L76) | N76: =IF(K76<=L76,"CAPACITY","QUOTA") | O76: =IF(K76<=0,"RESERVATION_DEFICIT",IF(L76<=0,"QUOTA_DEFICIT",IF(M76<I76*0.5,"READY_WITH_RISK","READY"))) | P76: mock
A77: East US 2 | B77: US | C77: Prod | D77: Standard_E32ads_v5 | E77: =VLOOKUP(D77,SKU_Family_Map!$A:$B,2,FALSE) | F77: crg-pr-eus2-reg | G77: 32 | H77: 5696 | I77: 684 | J77: =H77+I77 | K77: =J77-H77 | L77: =SUMIFS(Quota_Groups!$G:$G,Quota_Groups!$B:$B,A77,Quota_Groups!$D:$D,E77) | M77: =MIN(K77,L77) | N77: =IF(K77<=L77,"CAPACITY","QUOTA") | O77: =IF(K77<=0,"RESERVATION_DEFICIT",IF(L77<=0,"QUOTA_DEFICIT",IF(M77<I77*0.5,"READY_WITH_RISK","READY")))
A78: East US 2 | B78: US | C78: Prod | D78: Standard_E64ads_v5 | E78: =VLOOKUP(D78,SKU_Family_Map!$A:$B,2,FALSE) | F78: crg-pr-eus2-reg | G78: 64 | H78: 10688 | I78: 1283 | J78: =H78+I78 | K78: =J78-H78 | L78: =SUMIFS(Quota_Groups!$G:$G,Quota_Groups!$B:$B,A78,Quota_Groups!$D:$D,E78) | M78: =MIN(K78,L78) | N78: =IF(K78<=L78,"CAPACITY","QUOTA") | O78: =IF(K78<=0,"RESERVATION_DEFICIT",IF(L78<=0,"QUOTA_DEFICIT",IF(M78<I78*0.5,"READY_WITH_RISK","READY")))
A79: East US 2 | B79: US | C79: Prod | D79: Standard_E16ads_v5 | E79: =VLOOKUP(D79,SKU_Family_Map!$A:$B,2,FALSE) | F79: crg-pr-eus2-reg | G79: 16 | H79: 7152 | I79: 858 | J79: =H79+I79 | K79: =J79-H79 | L79: =SUMIFS(Quota_Groups!$G:$G,Quota_Groups!$B:$B,A79,Quota_Groups!$D:$D,E79) | M79: =MIN(K79,L79) | N79: =IF(K79<=L79,"CAPACITY","QUOTA") | O79: =IF(K79<=0,"RESERVATION_DEFICIT",IF(L79<=0,"QUOTA_DEFICIT",IF(M79<I79*0.5,"READY_WITH_RISK","READY")))
A80: East US 2 | B80: US | C80: Prod | D80: Standard_E32ads_v6 | E80: =VLOOKUP(D80,SKU_Family_Map!$A:$B,2,FALSE) | F80: crg-pr-eus2-reg | G80: 32 | H80: 23040 | I80: 2765 | J80: =H80+I80 | K80: =J80-H80 | L80: =SUMIFS(Quota_Groups!$G:$G,Quota_Groups!$B:$B,A80,Quota_Groups!$D:$D,E80) | M80: =MIN(K80,L80) | N80: =IF(K80<=L80,"CAPACITY","QUOTA") | O80: =IF(K80<=0,"RESERVATION_DEFICIT",IF(L80<=0,"QUOTA_DEFICIT",IF(M80<I80*0.5,"READY_WITH_RISK","READY")))
A81: East US 2 | B81: US | C81: Prod | D81: Standard_D8ads_v5 | E81: =VLOOKUP(D81,SKU_Family_Map!$A:$B,2,FALSE) | F81: crg-pr-eus2-reg | G81: 8 | H81: 10928 | I81: 1311 | J81: =H81+I81 | K81: =J81-H81 | L81: =SUMIFS(Quota_Groups!$G:$G,Quota_Groups!$B:$B,A81,Quota_Groups!$D:$D,E81) | M81: =MIN(K81,L81) | N81: =IF(K81<=L81,"CAPACITY","QUOTA") | O81: =IF(K81<=0,"RESERVATION_DEFICIT",IF(L81<=0,"QUOTA_DEFICIT",IF(M81<I81*0.5,"READY_WITH_RISK","READY")))
A82: East US 2 | B82: US | C82: Prod | D82: Standard_D16ads_v5 | E82: =VLOOKUP(D82,SKU_Family_Map!$A:$B,2,FALSE) | F82: crg-pr-eus2-reg | G82: 16 | H82: 6752 | I82: 810 | J82: =H82+I82 | K82: =J82-H82 | L82: =SUMIFS(Quota_Groups!$G:$G,Quota_Groups!$B:$B,A82,Quota_Groups!$D:$D,E82) | M82: =MIN(K82,L82) | N82: =IF(K82<=L82,"CAPACITY","QUOTA") | O82: =IF(K82<=0,"RESERVATION_DEFICIT",IF(L82<=0,"QUOTA_DEFICIT",IF(M82<I82*0.5,"READY_WITH_RISK","READY")))
A83: East US 2 | B83: US | C83: Prod | D83: Standard_D8as_v5 | E83: =VLOOKUP(D83,SKU_Family_Map!$A:$B,2,FALSE) | F83: crg-pr-eus2-reg | G83: 8 | H83: 9928 | I83: 1191 | J83: =H83+I83 | K83: =J83-H83 | L83: =SUMIFS(Quota_Groups!$G:$G,Quota_Groups!$B:$B,A83,Quota_Groups!$D:$D,E83) | M83: =MIN(K83,L83) | N83: =IF(K83<=L83,"CAPACITY","QUOTA") | O83: =IF(K83<=0,"RESERVATION_DEFICIT",IF(L83<=0,"QUOTA_DEFICIT",IF(M83<I83*0.5,"READY_WITH_RISK","READY")))
A84: East US 2 | B84: US | C84: Prod | D84: Standard_D16as_v5 | E84: =VLOOKUP(D84,SKU_Family_Map!$A:$B,2,FALSE) | F84: crg-pr-eus2-reg | G84: 16 | H84: 5392 | I84: 647 | J84: =H84+I84 | K84: =J84-H84 | L84: =SUMIFS(Quota_Groups!$G:$G,Quota_Groups!$B:$B,A84,Quota_Groups!$D:$D,E84) | M84: =MIN(K84,L84) | N84: =IF(K84<=L84,"CAPACITY","QUOTA") | O84: =IF(K84<=0,"RESERVATION_DEFICIT",IF(L84<=0,"QUOTA_DEFICIT",IF(M84<I84*0.5,"READY_WITH_RISK","READY")))
A85: East US 2 | B85: US | C85: NonProd | D85: Standard_E32ads_v5 | E85: =VLOOKUP(D85,SKU_Family_Map!$A:$B,2,FALSE) | F85: crg-np-eus2-reg | G85: 32 | H85: 80224 | I85: 9627 | J85: =H85+I85 | K85: =J85-H85 | L85: =SUMIFS(Quota_Groups!$G:$G,Quota_Groups!$B:$B,A85,Quota_Groups!$D:$D,E85) | M85: =MIN(K85,L85) | N85: =IF(K85<=L85,"CAPACITY","QUOTA") | O85: =IF(K85<=0,"RESERVATION_DEFICIT",IF(L85<=0,"QUOTA_DEFICIT",IF(M85<I85*0.5,"READY_WITH_RISK","READY")))
A86: East US 2 | B86: US | C86: NonProd | D86: Standard_E64ads_v5 | E86: =VLOOKUP(D86,SKU_Family_Map!$A:$B,2,FALSE) | F86: crg-np-eus2-reg | G86: 64 | H86: 52608 | I86: 6313 | J86: =H86+I86 | K86: =J86-H86 | L86: =SUMIFS(Quota_Groups!$G:$G,Quota_Groups!$B:$B,A86,Quota_Groups!$D:$D,E86) | M86: =MIN(K86,L86) | N86: =IF(K86<=L86,"CAPACITY","QUOTA") | O86: =IF(K86<=0,"RESERVATION_DEFICIT",IF(L86<=0,"QUOTA_DEFICIT",IF(M86<I86*0.5,"READY_WITH_RISK","READY")))
...

Sheet Quota_Groups
A1: QUOTA GROUPS — ONE pooled group per Region x Family (QUA-002/003/004)
A2: Quota plane. ONE governed group per region+family, POOLED across Prod+NonProd+DR (QUA-004); hoarded, distributed on demand (QUA-003).
A3: Quota Group | B3: Region | C3: Geography | D3: Quota Family | E3: Group Limit (pooled) | F3: Group Used (all envs) | G3: Group Available | H3: Hoarded Contrib | I3: Pending Increase | J3: Notes
A4: qg-wus3-eadsv5 | B4: West US 3 | C4: US | D4: Eadsv5 | E4: 0 | F4: =SUMIFS(Capacity_By_SKU!$H:$H,Capacity_By_SKU!$A:$A,B4,Capacity_By_SKU!$E:$E,D4) | G4: =E4-F4 | H4: 0 | I4: 0
A5: qg-wus3-eadsv6 | B5: West US 3 | C5: US | D5: Eadsv6 | E5: 0 | F5: =SUMIFS(Capacity_By_SKU!$H:$H,Capacity_By_SKU!$A:$A,B5,Capacity_By_SKU!$E:$E,D5) | G5: =E5-F5 | H5: 0 | I5: 0
A6: qg-wus3-dadsv5 | B6: West US 3 | C6: US | D6: Dadsv5 | E6: 0 | F6: =SUMIFS(Capacity_By_SKU!$H:$H,Capacity_By_SKU!$A:$A,B6,Capacity_By_SKU!$E:$E,D6) | G6: =E6-F6 | H6: 0 | I6: 0
A7: qg-wus3-dasv5 | B7: West US 3 | C7: US | D7: Dasv5 | E7: 0 | F7: =SUMIFS(Capacity_By_SKU!$H:$H,Capacity_By_SKU!$A:$A,B7,Capacity_By_SKU!$E:$E,D7) | G7: =E7-F7 | H7: 0 | I7: 0
A8: qg-cus-eadsv5 | B8: Central US | C8: US | D8: Eadsv5 | E8: 11505 | F8: =SUMIFS(Capacity_By_SKU!$H:$H,Capacity_By_SKU!$A:$A,B8,Capacity_By_SKU!$E:$E,D8) | G8: =E8-F8 | H8: 1150 | I8: 0
A9: qg-cus-eadsv6 | B9: Central US | C9: US | D9: Eadsv6 | E9: 1208 | F9: =SUMIFS(Capacity_By_SKU!$H:$H,Capacity_By_SKU!$A:$A,B9,Capacity_By_SKU!$E:$E,D9) | G9: =E9-F9 | H9: 121 | I9: 0
A10: qg-cus-dadsv5 | B10: Central US | C10: US | D10: Dadsv5 | E10: 6199 | F10: =SUMIFS(Capacity_By_SKU!$H:$H,Capacity_By_SKU!$A:$A,B10,Capacity_By_SKU!$E:$E,D10) | G10: =E10-F10 | H10: 620 | I10: 0
A11: qg-cus-dasv5 | B11: Central US | C11: US | D11: Dasv5 | E11: 19012 | F11: =SUMIFS(Capacity_By_SKU!$H:$H,Capacity_By_SKU!$A:$A,B11,Capacity_By_SKU!$E:$E,D11) | G11: =E11-F11 | H11: 1901 | I11: 0
A12: qg-cac-eadsv5 | B12: Canada Central | C12: US | D12: Eadsv5 | E12: 32818 | F12: =SUMIFS(Capacity_By_SKU!$H:$H,Capacity_By_SKU!$A:$A,B12,Capacity_By_SKU!$E:$E,D12) | G12: =E12-F12 | H12: 3282 | I12: 0 | J12: mock
A13: qg-cac-eadsv6 | B13: Canada Central | C13: US | D13: Eadsv6 | E13: 9304 | F13: =SUMIFS(Capacity_By_SKU!$H:$H,Capacity_By_SKU!$A:$A,B13,Capacity_By_SKU!$E:$E,D13) | G13: =E13-F13 | H13: 930 | I13: 0 | J13: mock
A14: qg-cac-dadsv5 | B14: Canada Central | C14: US | D14: Dadsv5 | E14: 10574 | F14: =SUMIFS(Capacity_By_SKU!$H:$H,Capacity_By_SKU!$A:$A,B14,Capacity_By_SKU!$E:$E,D14) | G14: =E14-F14 | H14: 1057 | I14: 0 | J14: mock
A15: qg-cac-dasv5 | B15: Canada Central | C15: US | D15: Dasv5 | E15: 11567 | F15: =SUMIFS(Capacity_By_SKU!$H:$H,Capacity_By_SKU!$A:$A,B15,Capacity_By_SKU!$E:$E,D15) | G15: =E15-F15 | H15: 1157 | I15: 0 | J15: mock
A16: qg-eus2-eadsv5 | B16: East US 2 | C16: US | D16: Eadsv5 | E16: 185410 | F16: =SUMIFS(Capacity_By_SKU!$H:$H,Capacity_By_SKU!$A:$A,B16,Capacity_By_SKU!$E:$E,D16) | G16: =E16-F16 | H16: 18541 | I16: 0
A17: qg-eus2-eadsv6 | B17: East US 2 | C17: US | D17: Eadsv6 | E17: 54611 | F17: =SUMIFS(Capacity_By_SKU!$H:$H,Capacity_By_SKU!$A:$A,B17,Capacity_By_SKU!$E:$E,D17) | G17: =E17-F17 | H17: 5461 | I17: 0
A18: qg-eus2-dadsv5 | B18: East US 2 | C18: US | D18: Dadsv5 | E18: 57240 | F18: =SUMIFS(Capacity_By_SKU!$H:$H,Capacity_By_SKU!$A:$A,B18,Capacity_By_SKU!$E:$E,D18) | G18: =E18-F18 | H18: 5724 | I18: 0
A19: qg-eus2-dasv5 | B19: East US 2 | C19: US | D19: Dasv5 | E19: 50385 | F19: =SUMIFS(Capacity_By_SKU!$H:$H,Capacity_By_SKU!$A:$A,B19,Capacity_By_SKU!$E:$E,D19) | G19: =E19-F19 | H19: 5038 | I19: 0
A20: qg-chn-eadsv5 | B20: Switzerland North | C20: EU | D20: Eadsv5 | E20: 0 | F20: =SUMIFS(Capacity_By_SKU!$H:$H,Capacity_By_SKU!$A:$A,B20,Capacity_By_SKU!$E:$E,D20) | G20: =E20-F20 | H20: 0 | I20: 0
A21: qg-chn-eadsv6 | B21: Switzerland North | C21: EU | D21: Eadsv6 | E21: 1524 | F21: =SUMIFS(Capacity_By_SKU!$H:$H,Capacity_By_SKU!$A:$A,B21,Capacity_By_SKU!$E:$E,D21) | G21: =E21-F21 | H21: 152 | I21: 0
A22: qg-chn-dadsv5 | B22: Switzerland North | C22: EU | D22: Dadsv5 | E22: 0 | F22: =SUMIFS(Capacity_By_SKU!$H:$H,Capacity_By_SKU!$A:$A,B22,Capacity_By_SKU!$E:$E,D22) | G22: =E22-F22 | H22: 0 | I22: 0
A23: qg-chn-dasv5 | B23: Switzerland North | C23: EU | D23: Dasv5 | E23: 0 | F23: =SUMIFS(Capacity_By_SKU!$H:$H,Capacity_By_SKU!$A:$A,B23,Capacity_By_SKU!$E:$E,D23) | G23: =E23-F23 | H23: 0 | I23: 0
A24: qg-sec-eadsv5 | B24: Sweden Central | C24: EU | D24: Eadsv5 | E24: 386 | F24: =SUMIFS(Capacity_By_SKU!$H:$H,Capacity_By_SKU!$A:$A,B24,Capacity_By_SKU!$E:$E,D24) | G24: =E24-F24 | H24: 39 | I24: 0
A25: qg-sec-eadsv6 | B25: Sweden Central | C25: EU | D25: Eadsv6 | E25: 2031 | F25: =SUMIFS(Capacity_By_SKU!$H:$H,Capacity_By_SKU!$A:$A,B25,Capacity_By_SKU!$E:$E,D25) | G25: =E25-F25 | H25: 203 | I25: 0
A26: qg-sec-dadsv5 | B26: Sweden Central | C26: EU | D26: Dadsv5 | E26: 0 | F26: =SUMIFS(Capacity_By_SKU!$H:$H,Capacity_By_SKU!$A:$A,B26,Capacity_By_SKU!$E:$E,D26) | G26: =E26-F26 | H26: 0 | I26: 0
A27: qg-sec-dasv5 | B27: Sweden Central | C27: EU | D27: Dasv5 | E27: 0 | F27: =SUMIFS(Capacity_By_SKU!$H:$H,Capacity_By_SKU!$A:$A,B27,Capacity_By_SKU!$E:$E,D27) | G27: =E27-F27 | H27: 0 | I27: 0
... A35: qg-weu-dasv5 | B35: West Europe | C35: EU | D35: Dasv5 | E35: 15048 | F35: =SUMIFS(Capacity_By_SKU!$H:$H,Capacity_By_SKU!$A:$A,B35,Capacity_By_SKU!$E:$E,D35) | G35: =E35-F35 | H35: 1505 | I35: 0

Sheet Score_Prod
A1: SCORE_PROD — SKU-grain placement score (Production) | Q1: TOP PICK
A2: Meets-All = 1 only when EVERY active SKU line has GROUP AVAIL ≥ Line Cores. Alpha=MIN(1−cores/GAVAIL), Beta=MIN(quota-avail/quota-limit), Eps=MIN(res-free/res) across all active lines. | Q2: Region | R2: =IFERROR(INDEX($A$4:$A$11,MATCH(1,$N$4:$N$11,0)),"NONE ELIGIBLE")
A3: Region | B3: Geo | C3: Env | D3: Active Lines | E3: Total Req Cores | F3: InGeo | G3: Meets-All | H3: Readiness (RDY-002) | I3: Eligible | J3: alpha_c | K3: beta_c | L3: eps_c | M3: PS | N3: Rank | O3: Binding | Q3: PS | R3: =IFERROR(INDEX($M$4:$M$11,MATCH(1,$N$4:$N$11,0)),"")
A4: West US 3 | B4: US | C4: Prod | D4: =Request!$B$17 | E4: =Request!$B$18 | F4: =IF(B4=Request!$B$4,1,0) | G4: =IF(Request!$B$17=0,0,MIN(IF(OR(Request!$B$8="",Request!$C$8=""),1,IF(MIN(SUMIFS(Capacity_By_SKU!$K:$K,Capacity_By_SKU!$A:$A,$A4,Capacity_By_SKU!$C:$C,"Prod",Capacity_By_SKU!$D:$D,Request!$B$8),SUMIFS(Quota_Groups!$G:$G,Quota_Groups!$B:$B,$A4,Quota_Groups!$D:$D,IFERROR(VLOOKUP(Request!$B$8,SKU_Family_Map!$A:$B,2,FALSE),"")))>=Request!$E$8,1,0)),IF(OR(Request!$B$9="",Request!$C$9=""),1,IF(MIN(SUMIFS(Capacity_By_SKU!$K:$K,Capacity_By_SKU!$A:$A,$A4,Capacity_By_SKU!$C:$C,"Prod",Capacity_By_SKU!$D:$D,Request!$B$9),SUMIFS(Quota_Groups!$G:$G,Quota_Groups!$B:$B,$A4,Quota_Groups!$D:$D,IFERROR(VLOOKUP(Request!$B$9,SKU_Family_Map!$A:$B,2,FALSE),"")))>=Request!$E$9,1,0)),IF(OR(Request!$B$10="",Request!$C$10=""),1,IF(MIN(SUMIFS(Capacity_By_SKU!$K:$K,Capacity_By_SKU!$A:$A,$A4,Capacity_By_SKU!$C:$C,"Prod",Capacity_By_SKU!$D:$D,Request!$B$10),SUMIFS(Quota_Groups!$G:$G,Quota_Groups!$B:$B,$A4,Quota_Groups!$D:$D,IFERROR(VLOOKUP(Request!$B$10,SKU_Family_Map!$A:$B,2,FALSE),"")))>=Request!$E$10,1,0)),IF(OR(Request!$B$11="",Request!$C$11=""),1,IF(MIN(SUMIFS(Capacity_By_SKU!$K:$K,Capacity_By_SKU!$A:$A,$A4,Capacity_By_SKU!$C:$C,"Prod",Capacity_By_SKU!$D:$D,Request!$B$11),SUMIFS(Quota_Groups!$G:$G,Quota_Groups!$B:$B,$A4,Quota_Groups!$D:$D,IFERROR(VLOOKUP(Request!$B$11,SKU_Family_Map!$A:$B,2,FALSE),"")))>=Request!$E$11,1,0)),IF(OR(Request!$B$12="",Request!$C$12=""),1,IF(MIN(SUMIFS(Capacity_By_SKU!$K:$K,Capacity_By_SKU!$A:$A,$A4,Capacity_By_SKU!$C:$C,"Prod",Capacity_By_SKU!$D:$D,Request!$B$12),SUMIFS(Quota_Groups!$G:$G,Quota_Groups!$B:$B,$A4,Quota_Groups!$D:$D,IFERROR(VLOOKUP(Request!$B$12,SKU_Family_Map!$A:$B,2,FALSE),"")))>=Request!$E$12,1,0)),IF(OR(Request!$B$13="",Request!$C$13=""),1,IF(MIN(SUMIFS(Capacity_By_SKU!$K:$K,Capacity_By_SKU!$A:$A,$A4,Capacity_By_SKU!$C:$C,"Prod",Capacity_By_SKU!$D:$D,Request!$B$13),SUMIFS(Quota_Groups!$G:$G,Quota_Groups!$B:$B,$A4,Quota_Groups!$D:$D,IFERROR(VLOOKUP(Request!$B$13,SKU_Family_Map!$A:$B,2,FALSE),"")))>=Request!$E$13,1,0)),IF(OR(Request!$B$14="",Request!$C$14=""),1,IF(MIN(SUMIFS(Capacity_By_SKU!$K:$K,Capacity_By_SKU!$A:$A,$A4,Capacity_By_SKU!$C:$C,"Prod",Capacity_By_SKU!$D:$D,Request!$B$14),SUMIFS(Quota_Groups!$G:$G,Quota_Groups!$B:$B,$A4,Quota_Groups!$D:$D,IFERROR(VLOOKUP(Request!$B$14,SKU_Family_Map!$A:$B,2,FALSE),"")))>=Request!$E$14,1,0)),IF(OR(Request!$B$15="",Request!$C$15=""),1,IF(MIN(SUMIFS(Capacity_By_SKU!$K:$K,Capacity_By_SKU!$A:$A,$A4,Capacity_By_SKU!$C:$C,"Prod",Capacity_By_SKU!$D:$D,Request!$B$15),SUMIFS(Quota_Groups!$G:$G,Quota_Groups!$B:$B,$A4,Quota_Groups!$D:$D,IFERROR(VLOOKUP(Request!$B$15,SKU_Family_Map!$A:$B,2,FALSE),"")))>=Request!$E$15,1,0)))) | H4: =IF(Request!$B$17=0,"NO_REQUEST",IF(SUM(IF(AND(Request!$B$8<>"",Request!$C$8<>"",SUMIFS(Capacity_By_SKU!$K:$K,Capacity_By_SKU!$A:$A,$A4,Capacity_By_SKU!$C:$C,"Prod",Capacity_By_SKU!$D:$D,Request!$B$8)<=0),1,0),IF(AND(Request!$B$9<>"",Request!$C$9<>"",SUMIFS(Capacity_By_SKU!$K:$K,Capacity_By_SKU!$A:$A,$A4,Capacity_By_SKU!$C:$C,"Prod",Capacity_By_SKU!$D:$D,Request!$B$9)<=0),1,0),IF(AND(Request!$B$10<>"",Request!$C$10<>"",SUMIFS(Capacity_By_SKU!$K:$K,Capacity_By_SKU!$A:$A,$A4,Capacity_By_SKU!$C:$C,"Prod",Capacity_By_SKU!$D:$D,Request!$B$10)<=0),1,0),IF(AND(Request!$B$11<>"",Request!$C$11<>"",SUMIFS(Capacity_By_SKU!$K:$K,Capacity_By_SKU!$A:$A,$A4,Capacity_By_SKU!$C:$C,"Prod",Capacity_By_SKU!$D:$D,Request!$B$11)<=0),1,0),IF(AND(Request!$B$12<>"",Request!$C$12<>"",SUMIFS(Capacity_By_SKU!$K:$K,Capacity_By_SKU!$A:$A,$A4,Capacity_By_SKU!$C:$C,"Prod",Capacity_By_SKU!$D:$D,Request!$B$12)<=0),1,0),IF(AND(Request!$B$13<>"",Request!$C$13<>"",SUMIFS(Capacity_By_SKU!$K:$K,Capacity_By_SKU!$A:$A,$A4,Capacity_By_SKU!$C:$C,"Prod",Capacity_By_SKU!$D:$D,Request!$B$13)<=0),1,0),IF(AND(Request!$B$14<>"",Request!$C$14<>"",SUMIFS(Capacity_By_SKU!$K:$K,Capacity_By_SKU!$A:$A,$A4,Capacity_By_SKU!$C:$C,"Prod",Capacity_By_SKU!$D:$D,Request!$B$14)<=0),1,0),IF(AND(Request!$B$15<>"",Request!$C$15<>"",SUMIFS(Capacity_By_SKU!$K:$K,Capacity_By_SKU!$A:$A,$A4,Capacity_By_SKU!$C:$C,"Prod",Capacity_By_SKU!$D:$D,Request!$B$15)<=0),1,0))>0,"RESERVATION_DEFICIT",IF(SUM(IF(AND(Request!$B$8<>"",Request!$C$8<>"",SUMIFS(Quota_Groups!$G:$G,Quota_Groups!$B:$B,$A4,Quota_Groups!$D:$D,IFERROR(VLOOKUP(Request!$B$8,SKU_Family_Map!$A:$B,2,FALSE),""))<=0),1,0),IF(AND(Request!$B$9<>"",Request!$C$9<>"",SUMIFS(Quota_Groups!$G:$G,Quota_Groups!$B:$B,$A4,Quota_Groups!$D:$D,IFERROR(VLOOKUP(Request!$B$9,SKU_Family_Map!$A:$B,2,FALSE),""))<=0),1,0),IF(AND(Request!$B$10<>"",Request!$C$10<>"",SUMIFS(Quota_Groups!$G:$G,Quota_Groups!$B:$B,$A4,Quota_Groups!$D:$D,IFERROR(VLOOKUP(Request!$B$10,SKU_Family_Map!$A:$B,2,FALSE),""))<=0),1,0),IF(AND(Request!$B$11<>"",Request!$C$11<>"",SUMIFS(Quota_Groups!$G:$G,Quota_Groups!$B:$B,$A4,Quota_Groups!$D:$D,IFERROR(VLOOKUP(Request!$B$11,SKU_Family_Map!$A:$B,2,FALSE),""))<=0),1,0),IF(AND(Request!$B$12<>"",Request!$C$12<>"",SUMIFS(Quota_Groups!$G:$G,Quota_Groups!$B:$B,$A4,Quota_Groups!$D:$D,IFERROR(VLOOKUP(Request!$B$12,SKU_Family_Map!$A:$B,2,FALSE),""))<=0),1,0),IF(AND(Request!$B$13<>"",Request!$C$13<>"",SUMIFS(Quota_Groups!$G:$G,Quota_Groups!$B:$B,$A4,Quota_Groups!$D:$D,IFERROR(VLOOKUP(Request!$B$13,SKU_Family_Map!$A:$B,2,FALSE),""))<=0),1,0),IF(AND(Request!$B$14<>"",Request!$C$14<>"",SUMIFS(Quota_Groups!$G:$G,Quota_Groups!$B:$B,$A4,Quota_Groups!$D:$D,IFERROR(VLOOKUP(Request!$B$14,SKU_Family_Map!$A:$B,2,FALSE),""))<=0),1,0),IF(AND(Request!$B$15<>"",Request!$C$15<>"",SUMIFS(Quota_Groups!$G:$G,Quota_Groups!$B:$B,$A4,Quota_Groups!$D:$D,IFERROR(VLOOKUP(Request!$B$15,SKU_Family_Map!$A:$B,2,FALSE),""))<=0),1,0))>0,"QUOTA_DEFICIT",IF(G4=0,"CAPACITY_DEFICIT",IF(MIN(IF(OR(Request!$B$8="",Request!$C$8=""),1,IFERROR(1-Request!$E$8/MIN(SUMIFS(Capacity_By_SKU!$K:$K,Capacity_By_SKU!$A:$A,$A4,Capacity_By_SKU!$C:$C,"Prod",Capacity_By_SKU!$D:$D,Request!$B$8),SUMIFS(Quota_Groups!$G:$G,Quota_Groups!$B:$B,$A4,Quota_Groups!$D:$D,IFERROR(VLOOKUP(Request!$B$8,SKU_Family_Map!$A:$B,2,FALSE),""))),0)),IF(OR(Request!$B$9="",Request!$C$9=""),1,IFERROR(1-Request!$E$9/MIN(SUMIFS(Capacity_By_SKU!$K:$K,Capacity_By_SKU!$A:$A,$A4,Capacity_By_SKU!$C:$C,"Prod",Capacity_By_SKU!$D:$D,Request!$B$9),SUMIFS(Quota_Groups!$G:$G,Quota_Groups!$B:$B,$A4,Quota_Groups!$D:$D,IFERROR(VLOOKUP(Request!$B$9,SKU_Family_Map!$A:$B,2,FALSE),""))),0)),IF(OR(Request!$B$10="",Request!$C$10=""),1,IFERROR(1-Request!$E$10/MIN(SUMIFS(Capacity_By_SKU!$K:$K,Capacity_By_SKU!$A:$A,$A4,Capacity_By_SKU!$C:$C,"Prod",Capacity_By_SKU!$D:$D,Request!$B$10),SUMIFS(Quota_Groups!$G:$G,Quota_Groups!$B:$B,$A4,Quota_Groups!$D:$D,IFERROR(VLOOKUP(Request!$B$10,SKU_Family_Map!$A:$B,2,FALSE),""))),0)),IF(OR(Request!$B$11="",Request!$C$11=""),1,IFERROR(1-Request!$E$11/MIN(SUMIFS(Capacity_By_SKU!$K:$K,Capacity_By_SKU!$A:$A,$A4,Capacity_By_SKU!$C:$C,"Prod",Capacity_By_SKU!$D:$D,Request!$B$11),SUMIFS(Quota_Groups!$G:$G,Quota_Groups!$B:$B,$A4,Quota_Groups!$D:$D,IFERROR(VLOOKUP(Request!$B$11,SKU_Family_Map!$A:$B,2,FALSE),""))),0)),IF(OR(Request!$B$12="",Request!$C$12=""),1,IFERROR(1-Request!$E$12/MIN(SUMIFS(Capacity_By_SKU!$K:$K,Capacity_By_SKU!$A:$A,$A4,Capacity_By_SKU!$C:$C,"Prod",Capacity_By_SKU!$D:$D,Request!$B$12),SUMIFS(Quota_Groups!$G:$G,Quota_Groups!$B:$B,$A4,Quota_Groups!$D:$D,IFERROR(VLOOKUP(Request!$B$12,SKU_Family_Map!$A:$B,2,FALSE),""))),0)),IF(OR(Request!$B$13="",Request!$C$13=""),1,IFERROR(1-Request!$E$13/MIN(SUMIFS(Capacity_By_SKU!$K:$K,Capacity_By_SKU!$A:$A,$A4,Capacity_By_SKU!$C:$C,"Prod",Capacity_By_SKU!$D:$D,Request!$B$13),SUMIFS(Quota_Groups!$G:$G,Quota_Groups!$B:$B,$A4,Quota_Groups!$D:$D,IFERROR(VLOOKUP(Request!$B$13,SKU_Family_Map!$A:$B,2,FALSE),""))),0)),IF(OR(Request!$B$14="",Request!$C$14=""),1,IFERROR(1-Request!$E$14/MIN(SUMIFS(Capacity_By_SKU!$K:$K,Capacity_By_SKU!$A:$A,$A4,Capacity_By_SKU!$C:$C,"Prod",Capacity_By_SKU!$D:$D,Request!$B$14),SUMIFS(Quota_Groups!$G:$G,Quota_Groups!$B:$B,$A4,Quota_Groups!$D:$D,IFERROR(VLOOKUP(Request!$B$14,SKU_Family_Map!$A:$B,2,FALSE),""))),0)),IF(OR(Request!$B$15="",Request!$C$15=""),1,IFERROR(1-Request!$E$15/MIN(SUMIFS(Capacity_By_SKU!$K:$K,Capacity_By_SKU!$A:$A,$A4,Capacity_By_SKU!$C:$C,"Prod",Capacity_By_SKU!$D:$D,Request!$B$15),SUMIFS(Quota_Groups!$G:$G,Quota_Groups!$B:$B,$A4,Quota_Groups!$D:$D,IFERROR(VLOOKUP(Request!$B$15,SKU_Family_Map!$A:$B,2,FALSE),""))),0)))<Policy!$B$10,"READY_WITH_RISK","READY"))))) | I4: =IF(AND(F4=1,G4=1,OR(H4="READY",H4="READY_WITH_RISK")),1,0) | J4: =IF(I4=1,MAX(0,MIN(IF(OR(Request!$B$8="",Request!$C$8=""),1,IFERROR(1-Request!$E$8/MIN(SUMIFS(Capacity_By_SKU!$K:$K,Capacity_By_SKU!$A:$A,$A4,Capacity_By_SKU!$C:$C,"Prod",Capacity_By_SKU!$D:$D,Request!$B$8),SUMIFS(Quota_Groups!$G:$G,Quota_Groups!$B:$B,$A4,Quota_Groups!$D:$D,IFERROR(VLOOKUP(Request!$B$8,SKU_Family_Map!$A:$B,2,FALSE),""))),0)),IF(OR(Request!$B$9="",Request!$C$9=""),1,IFERROR(1-Request!$E$9/MIN(SUMIFS(Capacity_By_SKU!$K:$K,Capacity_By_SKU!$A:$A,$A4,Capacity_By_SKU!$C:$C,"Prod",Capacity_By_SKU!$D:$D,Request!$B$9),SUMIFS(Quota_Groups!$G:$G,Quota_Groups!$B:$B,$A4,Quota_Groups!$D:$D,IFERROR(VLOOKUP(Request!$B$9,SKU_Family_Map!$A:$B,2,FALSE),""))),0)),IF(OR(Request!$B$10="",Request!$C$10=""),1,IFERROR(1-Request!$E$10/MIN(SUMIFS(Capacity_By_SKU!$K:$K,Capacity_By_SKU!$A:$A,$A4,Capacity_By_SKU!$C:$C,"Prod",Capacity_By_SKU!$D:$D,Request!$B$10),SUMIFS(Quota_Groups!$G:$G,Quota_Groups!$B:$B,$A4,Quota_Groups!$D:$D,IFERROR(VLOOKUP(Request!$B$10,SKU_Family_Map!$A:$B,2,FALSE),""))),0)),IF(OR(Request!$B$11="",Request!$C$11=""),1,IFERROR(1-Request!$E$11/MIN(SUMIFS(Capacity_By_SKU!$K:$K,Capacity_By_SKU!$A:$A,$A4,Capacity_By_SKU!$C:$C,"Prod",Capacity_By_SKU!$D:$D,Request!$B$11),SUMIFS(Quota_Groups!$G:$G,Quota_Groups!$B:$B,$A4,Quota_Groups!$D:$D,IFERROR(VLOOKUP(Request!$B$11,SKU_Family_Map!$A:$B,2,FALSE),""))),0)),IF(OR(Request!$B$12="",Request!$C$12=""),1,IFERROR(1-Request!$E$12/MIN(SUMIFS(Capacity_By_SKU!$K:$K,Capacity_By_SKU!$A:$A,$A4,Capacity_By_SKU!$C:$C,"Prod",Capacity_By_SKU!$D:$D,Request!$B$12),SUMIFS(Quota_Groups!$G:$G,Quota_Groups!$B:$B,$A4,Quota_Groups!$D:$D,IFERROR(VLOOKUP(Request!$B$12,SKU_Family_Map!$A:$B,2,FALSE),""))),0)),IF(OR(Request!$B$13="",Request!$C$13=""),1,IFERROR(1-Request!$E$13/MIN(SUMIFS(Capacity_By_SKU!$K:$K,Capacity_By_SKU!$A:$A,$A4,Capacity_By_SKU!$C:$C,"Prod",Capacity_By_SKU!$D:$D,Request!$B$13),SUMIFS(Quota_Groups!$G:$G,Quota_Groups!$B:$B,$A4,Quota_Groups!$D:$D,IFERROR(VLOOKUP(Request!$B$13,SKU_Family_Map!$A:$B,2,FALSE),""))),0)),IF(OR(Request!$B$14="",Request!$C$14=""),1,IFERROR(1-Request!$E$14/MIN(SUMIFS(Capacity_By_SKU!$K:$K,Capacity_By_SKU!$A:$A,$A4,Capacity_By_SKU!$C:$C,"Prod",Capacity_By_SKU!$D:$D,Request!$B$14),SUMIFS(Quota_Groups!$G:$G,Quota_Groups!$B:$B,$A4,Quota_Groups!$D:$D,IFERROR(VLOOKUP(Request!$B$14,SKU_Family_Map!$A:$B,2,FALSE),""))),0)),IF(OR(Request!$B$15="",Request!$C$15=""),1,IFERROR(1-Request!$E$15/MIN(SUMIFS(Capacity_By_SKU!$K:$K,Capacity_By_SKU!$A:$A,$A4,Capacity_By_SKU!$C:$C,"Prod",Capacity_By_SKU!$D:$D,Request!$B$15),SUMIFS(Quota_Groups!$G:$G,Quota_Groups!$B:$B,$A4,Quota_Groups!$D:$D,IFERROR(VLOOKUP(Request!$B$15,SKU_Family_Map!$A:$B,2,FALSE),""))),0)))),0) | K4: =IF(I4=1,MAX(0,MIN(IF(OR(Request!$B$8="",Request!$C$8=""),1,IFERROR(SUMIFS(Quota_Groups!$G:$G,Quota_Groups!$B:$B,$A4,Quota_Groups!$D:$D,IFERROR(VLOOKUP(Request!$B$8,SKU_Family_Map!$A:$B,2,FALSE),""))/MAX(SUMIFS(Quota_Groups!$E:$E,Quota_Groups!$B:$B,$A4,Quota_Groups!$D:$D,IFERROR(VLOOKUP(Request!$B$8,SKU_Family_Map!$A:$B,2,FALSE),"")),1),0)),IF(OR(Request!$B$9="",Request!$C$9=""),1,IFERROR(SUMIFS(Quota_Groups!$G:$G,Quota_Groups!$B:$B,$A4,Quota_Groups!$D:$D,IFERROR(VLOOKUP(Request!$B$9,SKU_Family_Map!$A:$B,2,FALSE),""))/MAX(SUMIFS(Quota_Groups!$E:$E,Quota_Groups!$B:$B,$A4,Quota_Groups!$D:$D,IFERROR(VLOOKUP(Request!$B$9,SKU_Family_Map!$A:$B,2,FALSE),"")),1),0)),IF(OR(Request!$B$10="",Request!$C$10=""),1,IFERROR(SUMIFS(Quota_Groups!$G:$G,Quota_Groups!$B:$B,$A4,Quota_Groups!$D:$D,IFERROR(VLOOKUP(Request!$B$10,SKU_Family_Map!$A:$B,2,FALSE),""))/MAX(SUMIFS(Quota_Groups!$E:$E,Quota_Groups!$B:$B,$A4,Quota_Groups!$D:$D,IFERROR(VLOOKUP(Request!$B$10,SKU_Family_Map!$A:$B,2,FALSE),"")),1),0)),IF(OR(Request!$B$11="",Request!$C$11=""),1,IFERROR(SUMIFS(Quota_Groups!$G:$G,Quota_Groups!$B:$B,$A4,Quota_Groups!$D:$D,IFERROR(VLOOKUP(Request!$B$11,SKU_Family_Map!$A:$B,2,FALSE),""))/MAX(SUMIFS(Quota_Groups!$E:$E,Quota_Groups!$B:$B,$A4,Quota_Groups!$D:$D,IFERROR(VLOOKUP(Request!$B$11,SKU_Family_Map!$A:$B,2,FALSE),"")),1),0)),IF(OR(Request!$B$12="",Request!$C$12=""),1,IFERROR(SUMIFS(Quota_Groups!$G:$G,Quota_Groups!$B:$B,$A4,Quota_Groups!$D:$D,IFERROR(VLOOKUP(Request!$B$12,SKU_Family_Map!$A:$B,2,FALSE),""))/MAX(SUMIFS(Quota_Groups!$E:$E,Quota_Groups!$B:$B,$A4,Quota_Groups!$D:$D,IFERROR(VLOOKUP(Request!$B$12,SKU_Family_Map!$A:$B,2,FALSE),"")),1),0)),IF(OR(Request!$B$13="",Request!$C$13=""),1,IFERROR(SUMIFS(Quota_Groups!$G:$G,Quota_Groups!$B:$B,$A4,Quota_Groups!$D:$D,IFERROR(VLOOKUP(Request!$B$13,SKU_Family_Map!$A:$B,2,FALSE),""))/MAX(SUMIFS(Quota_Groups!$E:$E,Quota_Groups!$B:$B,$A4,Quota_Groups!$D:$D,IFERROR(VLOOKUP(Request!$B$13,SKU_Family_Map!$A:$B,2,FALSE),"")),1),0)),IF(OR(Request!$B$14="",Request!$C$14=""),1,IFERROR(SUMIFS(Quota_Groups!$G:$G,Quota_Groups!$B:$B,$A4,Quota_Groups!$D:$D,IFERROR(VLOOKUP(Request!$B$14,SKU_Family_Map!$A:$B,2,FALSE),""))/MAX(SUMIFS(Quota_Groups!$E:$E,Quota_Groups!$B:$B,$A4,Quota_Groups!$D:$D,IFERROR(VLOOKUP(Request!$B$14,SKU_Family_Map!$A:$B,2,FALSE),"")),1),0)),IF(OR(Request!$B$15="",Request!$C$15=""),1,IFERROR(SUMIFS(Quota_Groups!$G:$G,Quota_Groups!$B:$B,$A4,Quota_Groups!$D:$D,IFERROR(VLOOKUP(Request!$B$15,SKU_Family_Map!$A:$B,2,FALSE),""))/MAX(SUMIFS(Quota_Groups!$E:$E,Quota_Groups!$B:$B,$A4,Quota_Groups!$D:$D,IFERROR(VLOOKUP(Request!$B$15,SKU_Family_Map!$A:$B,2,FALSE),"")),1),0)))),0) | L4: =IF(I4=1,MAX(0,MIN(IF(OR(Request!$B$8="",Request!$C$8=""),1,IFERROR(SUMIFS(Capacity_By_SKU!$K:$K,Capacity_By_SKU!$A:$A,$A4,Capacity_By_SKU!$C:$C,"Prod",Capacity_By_SKU!$D:$D,Request!$B$8)/MAX(SUMIFS(Capacity_By_SKU!$J:$J,Capacity_By_SKU!$A:$A,$A4,Capacity_By_SKU!$C:$C,"Prod",Capacity_By_SKU!$D:$D,Request!$B$8),1),0)),IF(OR(Request!$B$9="",Request!$C$9=""),1,IFERROR(SUMIFS(Capacity_By_SKU!$K:$K,Capacity_By_SKU!$A:$A,$A4,Capacity_By_SKU!$C:$C,"Prod",Capacity_By_SKU!$D:$D,Request!$B$9)/MAX(SUMIFS(Capacity_By_SKU!$J:$J,Capacity_By_SKU!$A:$A,$A4,Capacity_By_SKU!$C:$C,"Prod",Capacity_By_SKU!$D:$D,Request!$B$9),1),0)),IF(OR(Request!$B$10="",Request!$C$10=""),1,IFERROR(SUMIFS(Capacity_By_SKU!$K:$K,Capacity_By_SKU!$A:$A,$A4,Capacity_By_SKU!$C:$C,"Prod",Capacity_By_SKU!$D:$D,Request!$B$10)/MAX(SUMIFS(Capacity_By_SKU!$J:$J,Capacity_By_SKU!$A:$A,$A4,Capacity_By_SKU!$C:$C,"Prod",Capacity_By_SKU!$D:$D,Request!$B$10),1),0)),IF(OR(Request!$B$11="",Request!$C$11=""),1,IFERROR(SUMIFS(Capacity_By_SKU!$K:$K,Capacity_By_SKU!$A:$A,$A4,Capacity_By_SKU!$C:$C,"Prod",Capacity_By_SKU!$D:$D,Request!$B$11)/MAX(SUMIFS(Capacity_By_SKU!$J:$J,Capacity_By_SKU!$A:$A,$A4,Capacity_By_SKU!$C:$C,"Prod",Capacity_By_SKU!$D:$D,Request!$B$11),1),0)),IF(OR(Request!$B$12="",Request!$C$12=""),1,IFERROR(SUMIFS(Capacity_By_SKU!$K:$K,Capacity_By_SKU!$A:$A,$A4,Capacity_By_SKU!$C:$C,"Prod",Capacity_By_SKU!$D:$D,Request!$B$12)/MAX(SUMIFS(Capacity_By_SKU!$J:$J,Capacity_By_SKU!$A:$A,$A4,Capacity_By_SKU!$C:$C,"Prod",Capacity_By_SKU!$D:$D,Request!$B$12),1),0)),IF(OR(Request!$B$13="",Request!$C$13=""),1,IFERROR(SUMIFS(Capacity_By_SKU!$K:$K,Capacity_By_SKU!$A:$A,$A4,Capacity_By_SKU!$C:$C,"Prod",Capacity_By_SKU!$D:$D,Request!$B$13)/MAX(SUMIFS(Capacity_By_SKU!$J:$J,Capacity_By_SKU!$A:$A,$A4,Capacity_By_SKU!$C:$C,"Prod",Capacity_By_SKU!$D:$D,Request!$B$13),1),0)),IF(OR(Request!$B$14="",Request!$C$14=""),1,IFERROR(SUMIFS(Capacity_By_SKU!$K:$K,Capacity_By_SKU!$A:$A,$A4,Capacity_By_SKU!$C:$C,"Prod",Capacity_By_SKU!$D:$D,Request!$B$14)/MAX(SUMIFS(Capacity_By_SKU!$J:$J,Capacity_By_SKU!$A:$A,$A4,Capacity_By_SKU!$C:$C,"Prod",Capacity_By_SKU!$D:$D,Request!$B$14),1),0)),IF(OR(Request!$B$15="",Request!$C$15=""),1,IFERROR(SUMIFS(Capacity_By_SKU!$K:$K,Capacity_By_SKU!$A:$A,$A4,Capacity_By_SKU!$C:$C,"Prod",Capacity_By_SKU!$D:$D,Request!$B$15)/MAX(SUMIFS(Capacity_By_SKU!$J:$J,Capacity_By_SKU!$A:$A,$A4,Capacity_By_SKU!$C:$C,"Prod",Capacity_By_SKU!$D:$D,Request!$B$15),1),0)))),0) | M4: =IF(I4=1,ROUND(Policy!$B$4*J4+Policy!$B$5*K4+Policy!$B$6*L4,4),"") | N4: =IF(I4=1,SUMPRODUCT(($I$4:$I$11=1)*($M$4:$M$11>M4))+1,"") | O4: =IF(I4=0,"N/A",IF(MIN(IF(OR(Request!$B$8="",Request!$C$8=""),1,IFERROR(SUMIFS(Capacity_By_SKU!$K:$K,Capacity_By_SKU!$A:$A,$A4,Capacity_By_SKU!$C:$C,"Prod",Capacity_By_SKU!$D:$D,Request!$B$8)/MAX(SUMIFS(Capacity_By_SKU!$J:$J,Capacity_By_SKU!$A:$A,$A4,Capacity_By_SKU!$C:$C,"Prod",Capacity_By_SKU!$D:$D,Request!$B$8),1),0)),IF(OR(Request!$B$9="",Request!$C$9=""),1,IFERROR(SUMIFS(Capacity_By_SKU!$K:$K,Capacity_By_SKU!$A:$A,$A4,Capacity_By_SKU!$C:$C,"Prod",Capacity_By_SKU!$D:$D,Request!$B$9)/MAX(SUMIFS(Capacity_By_SKU!$J:$J,Capacity_By_SKU!$A:$A,$A4,Capacity_By_SKU!$C:$C,"Prod",Capacity_By_SKU!$D:$D,Request!$B$9),1),0)),IF(OR(Request!$B$10="",Request!$C$10=""),1,IFERROR(SUMIFS(Capacity_By_SKU!$K:$K,Capacity_By_SKU!$A:$A,$A4,Capacity_By_SKU!$C:$C,"Prod",Capacity_By_SKU!$D:$D,Request!$B$10)/MAX(SUMIFS(Capacity_By_SKU!$J:$J,Capacity_By_SKU!$A:$A,$A4,Capacity_By_SKU!$C:$C,"Prod",Capacity_By_SKU!$D:$D,Request!$B$10),1),0)),IF(OR(Request!$B$11="",Request!$C$11=""),1,IFERROR(SUMIFS(Capacity_By_SKU!$K:$K,Capacity_By_SKU!$A:$A,$A4,Capacity_By_SKU!$C:$C,"Prod",Capacity_By_SKU!$D:$D,Request!$B$11)/MAX(SUMIFS(Capacity_By_SKU!$J:$J,Capacity_By_SKU!$A:$A,$A4,Capacity_By_SKU!$C:$C,"Prod",Capacity_By_SKU!$D:$D,Request!$B$11),1),0)),IF(OR(Request!$B$12="",Request!$C$12=""),1,IFERROR(SUMIFS(Capacity_By_SKU!$K:$K,Capacity_By_SKU!$A:$A,$A4,Capacity_By_SKU!$C:$C,"Prod",Capacity_By_SKU!$D:$D,Request!$B$12)/MAX(SUMIFS(Capacity_By_SKU!$J:$J,Capacity_By_SKU!$A:$A,$A4,Capacity_By_SKU!$C:$C,"Prod",Capacity_By_SKU!$D:$D,Request!$B$12),1),0)),IF(OR(Request!$B$13="",Request!$C$13=""),1,IFERROR(SUMIFS(Capacity_By_SKU!$K:$K,Capacity_By_SKU!$A:$A,$A4,Capacity_By_SKU!$C:$C,"Prod",Capacity_By_SKU!$D:$D,Request!$B$13)/MAX(SUMIFS(Capacity_By_SKU!$J:$J,Capacity_By_SKU!$A:$A,$A4,Capacity_By_SKU!$C:$C,"Prod",Capacity_By_SKU!$D:$D,Request!$B$13),1),0)),IF(OR(Request!$B$14="",Request!$C$14=""),1,IFERROR(SUMIFS(Capacity_By_SKU!$K:$K,Capacity_By_SKU!$A:$A,$A4,Capacity_By_SKU!$C:$C,"Prod",Capacity_By_SKU!$D:$D,Request!$B$14)/MAX(SUMIFS(Capacity_By_SKU!$J:$J,Capacity_By_SKU!$A:$A,$A4,Capacity_By_SKU!$C:$C,"Prod",Capacity_By_SKU!$D:$D,Request!$B$14),1),0)),IF(OR(Request!$B$15="",Request!$C$15=""),1,IFERROR(SUMIFS(Capacity_By_SKU!$K:$K,Capacity_By_SKU!$A:$A,$A4,Capacity_By_SKU!$C:$C,"Prod",Capacity_By_SKU!$D:$D,Request!$B$15)/MAX(SUMIFS(Capacity_By_SKU!$J:$J,Capacity_By_SKU!$A:$A,$A4,Capacity_By_SKU!$C:$C,"Prod",Capacity_By_SKU!$D:$D,Request!$B$15),1),0)))<=MIN(IF(OR(Request!$B$8="",Request!$C$8=""),1,IFERROR(SUMIFS(Quota_Groups!$G:$G,Quota_Groups!$B:$B,$A4,Quota_Groups!$D:$D,IFERROR(VLOOKUP(Request!$B$8,SKU_Family_Map!$A:$B,2,FALSE),""))/MAX(SUMIFS(Quota_Groups!$E:$E,Quota_Groups!$B:$B,$A4,Quota_Groups!$D:$D,IFERROR(VLOOKUP(Request!$B$8,SKU_Family_Map!$A:$B,2,FALSE),"")),1),0)),IF(OR(Request!$B$9="",Request!$C$9=""),1,IFERROR(SUMIFS(Quota_Groups!$G:$G,Quota_Groups!$B:$B,$A4,Quota_Groups!$D:$D,IFERROR(VLOOKUP(Request!$B$9,SKU_Family_Map!$A:$B,2,FALSE),""))/MAX(SUMIFS(Quota_Groups!$E:$E,Quota_Groups!$B:$B,$A4,Quota_Groups!$D:$D,IFERROR(VLOOKUP(Request!$B$9,SKU_Family_Map!$A:$B,2,FALSE),"")),1),0)),IF(OR(Request!$B$10="",Request!$C$10=""),1,IFERROR(SUMIFS(Quota_Groups!$G:$G,Quota_Groups!$B:$B,$A4,Quota_Groups!$D:$D,IFERROR(VLOOKUP(Request!$B$10,SKU_Family_Map!$A:$B,2,FALSE),""))/MAX(SUMIFS(Quota_Groups!$E:$E,Quota_Groups!$B:$B,$A4,Quota_Groups!$D:$D,IFERROR(VLOOKUP(Request!$B$10,SKU_Family_Map!$A:$B,2,FALSE),"")),1),0)),IF(OR(Request!$B$11="",Request!$C$11=""),1,IFERROR(SUMIFS(Quota_Groups!$G:$G,Quota_Groups!$B:$B,$A4,Quota_Groups!$D:$D,IFERROR(VLOOKUP(Request!$B$11,SKU_Family_Map!$A:$B,2,FALSE),""))/MAX(SUMIFS(Quota_Groups!$E:$E,Quota_Groups!$B:$B,$A4,Quota_Groups!$D:$D,IFERROR(VLOOKUP(Request!$B$11,SKU_Family_Map!$A:$B,2,FALSE),"")),1),0)),IF(OR(Request!$B$12="",Request!$C$12=""),1,IFERROR(SUMIFS(Quota_Groups!$G:$G,Quota_Groups!$B:$B,$A4,Quota_Groups!$D:$D,IFERROR(VLOOKUP(Request!$B$12,SKU_Family_Map!$A:$B,2,FALSE),""))/MAX(SUMIFS(Quota_Groups!$E:$E,Quota_Groups!$B:$B,$A4,Quota_Groups!$D:$D,IFERROR(VLOOKUP(Request!$B$12,SKU_Family_Map!$A:$B,2,FALSE),"")),1),0)),IF(OR(Request!$B$13="",Request!$C$13=""),1,IFERROR(SUMIFS(Quota_Groups!$G:$G,Quota_Groups!$B:$B,$A4,Quota_Groups!$D:$D,IFERROR(VLOOKUP(Request!$B$13,SKU_Family_Map!$A:$B,2,FALSE),""))/MAX(SUMIFS(Quota_Groups!$E:$E,Quota_Groups!$B:$B,$A4,Quota_Groups!$D:$D,IFERROR(VLOOKUP(Request!$B$13,SKU_Family_Map!$A:$B,2,FALSE),"")),1),0)),IF(OR(Request!$B$14="",Request!$C$14=""),1,IFERROR(SUMIFS(Quota_Groups!$G:$G,Quota_Groups!$B:$B,$A4,Quota_Groups!$D:$D,IFERROR(VLOOKUP(Request!$B$14,SKU_Family_Map!$A:$B,2,FALSE),""))/MAX(SUMIFS(Quota_Groups!$E:$E,Quota_Groups!$B:$B,$A4,Quota_Groups!$D:$D,IFERROR(VLOOKUP(Request!$B$14,SKU_Family_Map!$A:$B,2,FALSE),"")),1),0)),IF(OR(Request!$B$15="",Request!$C$15=""),1,IFERROR(SUMIFS(Quota_Groups!$G:$G,Quota_Groups!$B:$B,$A4,Quota_Groups!$D:$D,IFERROR(VLOOKUP(Request!$B$15,SKU_Family_Map!$A:$B,2,FALSE),""))/MAX(SUMIFS(Quota_Groups!$E:$E,Quota_Groups!$B:$B,$A4,Quota_Groups!$D:$D,IFERROR(VLOOKUP(Request!$B$15,SKU_Family_Map!$A:$B,2,FALSE),"")),1),0))),"CAPACITY","QUOTA")) | Q4: Readiness | R4: =IFERROR(INDEX($H$4:$H$11,MATCH(1,$N$4:$N$11,0)),"")
