Workbook

Sheet How_To_Use
B1: ACRME Region Selection — WHAT-IF on the ACRME Region Catalogue (Formula-Only)
B2: Candidate regions = authoritative ACRME catalogue (baseline v2.4 Section 6). Usage distributed from the real SKU-usage files.
B4: WHAT THIS WORKBOOK DOES
B5: This what-if runs the ACRME weightage model over the ACTUAL ACRME in-scope regions (not the regions that happen to appear in the usage export). Your real usage is DISTRIBUTED onto those catalogue regions, and the engine scores every region so you can see where new workload should land. All results are live formulas — change any input and everything recalculates. No macros.
B7: 4-REGION MODEL SCENARIO — WHAT-IF EXPLORATION
B8: • **US**: upgraded from 3-region (baseline) → **4-region model**. All 4 US Standard regions (West US 3, Central US, Canada Central, East US 2) now compete for placement. **PLC-010a co-location NO LONGER APPLIES** — Prod / CVAL / DR can each occupy separate regions.
B9: • **EU**: upgraded from 2-region (baseline) → **4-region model**. All 4 EU Standard regions (Switzerland North, Sweden Central, North Europe, West Europe) now compete. **CVAL and DR no longer co-locate** — they occupy distinct regions, improving blast-radius isolation.
B10: • **Australia, Asia Pacific**: remain 2-region (unchanged from baseline). CVAL/DR co-location still applies.
B11: • **Middle East**: remains cross-geo DR (unchanged). Prod+CVAL local in Middle East; DR in Europe.
B12: • **Impact on HC gates**: HC-6/HC-7 (CVAL/DR co-location checks) disabled for US and EU 4-region geographies. HC-3 (individual environment checks) still applies to all regions.
B13: • **Middle East** regions (Saudi Arabia East, UAE North) remain RESTRICTED — production-only; explicit Prod region required on Setup (cell B8). DR still auto-selects cross-geo in a Standard Europe region.
B15: HOW THE DISTRIBUTION WORKS
... B42: • PS_NonProd δ duplicates its α (baseline design-of-record). DR bootstrap / target are configurable placeholders.

Sheet Usage_Source
A1: CURRENT USAGE — SOURCE SNAPSHOT (real, from uploaded files)
A2: Real aggregation from SKU_USage (1).xlsx (Total Cores). Prod = tag 'Prod'; all other tags = Non-Prod. This is provenance; the engine reads the distributed Capacity_Usage sheet. ACRME catalogue regions absent from source data use SYNTHETIC capacity — see the footer section below. NOTE: Saudi Arabia East is a FUTURE REGION (not yet GA; Microsoft target Q4 2026, Eastern Province) — no real usage data exists; capacity figures are entirely SYNTHETIC.
A3: Region (as in data) | B3: Geography | C3: Class in this mockup | D3: Prod Cores | E3: Non-Prod Cores | F3: Total Cores | G3: AKS Cores | H3: Unique Subs | I3: ACRME catalogue region?
A4: East US 2 | B4: US | C4: Standard | D4: 139410 | E4: 328418 | F4: 467828 | G4: 155696 | H4: 150 | I4: ACRME region
A5: West Europe | B5: EU | C5: Standard | D5: 41088 | E5: 139820 | F5: 180908 | G5: 58982 | H5: 69 | I5: ACRME region
A6: Southeast Asia | B6: Asia Pacific | C6: Standard | D6: 19388 | E6: 22766 | F6: 42154 | G6: 12338 | H6: 43 | I6: ACRME region
A7: Central US | B7: US | C7: Standard | D7: 17964 | E7: 22318 | F7: 40282 | G7: 19626 | H7: 65 | I7: ACRME region
A8: Australia East | B8: Australia | C8: Standard | D8: 8436 | E8: 17002 | F8: 25438 | G8: 8616 | H8: 34 | I8: ACRME region
A9: North Europe | B9: EU | C9: Standard | D9: 5448 | E9: 6944 | F9: 12392 | G9: 6000 | H9: 30 | I9: ACRME region
A10: East Asia | B10: Asia Pacific | C10: Standard | D10: 3068 | E10: 3100 | F10: 6168 | G10: 2824 | H10: 21 | I10: ACRME region
A11: Australia Southeast | B11: Australia | C11: Standard | D11: 1976 | E11: 2644 | F11: 4620 | G11: 2096 | H11: 14 | I11: ACRME region
A12: Sweden Central | B12: EU | C12: Standard | D12: 1632 | E12: 1760 | F12: 3392 | G12: 1696 | H12: 13 | I12: ACRME region
A13: Switzerland North | B13: EU | C13: Standard | D13: 1216 | E13: 1312 | F13: 2528 | G13: 1264 | H13: 11 | I13: ACRME region
A14: South Africa North | B14: Middle East | C14: Restricted | D14: 0 | E14: 1736 | F14: 1736 | G14: 868 | H14: 1 | I14: folds into geography (not an ACRME region)
A15: Central India | B15: Asia Pacific | C15: — | D15: 698 | E15: 0 | F15: 698 | G15: 0 | H15: 1 | I15: folds into geography (not an ACRME region)
... A17: West US 3 | B17: US | C17: Standard | D17: 0 | E17: 2 | F17: 2 | G17: 0 | H17: 1 | I17: ACRME region
A18: TOTAL | D18: =SUM(D4:D17) | E18: =SUM(E4:E17) | F18: =SUM(F4:F17) | G18: =SUM(G4:G17)
A20: ACRME CATALOGUE REGIONS — ABSENT FROM SOURCE DATA (capacity figures are SYNTHETIC)
A21: Canada Central | B21: US | C21: Standard | D21: absent from source data; mock subscription count used; capacity figures SYNTHETIC
A22: Saudi Arabia East | B22: Middle East | C22: Restricted | D22: FUTURE REGION — not yet GA (Microsoft target Q4 2026, Eastern Province); no real usage data; capacity figures SYNTHETIC
A23: UAE North | B23: Middle East | C23: Restricted | D23: GA region — absent from ACRME source data; capacity figures SYNTHETIC

Sheet Setup
A1: SETUP — Customer & Workload | E1: Lookup tables (do not edit)
E2: SKU | F2: vCPU/VM
A3: Geography | B3: US | E3: E16ads_v5 | F3: 16
A4: SKU | B4: E16ads_v5 | E4: E32ads_v5 | F4: 32
A5: VM count | B5: 3 | E5: E8ads_v5 | F5: 8
A6: vCPU per VM | B6: =VLOOKUP(B4,E3:F10,2,FALSE) | E6: E4ads_v5 | F6: 4
A7: Requested vCPU | B7: =B5*B6 | E7: D8ads_v5 | F7: 8
A8: Prod region (req. for Middle East) | E8: D4ads_v5 | F8: 4
A9: Customer ID | B9: CUST-0042 | E9: D2ads_v5 | F9: 2
A10: Distribution model | B10: =VLOOKUP(B3,E13:G17,2,FALSE) | E10: D16ads_v5 | F10: 16
A11: DR scope geography | B11: =VLOOKUP(B3,E13:G17,3,FALSE)
E12: Geography | F12: Model | G12: DR Scope Geo
E13: US | F13: 4-region | G13: US
E14: EU | F14: 4-region | G14: EU
E15: Australia | F15: 2-region | G15: Australia
E16: Asia Pacific | F16: 2-region | G16: Asia Pacific
E17: Middle East | F17: cross-geo | G17: EU

Sheet Policy
A1: POLICY — Weights & Parameters
A2: alpha (α) — Capacity headroom | B2: 0.3
A3: beta (β) — Quota headroom | B3: 0.2
A4: gamma (γ) — Distribution fairness | B4: 0.25
A5: delta (δ) — DR readiness | B5: 0.15
A6: epsilon (ε) — Zone diversity | B6: 0.1
A7: Weight sum | B7: =SUM(B2:B6)
A8: Validation | B8: =IF(ABS(B7-1)<=0.001,"VALID","INVALID — must sum to 1.0")
A10: total_customers source | B10: Live geography count (PLC-012) | D10: total_customers(g) = customers in geography g with any environment provisioned or being deployed (baseline v2.5 amended, PLC-012 / A.10). Live, not configurable. Workbook stand-in: sum of Cust Count over the geography's regions.
A11: γ when total_customers = 0 | B11: 1
A13: DR bootstrap qty (vCPU) | B13: 40
A14: DR coverage target | B14: 0.8
A15: Min Prod headroom (vCPU) | B15: 20
A16: Min NonProd headroom (vCPU) | B16: 20
A17: Min DR headroom (vCPU) | B17: 16

Sheet Capacity_Usage
A1: ACRME CATALOGUE — CAPACITY & USAGE (real usage distributed across the actual ACRME regions)
A2: Alloc / Q-Used = real usage distributed onto ACRME regions (geography totals preserved). Reserved / Quota = max(even balanced-share, region alloc) + 8% margin (positive but varying headroom). Class: Standard = engine-selectable; Restricted (Middle East) = production-only, explicit Prod region required. Yellow = editable; grey = computed.
A3: Region ID | B3: Region Name | C3: Geography | D3: Model | E3: AZ | F3: Prod Reserved | G3: Prod Alloc | H3: Prod Free | I3: Prod Q-Limit | J3: Prod Q-Used | K3: Prod Q-Headroom | L3: NP Reserved | M3: NP Alloc | N3: NP Eff-Free | O3: NP Q-Limit | P3: NP Q-Used | Q3: NP Q-Headroom | R3: DR Reserved | S3: DR Free | T3: DR Coverage | U3: Cust Count | V3: Class
A4: westus3 | B4: West US 3 | C4: US | D4: 3-region | E4: 3 | F4: 42492 | G4: 2 | H4: =F4-G4 | I4: 63738 | J4: 2 | K4: =I4-J4 | L4: 94710 | M4: 2 | N4: 94708 | O4: 142064 | P4: 2 | Q4: =O4-P4 | R4: 19672 | S4: 16722 | T4: 0.6 | U4: 1 | V4: Standard
A5: centralus | B5: Central US | C5: US | D5: 3-region | E5: 3 | F5: 42492 | G5: 12292 | H5: =F5-G5 | I5: 63738 | J5: 12292 | K5: =I5-J5 | L5: 94710 | M5: 27398 | N5: 67312 | O5: 142064 | P5: 27398 | Q5: =O5-P5 | R5: 19672 | S5: 16722 | T5: 0.6 | U5: 65 | V5: Standard
A6: canadacentral | B6: Canada Central | C6: US | D6: 3-region | E6: 3 | F6: 42492 | G6: 2326 | H6: =F6-G6 | I6: 63738 | J6: 2326 | K6: =I6-J6 | L6: 94710 | M6: 5186 | N6: 89524 | O6: 142064 | P6: 5186 | Q6: =O6-P6 | R6: 19672 | S6: 16722 | T6: 0.6 | U6: 10 | V6: Standard
A7: eastus2 | B7: East US 2 | C7: US | D7: 3-region | E7: 3 | F7: 154178 | G7: 142756 | H7: =F7-G7 | I7: 231266 | J7: 142756 | K7: =I7-J7 | L7: 343646 | M7: 318190 | N7: 25456 | O7: 515468 | P7: 318190 | Q7: =O7-P7 | R7: 19672 | S7: 16722 | T7: 0.6 | U7: 150 | V7: Standard
A8: switzerlandnorth | B8: Switzerland North | C8: EU | D8: 2-region | E8: 3 | F8: 13334 | G8: 628 | H8: =F8-G8 | I8: 20002 | J8: 628 | K8: =I8-J8 | L8: 40456 | M8: 1902 | N8: 38554 | O8: 60684 | P8: 1902 | Q8: =O8-P8 | R8: 6174 | S8: 5248 | T8: 0.6 | U8: 11 | V8: Standard
A9: swedencentral | B9: Sweden Central | C9: EU | D9: 2-region | E9: 3 | F9: 13334 | G9: 842 | H9: =F9-G9 | I9: 20002 | J9: 842 | K9: =I9-J9 | L9: 40456 | M9: 2552 | N9: 37904 | O9: 60684 | P9: 2552 | Q9: =O9-P9 | R9: 6174 | S9: 5248 | T9: 0.6 | U9: 13 | V9: Standard
A10: northeurope | B10: North Europe | C10: EU | D10: 2-region | E10: 3 | F10: 13334 | G10: 3072 | H10: =F10-G10 | I10: 20002 | J10: 3072 | K10: =I10-J10 | L10: 40456 | M10: 9322 | N10: 31134 | O10: 60684 | P10: 9322 | Q10: =O10-P10 | R10: 6174 | S10: 5248 | T10: 0.6 | U10: 30 | V10: Standard
A11: westeurope | B11: West Europe | C11: EU | D11: 2-region | E11: 3 | F11: 48434 | G11: 44846 | H11: =F11-G11 | I11: 72650 | J11: 44846 | K11: =I11-J11 | L11: 146950 | M11: 136064 | N11: 10886 | O11: 220424 | P11: 136064 | Q11: =O11-P11 | R11: 6174 | S11: 5248 | T11: 0.6 | U11: 69 | V11: Standard
A12: australiaeast | B12: Australia East | C12: Australia | D12: 2-region | E12: 3 | F12: 9518 | G12: 8812 | H12: =F12-G12 | I12: 14276 | J12: 8812 | K12: =I12-J12 | L12: 17958 | M12: 16628 | N12: 1330 | O12: 26936 | P12: 16628 | Q12: =O12-P12 | R12: 2604 | S12: 2214 | T12: 0.6 | U12: 34 | V12: Standard
A13: australiasoutheast | B13: Australia Southeast | C13: Australia | D13: 2-region | E13: 2 | F13: 5624 | G13: 1602 | H13: =F13-G13 | I13: 8434 | J13: 1602 | K13: =I13-J13 | L13: 10610 | M13: 3020 | N13: 7590 | O13: 15914 | P13: 3020 | Q13: =O13-P13 | R13: 2604 | S13: 2214 | T13: 0.6 | U13: 14 | V13: Standard
A14: eastasia | B14: East Asia | C14: Asia Pacific | D14: 2-region | E14: 3 | F14: 12504 | G14: 2956 | H14: =F14-G14 | I14: 18756 | J14: 2956 | K14: =I14-J14 | L14: 13968 | M14: 3302 | N14: 10666 | O14: 20952 | P14: 3302 | Q14: =O14-P14 | R14: 5790 | S14: 4922 | T14: 0.6 | U14: 21 | V14: Standard
A15: southeastasia | B15: Southeast Asia | C15: Asia Pacific | D15: 2-region | E15: 3 | F15: 21816 | G15: 20200 | H15: =F15-G15 | I15: 32722 | J15: 20200 | K15: =I15-J15 | L15: 24370 | M15: 22566 | N15: 1804 | O15: 36556 | P15: 22566 | Q15: =O15-P15 | R15: 5790 | S15: 4922 | T15: 0.6 | U15: 43 | V15: Standard
... A17: uaenorth | B17: UAE North | C17: Middle East | D17: cross-geo | E17: 3 | F17: 1296 | G17: 1200 | H17: =F17-G17 | I17: 1944 | J17: 1200 | K17: =I17-J17 | L17: 1838 | M17: 1700 | N17: 138 | O17: 2756 | P17: 1700 | Q17: =O17-P17 | R17: 0 | S17: 0 | T17: 0 | U17: 4 | V17: Restricted

Sheet HC_Gate
A1: HARD CONSTRAINT GATE
A3: Region | B3: Geography | C3: Class | D3: Req vCPU | E3: HC-3 Prod | F3: HC-3 NonProd | G3: HC-3 DR | H3: HC-6 DR Floor | I3: HC-7 DR Integ | J3: Eligible Prod | K3: Eligible NonProd | L3: Eligible DR
A4: =Capacity_Usage!B4 | B4: =Capacity_Usage!C4 | C4: =Capacity_Usage!V4 | D4: =Setup!$B$7 | E4: =IF(AND(Capacity_Usage!K4>=Setup!$B$7,Capacity_Usage!K4-Setup!$B$7>=Policy!$B$15),"PASS","FAIL") | F4: =IF(AND(Capacity_Usage!N4>=Setup!$B$7,Capacity_Usage!Q4-Setup!$B$7>=Policy!$B$16),"PASS","FAIL") | G4: =IF(Capacity_Usage!S4>=Policy!$B$13,"PASS","FAIL") | H4: =IF(OR(B4="US",B4="EU"),"N/A (4-region)",IF(Capacity_Usage!S4+Capacity_Usage!N4>=Policy!$B$13,"PASS","FAIL")) | I4: =IF(OR(B4="US",B4="EU"),"N/A (4-region)",IF(Capacity_Usage!P4+Setup!$B$7<=Capacity_Usage!O4-Policy!$B$13,"PASS","FAIL")) | J4: =IF(E4="PASS","YES","NO") | K4: =IF(AND(F4="PASS",OR(I4="PASS",I4="N/A (4-region)")),"YES","NO") | L4: =IF(AND(G4="PASS",OR(H4="PASS",H4="N/A (4-region)")),"YES","NO")
A5: =Capacity_Usage!B5 | B5: =Capacity_Usage!C5 | C5: =Capacity_Usage!V5 | D5: =Setup!$B$7 | E5: =IF(AND(Capacity_Usage!K5>=Setup!$B$7,Capacity_Usage!K5-Setup!$B$7>=Policy!$B$15),"PASS","FAIL") | F5: =IF(AND(Capacity_Usage!N5>=Setup!$B$7,Capacity_Usage!Q5-Setup!$B$7>=Policy!$B$16),"PASS","FAIL") | G5: =IF(Capacity_Usage!S5>=Policy!$B$13,"PASS","FAIL") | H5: =IF(OR(B5="US",B5="EU"),"N/A (4-region)",IF(Capacity_Usage!S5+Capacity_Usage!N5>=Policy!$B$13,"PASS","FAIL")) | I5: =IF(OR(B5="US",B5="EU"),"N/A (4-region)",IF(Capacity_Usage!P5+Setup!$B$7<=Capacity_Usage!O5-Policy!$B$13,"PASS","FAIL")) | J5: =IF(E5="PASS","YES","NO") | K5: =IF(AND(F5="PASS",OR(I5="PASS",I5="N/A (4-region)")),"YES","NO") | L5: =IF(AND(G5="PASS",OR(H5="PASS",H5="N/A (4-region)")),"YES","NO")
A6: =Capacity_Usage!B6 | B6: =Capacity_Usage!C6 | C6: =Capacity_Usage!V6 | D6: =Setup!$B$7 | E6: =IF(AND(Capacity_Usage!K6>=Setup!$B$7,Capacity_Usage!K6-Setup!$B$7>=Policy!$B$15),"PASS","FAIL") | F6: =IF(AND(Capacity_Usage!N6>=Setup!$B$7,Capacity_Usage!Q6-Setup!$B$7>=Policy!$B$16),"PASS","FAIL") | G6: =IF(Capacity_Usage!S6>=Policy!$B$13,"PASS","FAIL") | H6: =IF(OR(B6="US",B6="EU"),"N/A (4-region)",IF(Capacity_Usage!S6+Capacity_Usage!N6>=Policy!$B$13,"PASS","FAIL")) | I6: =IF(OR(B6="US",B6="EU"),"N/A (4-region)",IF(Capacity_Usage!P6+Setup!$B$7<=Capacity_Usage!O6-Policy!$B$13,"PASS","FAIL")) | J6: =IF(E6="PASS","YES","NO") | K6: =IF(AND(F6="PASS",OR(I6="PASS",I6="N/A (4-region)")),"YES","NO") | L6: =IF(AND(G6="PASS",OR(H6="PASS",H6="N/A (4-region)")),"YES","NO")
A7: =Capacity_Usage!B7 | B7: =Capacity_Usage!C7 | C7: =Capacity_Usage!V7 | D7: =Setup!$B$7 | E7: =IF(AND(Capacity_Usage!K7>=Setup!$B$7,Capacity_Usage!K7-Setup!$B$7>=Policy!$B$15),"PASS","FAIL") | F7: =IF(AND(Capacity_Usage!N7>=Setup!$B$7,Capacity_Usage!Q7-Setup!$B$7>=Policy!$B$16),"PASS","FAIL") | G7: =IF(Capacity_Usage!S7>=Policy!$B$13,"PASS","FAIL") | H7: =IF(OR(B7="US",B7="EU"),"N/A (4-region)",IF(Capacity_Usage!S7+Capacity_Usage!N7>=Policy!$B$13,"PASS","FAIL")) | I7: =IF(OR(B7="US",B7="EU"),"N/A (4-region)",IF(Capacity_Usage!P7+Setup!$B$7<=Capacity_Usage!O7-Policy!$B$13,"PASS","FAIL")) | J7: =IF(E7="PASS","YES","NO") | K7: =IF(AND(F7="PASS",OR(I7="PASS",I7="N/A (4-region)")),"YES","NO") | L7: =IF(AND(G7="PASS",OR(H7="PASS",H7="N/A (4-region)")),"YES","NO")
A8: =Capacity_Usage!B8 | B8: =Capacity_Usage!C8 | C8: =Capacity_Usage!V8 | D8: =Setup!$B$7 | E8: =IF(AND(Capacity_Usage!K8>=Setup!$B$7,Capacity_Usage!K8-Setup!$B$7>=Policy!$B$15),"PASS","FAIL") | F8: =IF(AND(Capacity_Usage!N8>=Setup!$B$7,Capacity_Usage!Q8-Setup!$B$7>=Policy!$B$16),"PASS","FAIL") | G8: =IF(Capacity_Usage!S8>=Policy!$B$13,"PASS","FAIL") | H8: =IF(OR(B8="US",B8="EU"),"N/A (4-region)",IF(Capacity_Usage!S8+Capacity_Usage!N8>=Policy!$B$13,"PASS","FAIL")) | I8: =IF(OR(B8="US",B8="EU"),"N/A (4-region)",IF(Capacity_Usage!P8+Setup!$B$7<=Capacity_Usage!O8-Policy!$B$13,"PASS","FAIL")) | J8: =IF(E8="PASS","YES","NO") | K8: =IF(AND(F8="PASS",OR(I8="PASS",I8="N/A (4-region)")),"YES","NO") | L8: =IF(AND(G8="PASS",OR(H8="PASS",H8="N/A (4-region)")),"YES","NO")
A9: =Capacity_Usage!B9 | B9: =Capacity_Usage!C9 | C9: =Capacity_Usage!V9 | D9: =Setup!$B$7 | E9: =IF(AND(Capacity_Usage!K9>=Setup!$B$7,Capacity_Usage!K9-Setup!$B$7>=Policy!$B$15),"PASS","FAIL") | F9: =IF(AND(Capacity_Usage!N9>=Setup!$B$7,Capacity_Usage!Q9-Setup!$B$7>=Policy!$B$16),"PASS","FAIL") | G9: =IF(Capacity_Usage!S9>=Policy!$B$13,"PASS","FAIL") | H9: =IF(OR(B9="US",B9="EU"),"N/A (4-region)",IF(Capacity_Usage!S9+Capacity_Usage!N9>=Policy!$B$13,"PASS","FAIL")) | I9: =IF(OR(B9="US",B9="EU"),"N/A (4-region)",IF(Capacity_Usage!P9+Setup!$B$7<=Capacity_Usage!O9-Policy!$B$13,"PASS","FAIL")) | J9: =IF(E9="PASS","YES","NO") | K9: =IF(AND(F9="PASS",OR(I9="PASS",I9="N/A (4-region)")),"YES","NO") | L9: =IF(AND(G9="PASS",OR(H9="PASS",H9="N/A (4-region)")),"YES","NO")
A10: =Capacity_Usage!B10 | B10: =Capacity_Usage!C10 | C10: =Capacity_Usage!V10 | D10: =Setup!$B$7 | E10: =IF(AND(Capacity_Usage!K10>=Setup!$B$7,Capacity_Usage!K10-Setup!$B$7>=Policy!$B$15),"PASS","FAIL") | F10: =IF(AND(Capacity_Usage!N10>=Setup!$B$7,Capacity_Usage!Q10-Setup!$B$7>=Policy!$B$16),"PASS","FAIL") | G10: =IF(Capacity_Usage!S10>=Policy!$B$13,"PASS","FAIL") | H10: =IF(OR(B10="US",B10="EU"),"N/A (4-region)",IF(Capacity_Usage!S10+Capacity_Usage!N10>=Policy!$B$13,"PASS","FAIL")) | I10: =IF(OR(B10="US",B10="EU"),"N/A (4-region)",IF(Capacity_Usage!P10+Setup!$B$7<=Capacity_Usage!O10-Policy!$B$13,"PASS","FAIL")) | J10: =IF(E10="PASS","YES","NO") | K10: =IF(AND(F10="PASS",OR(I10="PASS",I10="N/A (4-region)")),"YES","NO") | L10: =IF(AND(G10="PASS",OR(H10="PASS",H10="N/A (4-region)")),"YES","NO")
A11: =Capacity_Usage!B11 | B11: =Capacity_Usage!C11 | C11: =Capacity_Usage!V11 | D11: =Setup!$B$7 | E11: =IF(AND(Capacity_Usage!K11>=Setup!$B$7,Capacity_Usage!K11-Setup!$B$7>=Policy!$B$15),"PASS","FAIL") | F11: =IF(AND(Capacity_Usage!N11>=Setup!$B$7,Capacity_Usage!Q11-Setup!$B$7>=Policy!$B$16),"PASS","FAIL") | G11: =IF(Capacity_Usage!S11>=Policy!$B$13,"PASS","FAIL") | H11: =IF(OR(B11="US",B11="EU"),"N/A (4-region)",IF(Capacity_Usage!S11+Capacity_Usage!N11>=Policy!$B$13,"PASS","FAIL")) | I11: =IF(OR(B11="US",B11="EU"),"N/A (4-region)",IF(Capacity_Usage!P11+Setup!$B$7<=Capacity_Usage!O11-Policy!$B$13,"PASS","FAIL")) | J11: =IF(E11="PASS","YES","NO") | K11: =IF(AND(F11="PASS",OR(I11="PASS",I11="N/A (4-region)")),"YES","NO") | L11: =IF(AND(G11="PASS",OR(H11="PASS",H11="N/A (4-region)")),"YES","NO")
A12: =Capacity_Usage!B12 | B12: =Capacity_Usage!C12 | C12: =Capacity_Usage!V12 | D12: =Setup!$B$7 | E12: =IF(AND(Capacity_Usage!K12>=Setup!$B$7,Capacity_Usage!K12-Setup!$B$7>=Policy!$B$15),"PASS","FAIL") | F12: =IF(AND(Capacity_Usage!N12>=Setup!$B$7,Capacity_Usage!Q12-Setup!$B$7>=Policy!$B$16),"PASS","FAIL") | G12: =IF(Capacity_Usage!S12>=Policy!$B$13,"PASS","FAIL") | H12: =IF(OR(B12="US",B12="EU"),"N/A (4-region)",IF(Capacity_Usage!S12+Capacity_Usage!N12>=Policy!$B$13,"PASS","FAIL")) | I12: =IF(OR(B12="US",B12="EU"),"N/A (4-region)",IF(Capacity_Usage!P12+Setup!$B$7<=Capacity_Usage!O12-Policy!$B$13,"PASS","FAIL")) | J12: =IF(E12="PASS","YES","NO") | K12: =IF(AND(F12="PASS",OR(I12="PASS",I12="N/A (4-region)")),"YES","NO") | L12: =IF(AND(G12="PASS",OR(H12="PASS",H12="N/A (4-region)")),"YES","NO")
A13: =Capacity_Usage!B13 | B13: =Capacity_Usage!C13 | C13: =Capacity_Usage!V13 | D13: =Setup!$B$7 | E13: =IF(AND(Capacity_Usage!K13>=Setup!$B$7,Capacity_Usage!K13-Setup!$B$7>=Policy!$B$15),"PASS","FAIL") | F13: =IF(AND(Capacity_Usage!N13>=Setup!$B$7,Capacity_Usage!Q13-Setup!$B$7>=Policy!$B$16),"PASS","FAIL") | G13: =IF(Capacity_Usage!S13>=Policy!$B$13,"PASS","FAIL") | H13: =IF(OR(B13="US",B13="EU"),"N/A (4-region)",IF(Capacity_Usage!S13+Capacity_Usage!N13>=Policy!$B$13,"PASS","FAIL")) | I13: =IF(OR(B13="US",B13="EU"),"N/A (4-region)",IF(Capacity_Usage!P13+Setup!$B$7<=Capacity_Usage!O13-Policy!$B$13,"PASS","FAIL")) | J13: =IF(E13="PASS","YES","NO") | K13: =IF(AND(F13="PASS",OR(I13="PASS",I13="N/A (4-region)")),"YES","NO") | L13: =IF(AND(G13="PASS",OR(H13="PASS",H13="N/A (4-region)")),"YES","NO")
A14: =Capacity_Usage!B14 | B14: =Capacity_Usage!C14 | C14: =Capacity_Usage!V14 | D14: =Setup!$B$7 | E14: =IF(AND(Capacity_Usage!K14>=Setup!$B$7,Capacity_Usage!K14-Setup!$B$7>=Policy!$B$15),"PASS","FAIL") | F14: =IF(AND(Capacity_Usage!N14>=Setup!$B$7,Capacity_Usage!Q14-Setup!$B$7>=Policy!$B$16),"PASS","FAIL") | G14: =IF(Capacity_Usage!S14>=Policy!$B$13,"PASS","FAIL") | H14: =IF(OR(B14="US",B14="EU"),"N/A (4-region)",IF(Capacity_Usage!S14+Capacity_Usage!N14>=Policy!$B$13,"PASS","FAIL")) | I14: =IF(OR(B14="US",B14="EU"),"N/A (4-region)",IF(Capacity_Usage!P14+Setup!$B$7<=Capacity_Usage!O14-Policy!$B$13,"PASS","FAIL")) | J14: =IF(E14="PASS","YES","NO") | K14: =IF(AND(F14="PASS",OR(I14="PASS",I14="N/A (4-region)")),"YES","NO") | L14: =IF(AND(G14="PASS",OR(H14="PASS",H14="N/A (4-region)")),"YES","NO")
A15: =Capacity_Usage!B15 | B15: =Capacity_Usage!C15 | C15: =Capacity_Usage!V15 | D15: =Setup!$B$7 | E15: =IF(AND(Capacity_Usage!K15>=Setup!$B$7,Capacity_Usage!K15-Setup!$B$7>=Policy!$B$15),"PASS","FAIL") | F15: =IF(AND(Capacity_Usage!N15>=Setup!$B$7,Capacity_Usage!Q15-Setup!$B$7>=Policy!$B$16),"PASS","FAIL") | G15: =IF(Capacity_Usage!S15>=Policy!$B$13,"PASS","FAIL") | H15: =IF(OR(B15="US",B15="EU"),"N/A (4-region)",IF(Capacity_Usage!S15+Capacity_Usage!N15>=Policy!$B$13,"PASS","FAIL")) | I15: =IF(OR(B15="US",B15="EU"),"N/A (4-region)",IF(Capacity_Usage!P15+Setup!$B$7<=Capacity_Usage!O15-Policy!$B$13,"PASS","FAIL")) | J15: =IF(E15="PASS","YES","NO") | K15: =IF(AND(F15="PASS",OR(I15="PASS",I15="N/A (4-region)")),"YES","NO") | L15: =IF(AND(G15="PASS",OR(H15="PASS",H15="N/A (4-region)")),"YES","NO")
... A17: =Capacity_Usage!B17 | B17: =Capacity_Usage!C17 | C17: =Capacity_Usage!V17 | D17: =Setup!$B$7 | E17: =IF(AND(Capacity_Usage!K17>=Setup!$B$7,Capacity_Usage!K17-Setup!$B$7>=Policy!$B$15),"PASS","FAIL") | F17: =IF(AND(Capacity_Usage!N17>=Setup!$B$7,Capacity_Usage!Q17-Setup!$B$7>=Policy!$B$16),"PASS","FAIL") | G17: =IF(Capacity_Usage!S17>=Policy!$B$13,"PASS","FAIL") | H17: =IF(OR(B17="US",B17="EU"),"N/A (4-region)",IF(Capacity_Usage!S17+Capacity_Usage!N17>=Policy!$B$13,"PASS","FAIL")) | I17: =IF(OR(B17="US",B17="EU"),"N/A (4-region)",IF(Capacity_Usage!P17+Setup!$B$7<=Capacity_Usage!O17-Policy!$B$13,"PASS","FAIL")) | J17: =IF(E17="PASS","YES","NO") | K17: =IF(AND(F17="PASS",OR(I17="PASS",I17="N/A (4-region)")),"YES","NO") | L17: =IF(AND(G17="PASS",OR(H17="PASS",H17="N/A (4-region)")),"YES","NO")

Sheet Scoring_Prod
A1: PS_Prod — Production Placement Score | T1: PROD WINNER
T2: Selection mode | U2: =IF(Setup!$B$8="","Engine argmax","Customer-supplied")
A3: Region | B3: Geography | C3: InScope | D3: Eligible | E3: AutoSel | F3: total_cust | G3: α_raw | H3: α_c | I3: β_raw | J3: β_c | K3: γ_raw | L3: γ_c | M3: δ_raw | N3: δ_c | O3: ε_raw | P3: ε_c | Q3: PS | R3: Candidate | S3: Rank | T3: Region | U3: =IF(Setup!$B$8<>"",Setup!$B$8,IF(MAX(R4:R17)<0,"NONE ELIGIBLE",INDEX(A4:A17,MATCH(MAX(R4:R17),R4:R17,0))))
A4: =Capacity_Usage!B4 | B4: =Capacity_Usage!C4 | C4: =IF(Capacity_Usage!C4=Setup!$B$3,1,0) | D4: =IF(HC_Gate!J4="YES",1,0) | E4: =IF(OR(Capacity_Usage!V4="Standard",Capacity_Usage!B4=Setup!$B$8),1,0) | F4: =SUMIFS(Capacity_Usage!$U$4:$U$17,Capacity_Usage!$C$4:$C$17,Capacity_Usage!C4) | G4: =IFERROR(Capacity_Usage!N4/Capacity_Usage!F4,0) | H4: =MIN(MAX(G4,0),1) | I4: =IFERROR(Capacity_Usage!K4/Capacity_Usage!I4,0) | J4: =MIN(MAX(I4,0),1) | K4: =IF(F4=0,Policy!$B$11,1-Capacity_Usage!U4/F4) | L4: =MIN(MAX(K4,0),1) | M4: =IFERROR(Capacity_Usage!T4,0) | N4: =MIN(MAX(M4,0),1) | O4: =Capacity_Usage!E4/3 | P4: =MIN(MAX(O4,0),1) | Q4: =Policy!$B$2*H4+Policy!$B$3*J4+Policy!$B$4*L4+Policy!$B$5*N4+Policy!$B$6*P4 | R4: =IF(AND(C4=1,D4=1,E4=1),Q4,-1) | S4: =IF(R4<0,"",COUNTIF($R$4:$R$17,">"&R4)+1) | T4: Score | U4: =IF(Setup!$B$8<>"",INDEX(Q4:Q17,MATCH(Setup!$B$8,A4:A17,0)),IF(MAX(R4:R17)<0,"",MAX(R4:R17)))
A5: =Capacity_Usage!B5 | B5: =Capacity_Usage!C5 | C5: =IF(Capacity_Usage!C5=Setup!$B$3,1,0) | D5: =IF(HC_Gate!J5="YES",1,0) | E5: =IF(OR(Capacity_Usage!V5="Standard",Capacity_Usage!B5=Setup!$B$8),1,0) | F5: =SUMIFS(Capacity_Usage!$U$4:$U$17,Capacity_Usage!$C$4:$C$17,Capacity_Usage!C5) | G5: =IFERROR(Capacity_Usage!N5/Capacity_Usage!F5,0) | H5: =MIN(MAX(G5,0),1) | I5: =IFERROR(Capacity_Usage!K5/Capacity_Usage!I5,0) | J5: =MIN(MAX(I5,0),1) | K5: =IF(F5=0,Policy!$B$11,1-Capacity_Usage!U5/F5) | L5: =MIN(MAX(K5,0),1) | M5: =IFERROR(Capacity_Usage!T5,0) | N5: =MIN(MAX(M5,0),1) | O5: =Capacity_Usage!E5/3 | P5: =MIN(MAX(O5,0),1) | Q5: =Policy!$B$2*H5+Policy!$B$3*J5+Policy!$B$4*L5+Policy!$B$5*N5+Policy!$B$6*P5 | R5: =IF(AND(C5=1,D5=1,E5=1),Q5,-1) | S5: =IF(R5<0,"",COUNTIF($R$4:$R$17,">"&R5)+1)
A6: =Capacity_Usage!B6 | B6: =Capacity_Usage!C6 | C6: =IF(Capacity_Usage!C6=Setup!$B$3,1,0) | D6: =IF(HC_Gate!J6="YES",1,0) | E6: =IF(OR(Capacity_Usage!V6="Standard",Capacity_Usage!B6=Setup!$B$8),1,0) | F6: =SUMIFS(Capacity_Usage!$U$4:$U$17,Capacity_Usage!$C$4:$C$17,Capacity_Usage!C6) | G6: =IFERROR(Capacity_Usage!N6/Capacity_Usage!F6,0) | H6: =MIN(MAX(G6,0),1) | I6: =IFERROR(Capacity_Usage!K6/Capacity_Usage!I6,0) | J6: =MIN(MAX(I6,0),1) | K6: =IF(F6=0,Policy!$B$11,1-Capacity_Usage!U6/F6) | L6: =MIN(MAX(K6,0),1) | M6: =IFERROR(Capacity_Usage!T6,0) | N6: =MIN(MAX(M6,0),1) | O6: =Capacity_Usage!E6/3 | P6: =MIN(MAX(O6,0),1) | Q6: =Policy!$B$2*H6+Policy!$B$3*J6+Policy!$B$4*L6+Policy!$B$5*N6+Policy!$B$6*P6 | R6: =IF(AND(C6=1,D6=1,E6=1),Q6,-1) | S6: =IF(R6<0,"",COUNTIF($R$4:$R$17,">"&R6)+1)
A7: =Capacity_Usage!B7 | B7: =Capacity_Usage!C7 | C7: =IF(Capacity_Usage!C7=Setup!$B$3,1,0) | D7: =IF(HC_Gate!J7="YES",1,0) | E7: =IF(OR(Capacity_Usage!V7="Standard",Capacity_Usage!B7=Setup!$B$8),1,0) | F7: =SUMIFS(Capacity_Usage!$U$4:$U$17,Capacity_Usage!$C$4:$C$17,Capacity_Usage!C7) | G7: =IFERROR(Capacity_Usage!N7/Capacity_Usage!F7,0) | H7: =MIN(MAX(G7,0),1) | I7: =IFERROR(Capacity_Usage!K7/Capacity_Usage!I7,0) | J7: =MIN(MAX(I7,0),1) | K7: =IF(F7=0,Policy!$B$11,1-Capacity_Usage!U7/F7) | L7: =MIN(MAX(K7,0),1) | M7: =IFERROR(Capacity_Usage!T7,0) | N7: =MIN(MAX(M7,0),1) | O7: =Capacity_Usage!E7/3 | P7: =MIN(MAX(O7,0),1) | Q7: =Policy!$B$2*H7+Policy!$B$3*J7+Policy!$B$4*L7+Policy!$B$5*N7+Policy!$B$6*P7 | R7: =IF(AND(C7=1,D7=1,E7=1),Q7,-1) | S7: =IF(R7<0,"",COUNTIF($R$4:$R$17,">"&R7)+1)
A8: =Capacity_Usage!B8 | B8: =Capacity_Usage!C8 | C8: =IF(Capacity_Usage!C8=Setup!$B$3,1,0) | D8: =IF(HC_Gate!J8="YES",1,0) | E8: =IF(OR(Capacity_Usage!V8="Standard",Capacity_Usage!B8=Setup!$B$8),1,0) | F8: =SUMIFS(Capacity_Usage!$U$4:$U$17,Capacity_Usage!$C$4:$C$17,Capacity_Usage!C8) | G8: =IFERROR(Capacity_Usage!N8/Capacity_Usage!F8,0) | H8: =MIN(MAX(G8,0),1) | I8: =IFERROR(Capacity_Usage!K8/Capacity_Usage!I8,0) | J8: =MIN(MAX(I8,0),1) | K8: =IF(F8=0,Policy!$B$11,1-Capacity_Usage!U8/F8) | L8: =MIN(MAX(K8,0),1) | M8: =IFERROR(Capacity_Usage!T8,0) | N8: =MIN(MAX(M8,0),1) | O8: =Capacity_Usage!E8/3 | P8: =MIN(MAX(O8,0),1) | Q8: =Policy!$B$2*H8+Policy!$B$3*J8+Policy!$B$4*L8+Policy!$B$5*N8+Policy!$B$6*P8 | R8: =IF(AND(C8=1,D8=1,E8=1),Q8,-1) | S8: =IF(R8<0,"",COUNTIF($R$4:$R$17,">"&R8)+1)
A9: =Capacity_Usage!B9 | B9: =Capacity_Usage!C9 | C9: =IF(Capacity_Usage!C9=Setup!$B$3,1,0) | D9: =IF(HC_Gate!J9="YES",1,0) | E9: =IF(OR(Capacity_Usage!V9="Standard",Capacity_Usage!B9=Setup!$B$8),1,0) | F9: =SUMIFS(Capacity_Usage!$U$4:$U$17,Capacity_Usage!$C$4:$C$17,Capacity_Usage!C9) | G9: =IFERROR(Capacity_Usage!N9/Capacity_Usage!F9,0) | H9: =MIN(MAX(G9,0),1) | I9: =IFERROR(Capacity_Usage!K9/Capacity_Usage!I9,0) | J9: =MIN(MAX(I9,0),1) | K9: =IF(F9=0,Policy!$B$11,1-Capacity_Usage!U9/F9) | L9: =MIN(MAX(K9,0),1) | M9: =IFERROR(Capacity_Usage!T9,0) | N9: =MIN(MAX(M9,0),1) | O9: =Capacity_Usage!E9/3 | P9: =MIN(MAX(O9,0),1) | Q9: =Policy!$B$2*H9+Policy!$B$3*J9+Policy!$B$4*L9+Policy!$B$5*N9+Policy!$B$6*P9 | R9: =IF(AND(C9=1,D9=1,E9=1),Q9,-1) | S9: =IF(R9<0,"",COUNTIF($R$4:$R$17,">"&R9)+1)
A10: =Capacity_Usage!B10 | B10: =Capacity_Usage!C10 | C10: =IF(Capacity_Usage!C10=Setup!$B$3,1,0) | D10: =IF(HC_Gate!J10="YES",1,0) | E10: =IF(OR(Capacity_Usage!V10="Standard",Capacity_Usage!B10=Setup!$B$8),1,0) | F10: =SUMIFS(Capacity_Usage!$U$4:$U$17,Capacity_Usage!$C$4:$C$17,Capacity_Usage!C10) | G10: =IFERROR(Capacity_Usage!N10/Capacity_Usage!F10,0) | H10: =MIN(MAX(G10,0),1) | I10: =IFERROR(Capacity_Usage!K10/Capacity_Usage!I10,0) | J10: =MIN(MAX(I10,0),1) | K10: =IF(F10=0,Policy!$B$11,1-Capacity_Usage!U10/F10) | L10: =MIN(MAX(K10,0),1) | M10: =IFERROR(Capacity_Usage!T10,0) | N10: =MIN(MAX(M10,0),1) | O10: =Capacity_Usage!E10/3 | P10: =MIN(MAX(O10,0),1) | Q10: =Policy!$B$2*H10+Policy!$B$3*J10+Policy!$B$4*L10+Policy!$B$5*N10+Policy!$B$6*P10 | R10: =IF(AND(C10=1,D10=1,E10=1),Q10,-1) | S10: =IF(R10<0,"",COUNTIF($R$4:$R$17,">"&R10)+1)
A11: =Capacity_Usage!B11 | B11: =Capacity_Usage!C11 | C11: =IF(Capacity_Usage!C11=Setup!$B$3,1,0) | D11: =IF(HC_Gate!J11="YES",1,0) | E11: =IF(OR(Capacity_Usage!V11="Standard",Capacity_Usage!B11=Setup!$B$8),1,0) | F11: =SUMIFS(Capacity_Usage!$U$4:$U$17,Capacity_Usage!$C$4:$C$17,Capacity_Usage!C11) | G11: =IFERROR(Capacity_Usage!N11/Capacity_Usage!F11,0) | H11: =MIN(MAX(G11,0),1) | I11: =IFERROR(Capacity_Usage!K11/Capacity_Usage!I11,0) | J11: =MIN(MAX(I11,0),1) | K11: =IF(F11=0,Policy!$B$11,1-Capacity_Usage!U11/F11) | L11: =MIN(MAX(K11,0),1) | M11: =IFERROR(Capacity_Usage!T11,0) | N11: =MIN(MAX(M11,0),1) | O11: =Capacity_Usage!E11/3 | P11: =MIN(MAX(O11,0),1) | Q11: =Policy!$B$2*H11+Policy!$B$3*J11+Policy!$B$4*L11+Policy!$B$5*N11+Policy!$B$6*P11 | R11: =IF(AND(C11=1,D11=1,E11=1),Q11,-1) | S11: =IF(R11<0,"",COUNTIF($R$4:$R$17,">"&R11)+1)
A12: =Capacity_Usage!B12 | B12: =Capacity_Usage!C12 | C12: =IF(Capacity_Usage!C12=Setup!$B$3,1,0) | D12: =IF(HC_Gate!J12="YES",1,0) | E12: =IF(OR(Capacity_Usage!V12="Standard",Capacity_Usage!B12=Setup!$B$8),1,0) | F12: =SUMIFS(Capacity_Usage!$U$4:$U$17,Capacity_Usage!$C$4:$C$17,Capacity_Usage!C12) | G12: =IFERROR(Capacity_Usage!N12/Capacity_Usage!F12,0) | H12: =MIN(MAX(G12,0),1) | I12: =IFERROR(Capacity_Usage!K12/Capacity_Usage!I12,0) | J12: =MIN(MAX(I12,0),1) | K12: =IF(F12=0,Policy!$B$11,1-Capacity_Usage!U12/F12) | L12: =MIN(MAX(K12,0),1) | M12: =IFERROR(Capacity_Usage!T12,0) | N12: =MIN(MAX(M12,0),1) | O12: =Capacity_Usage!E12/3 | P12: =MIN(MAX(O12,0),1) | Q12: =Policy!$B$2*H12+Policy!$B$3*J12+Policy!$B$4*L12+Policy!$B$5*N12+Policy!$B$6*P12 | R12: =IF(AND(C12=1,D12=1,E12=1),Q12,-1) | S12: =IF(R12<0,"",COUNTIF($R$4:$R$17,">"&R12)+1)
A13: =Capacity_Usage!B13 | B13: =Capacity_Usage!C13 | C13: =IF(Capacity_Usage!C13=Setup!$B$3,1,0) | D13: =IF(HC_Gate!J13="YES",1,0) | E13: =IF(OR(Capacity_Usage!V13="Standard",Capacity_Usage!B13=Setup!$B$8),1,0) | F13: =SUMIFS(Capacity_Usage!$U$4:$U$17,Capacity_Usage!$C$4:$C$17,Capacity_Usage!C13) | G13: =IFERROR(Capacity_Usage!N13/Capacity_Usage!F13,0) | H13: =MIN(MAX(G13,0),1) | I13: =IFERROR(Capacity_Usage!K13/Capacity_Usage!I13,0) | J13: =MIN(MAX(I13,0),1) | K13: =IF(F13=0,Policy!$B$11,1-Capacity_Usage!U13/F13) | L13: =MIN(MAX(K13,0),1) | M13: =IFERROR(Capacity_Usage!T13,0) | N13: =MIN(MAX(M13,0),1) | O13: =Capacity_Usage!E13/3 | P13: =MIN(MAX(O13,0),1) | Q13: =Policy!$B$2*H13+Policy!$B$3*J13+Policy!$B$4*L13+Policy!$B$5*N13+Policy!$B$6*P13 | R13: =IF(AND(C13=1,D13=1,E13=1),Q13,-1) | S13: =IF(R13<0,"",COUNTIF($R$4:$R$17,">"&R13)+1)
A14: =Capacity_Usage!B14 | B14: =Capacity_Usage!C14 | C14: =IF(Capacity_Usage!C14=Setup!$B$3,1,0) | D14: =IF(HC_Gate!J14="YES",1,0) | E14: =IF(OR(Capacity_Usage!V14="Standard",Capacity_Usage!B14=Setup!$B$8),1,0) | F14: =SUMIFS(Capacity_Usage!$U$4:$U$17,Capacity_Usage!$C$4:$C$17,Capacity_Usage!C14) | G14: =IFERROR(Capacity_Usage!N14/Capacity_Usage!F14,0) | H14: =MIN(MAX(G14,0),1) | I14: =IFERROR(Capacity_Usage!K14/Capacity_Usage!I14,0) | J14: =MIN(MAX(I14,0),1) | K14: =IF(F14=0,Policy!$B$11,1-Capacity_Usage!U14/F14) | L14: =MIN(MAX(K14,0),1) | M14: =IFERROR(Capacity_Usage!T14,0) | N14: =MIN(MAX(M14,0),1) | O14: =Capacity_Usage!E14/3 | P14: =MIN(MAX(O14,0),1) | Q14: =Policy!$B$2*H14+Policy!$B$3*J14+Policy!$B$4*L14+Policy!$B$5*N14+Policy!$B$6*P14 | R14: =IF(AND(C14=1,D14=1,E14=1),Q14,-1) | S14: =IF(R14<0,"",COUNTIF($R$4:$R$17,">"&R14)+1)
A15: =Capacity_Usage!B15 | B15: =Capacity_Usage!C15 | C15: =IF(Capacity_Usage!C15=Setup!$B$3,1,0) | D15: =IF(HC_Gate!J15="YES",1,0) | E15: =IF(OR(Capacity_Usage!V15="Standard",Capacity_Usage!B15=Setup!$B$8),1,0) | F15: =SUMIFS(Capacity_Usage!$U$4:$U$17,Capacity_Usage!$C$4:$C$17,Capacity_Usage!C15) | G15: =IFERROR(Capacity_Usage!N15/Capacity_Usage!F15,0) | H15: =MIN(MAX(G15,0),1) | I15: =IFERROR(Capacity_Usage!K15/Capacity_Usage!I15,0) | J15: =MIN(MAX(I15,0),1) | K15: =IF(F15=0,Policy!$B$11,1-Capacity_Usage!U15/F15) | L15: =MIN(MAX(K15,0),1) | M15: =IFERROR(Capacity_Usage!T15,0) | N15: =MIN(MAX(M15,0),1) | O15: =Capacity_Usage!E15/3 | P15: =MIN(MAX(O15,0),1) | Q15: =Policy!$B$2*H15+Policy!$B$3*J15+Policy!$B$4*L15+Policy!$B$5*N15+Policy!$B$6*P15 | R15: =IF(AND(C15=1,D15=1,E15=1),Q15,-1) | S15: =IF(R15<0,"",COUNTIF($R$4:$R$17,">"&R15)+1)
A16: =Capacity_Usage!B16 | B16: =Capacity_Usage!C16 | C16: =IF(Capacity_Usage!C16=Setup!$B$3,1,0) | D16: =IF(HC_Gate!J16="YES",1,0) | E16: =IF(OR(Capacity_Usage!V16="Standard",Capacity_Usage!B16=Setup!$B$8),1,0) | F16: =SUMIFS(Capacity_Usage!$U$4:$U$17,Capacity_Usage!$C$4:$C$17,Capacity_Usage!C16) | G16: =IFERROR(Capacity_Usage!N16/Capacity_Usage!F16,0) | H16: =MIN(MAX(G16,0),1) | I16: =IFERROR(Capacity_Usage!K16/Capacity_Usage!I16,0) | J16: =MIN(MAX(I16,0),1) | K16: =IF(F16=0,Policy!$B$11,1-Capacity_Usage!U16/F16) | L16: =MIN(MAX(K16,0),1) | M16: =IFERROR(Capacity_Usage!T16,0) | N16: =MIN(MAX(M16,0),1) | O16: =Capacity_Usage!E16/3 | P16: =MIN(MAX(O16,0),1) | Q16: =Policy!$B$2*H16+Policy!$B$3*J16+Policy!$B$4*L16+Policy!$B$5*N16+Policy!$B$6*P16 | R16: =IF(AND(C16=1,D16=1,E16=1),Q16,-1) | S16: =IF(R16<0,"",COUNTIF($R$4:$R$17,">"&R16)+1)
A17: =Capacity_Usage!B17 | B17: =Capacity_Usage!C17 | C17: =IF(Capacity_Usage!C17=Setup!$B$3,1,0) | D17: =IF(HC_Gate!J17="YES",1,0) | E17: =IF(OR(Capacity_Usage!V17="Standard",Capacity_Usage!B17=Setup!$B$8),1,0) | F17: =SUMIFS(Capacity_Usage!$U$4:$U$17,Capacity_Usage!$C$4:$C$17,Capacity_Usage!C17) | G17: =IFERROR(Capacity_Usage!N17/Capacity_Usage!F17,0) | H17: =MIN(MAX(G17,0),1) | I17: =IFERROR(Capacity_Usage!K17/Capacity_Usage!I17,0) | J17: =MIN(MAX(I17,0),1) | K17: =IF(F17=0,Policy!$B$11,1-Capacity_Usage!U17/F17) | L17: =MIN(MAX(K17,0),1) | M17: =IFERROR(Capacity_Usage!T17,0) | N17: =MIN(MAX(M17,0),1) | O17: =Capacity_Usage!E17/3 | P17: =MIN(MAX(O17,0),1) | Q17: =Policy!$B$2*H17+Policy!$B$3*J17+Policy!$B$4*L17+Policy!$B$5*N17+Policy!$B$6*P17 | R17: =IF(AND(C17=1,D17=1,E17=1),Q17,-1) | S17: =IF(R17<0,"",COUNTIF($R$4:$R$17,">"&R17)+1)

Sheet Scoring_CVAL
A1: PS_NonProd — CVAL Placement Score (δ duplicates α — known design gap) | T1: CVAL WINNER
T2: Region | U2: =IF(Setup!$B$3="Middle East",Scoring_Prod!$U$3,IF(MAX(R4:R17)<0,"NONE ELIGIBLE",INDEX(A4:A17,MATCH(MAX(R4:R17),R4:R17,0))))
A3: Region | B3: Geography | C3: InScope | D3: Eligible | E3: AutoSel | F3: total_cust | G3: α_raw | H3: α_c | I3: β_raw | J3: β_c | K3: γ_raw | L3: γ_c | M3: δ_raw | N3: δ_c | O3: ε_raw | P3: ε_c | Q3: PS | R3: Candidate | S3: Rank | T3: Score | U3: =IF(Setup!$B$3="Middle East",Scoring_Prod!$U$4,IF(MAX(R4:R17)<0,"",MAX(R4:R17)))
A4: =Capacity_Usage!B4 | B4: =Capacity_Usage!C4 | C4: =IF(Capacity_Usage!C4=Setup!$B$3,1,0) | D4: =IF(HC_Gate!K4="YES",1,0) | E4: =IF(OR(Capacity_Usage!V4="Standard",Capacity_Usage!B4=Setup!$B$8),1,0) | F4: =SUMIFS(Capacity_Usage!$U$4:$U$17,Capacity_Usage!$C$4:$C$17,Capacity_Usage!C4) | G4: =IFERROR(Capacity_Usage!N4/Capacity_Usage!L4,0) | H4: =MIN(MAX(G4,0),1) | I4: =IFERROR(Capacity_Usage!Q4/Capacity_Usage!O4,0) | J4: =MIN(MAX(I4,0),1) | K4: =IF(F4=0,Policy!$B$11,1-Capacity_Usage!U4/F4) | L4: =MIN(MAX(K4,0),1) | M4: =IFERROR(Capacity_Usage!N4/Capacity_Usage!L4,0) | N4: =MIN(MAX(M4,0),1) | O4: =Capacity_Usage!E4/3 | P4: =MIN(MAX(O4,0),1) | Q4: =Policy!$B$2*H4+Policy!$B$3*J4+Policy!$B$4*L4+Policy!$B$5*N4+Policy!$B$6*P4 | R4: =IF(AND(C4=1,D4=1,E4=1,A4<>Scoring_Prod!$U$3),Q4,-1) | S4: =IF(R4<0,"",COUNTIF($R$4:$R$17,">"&R4)+1)
A5: =Capacity_Usage!B5 | B5: =Capacity_Usage!C5 | C5: =IF(Capacity_Usage!C5=Setup!$B$3,1,0) | D5: =IF(HC_Gate!K5="YES",1,0) | E5: =IF(OR(Capacity_Usage!V5="Standard",Capacity_Usage!B5=Setup!$B$8),1,0) | F5: =SUMIFS(Capacity_Usage!$U$4:$U$17,Capacity_Usage!$C$4:$C$17,Capacity_Usage!C5) | G5: =IFERROR(Capacity_Usage!N5/Capacity_Usage!L5,0) | H5: =MIN(MAX(G5,0),1) | I5: =IFERROR(Capacity_Usage!Q5/Capacity_Usage!O5,0) | J5: =MIN(MAX(I5,0),1) | K5: =IF(F5=0,Policy!$B$11,1-Capacity_Usage!U5/F5) | L5: =MIN(MAX(K5,0),1) | M5: =IFERROR(Capacity_Usage!N5/Capacity_Usage!L5,0) | N5: =MIN(MAX(M5,0),1) | O5: =Capacity_Usage!E5/3 | P5: =MIN(MAX(O5,0),1) | Q5: =Policy!$B$2*H5+Policy!$B$3*J5+Policy!$B$4*L5+Policy!$B$5*N5+Policy!$B$6*P5 | R5: =IF(AND(C5=1,D5=1,E5=1,A5<>Scoring_Prod!$U$3),Q5,-1) | S5: =IF(R5<0,"",COUNTIF($R$4:$R$17,">"&R5)+1)
A6: =Capacity_Usage!B6 | B6: =Capacity_Usage!C6 | C6: =IF(Capacity_Usage!C6=Setup!$B$3,1,0) | D6: =IF(HC_Gate!K6="YES",1,0) | E6: =IF(OR(Capacity_Usage!V6="Standard",Capacity_Usage!B6=Setup!$B$8),1,0) | F6: =SUMIFS(Capacity_Usage!$U$4:$U$17,Capacity_Usage!$C$4:$C$17,Capacity_Usage!C6) | G6: =IFERROR(Capacity_Usage!N6/Capacity_Usage!L6,0) | H6: =MIN(MAX(G6,0),1) | I6: =IFERROR(Capacity_Usage!Q6/Capacity_Usage!O6,0) | J6: =MIN(MAX(I6,0),1) | K6: =IF(F6=0,Policy!$B$11,1-Capacity_Usage!U6/F6) | L6: =MIN(MAX(K6,0),1) | M6: =IFERROR(Capacity_Usage!N6/Capacity_Usage!L6,0) | N6: =MIN(MAX(M6,0),1) | O6: =Capacity_Usage!E6/3 | P6: =MIN(MAX(O6,0),1) | Q6: =Policy!$B$2*H6+Policy!$B$3*J6+Policy!$B$4*L6+Policy!$B$5*N6+Policy!$B$6*P6 | R6: =IF(AND(C6=1,D6=1,E6=1,A6<>Scoring_Prod!$U$3),Q6,-1) | S6: =IF(R6<0,"",COUNTIF($R$4:$R$17,">"&R6)+1)
A7: =Capacity_Usage!B7 | B7: =Capacity_Usage!C7 | C7: =IF(Capacity_Usage!C7=Setup!$B$3,1,0) | D7: =IF(HC_Gate!K7="YES",1,0) | E7: =IF(OR(Capacity_Usage!V7="Standard",Capacity_Usage!B7=Setup!$B$8),1,0) | F7: =SUMIFS(Capacity_Usage!$U$4:$U$17,Capacity_Usage!$C$4:$C$17,Capacity_Usage!C7) | G7: =IFERROR(Capacity_Usage!N7/Capacity_Usage!L7,0) | H7: =MIN(MAX(G7,0),1) | I7: =IFERROR(Capacity_Usage!Q7/Capacity_Usage!O7,0) | J7: =MIN(MAX(I7,0),1) | K7: =IF(F7=0,Policy!$B$11,1-Capacity_Usage!U7/F7) | L7: =MIN(MAX(K7,0),1) | M7: =IFERROR(Capacity_Usage!N7/Capacity_Usage!L7,0) | N7: =MIN(MAX(M7,0),1) | O7: =Capacity_Usage!E7/3 | P7: =MIN(MAX(O7,0),1) | Q7: =Policy!$B$2*H7+Policy!$B$3*J7+Policy!$B$4*L7+Policy!$B$5*N7+Policy!$B$6*P7 | R7: =IF(AND(C7=1,D7=1,E7=1,A7<>Scoring_Prod!$U$3),Q7,-1) | S7: =IF(R7<0,"",COUNTIF($R$4:$R$17,">"&R7)+1)
A8: =Capacity_Usage!B8 | B8: =Capacity_Usage!C8 | C8: =IF(Capacity_Usage!C8=Setup!$B$3,1,0) | D8: =IF(HC_Gate!K8="YES",1,0) | E8: =IF(OR(Capacity_Usage!V8="Standard",Capacity_Usage!B8=Setup!$B$8),1,0) | F8: =SUMIFS(Capacity_Usage!$U$4:$U$17,Capacity_Usage!$C$4:$C$17,Capacity_Usage!C8) | G8: =IFERROR(Capacity_Usage!N8/Capacity_Usage!L8,0) | H8: =MIN(MAX(G8,0),1) | I8: =IFERROR(Capacity_Usage!Q8/Capacity_Usage!O8,0) | J8: =MIN(MAX(I8,0),1) | K8: =IF(F8=0,Policy!$B$11,1-Capacity_Usage!U8/F8) | L8: =MIN(MAX(K8,0),1) | M8: =IFERROR(Capacity_Usage!N8/Capacity_Usage!L8,0) | N8: =MIN(MAX(M8,0),1) | O8: =Capacity_Usage!E8/3 | P8: =MIN(MAX(O8,0),1) | Q8: =Policy!$B$2*H8+Policy!$B$3*J8+Policy!$B$4*L8+Policy!$B$5*N8+Policy!$B$6*P8 | R8: =IF(AND(C8=1,D8=1,E8=1,A8<>Scoring_Prod!$U$3),Q8,-1) | S8: =IF(R8<0,"",COUNTIF($R$4:$R$17,">"&R8)+1)
A9: =Capacity_Usage!B9 | B9: =Capacity_Usage!C9 | C9: =IF(Capacity_Usage!C9=Setup!$B$3,1,0) | D9: =IF(HC_Gate!K9="YES",1,0) | E9: =IF(OR(Capacity_Usage!V9="Standard",Capacity_Usage!B9=Setup!$B$8),1,0) | F9: =SUMIFS(Capacity_Usage!$U$4:$U$17,Capacity_Usage!$C$4:$C$17,Capacity_Usage!C9) | G9: =IFERROR(Capacity_Usage!N9/Capacity_Usage!L9,0) | H9: =MIN(MAX(G9,0),1) | I9: =IFERROR(Capacity_Usage!Q9/Capacity_Usage!O9,0) | J9: =MIN(MAX(I9,0),1) | K9: =IF(F9=0,Policy!$B$11,1-Capacity_Usage!U9/F9) | L9: =MIN(MAX(K9,0),1) | M9: =IFERROR(Capacity_Usage!N9/Capacity_Usage!L9,0) | N9: =MIN(MAX(M9,0),1) | O9: =Capacity_Usage!E9/3 | P9: =MIN(MAX(O9,0),1) | Q9: =Policy!$B$2*H9+Policy!$B$3*J9+Policy!$B$4*L9+Policy!$B$5*N9+Policy!$B$6*P9 | R9: =IF(AND(C9=1,D9=1,E9=1,A9<>Scoring_Prod!$U$3),Q9,-1) | S9: =IF(R9<0,"",COUNTIF($R$4:$R$17,">"&R9)+1)
A10: =Capacity_Usage!B10 | B10: =Capacity_Usage!C10 | C10: =IF(Capacity_Usage!C10=Setup!$B$3,1,0) | D10: =IF(HC_Gate!K10="YES",1,0) | E10: =IF(OR(Capacity_Usage!V10="Standard",Capacity_Usage!B10=Setup!$B$8),1,0) | F10: =SUMIFS(Capacity_Usage!$U$4:$U$17,Capacity_Usage!$C$4:$C$17,Capacity_Usage!C10) | G10: =IFERROR(Capacity_Usage!N10/Capacity_Usage!L10,0) | H10: =MIN(MAX(G10,0),1) | I10: =IFERROR(Capacity_Usage!Q10/Capacity_Usage!O10,0) | J10: =MIN(MAX(I10,0),1) | K10: =IF(F10=0,Policy!$B$11,1-Capacity_Usage!U10/F10) | L10: =MIN(MAX(K10,0),1) | M10: =IFERROR(Capacity_Usage!N10/Capacity_Usage!L10,0) | N10: =MIN(MAX(M10,0),1) | O10: =Capacity_Usage!E10/3 | P10: =MIN(MAX(O10,0),1) | Q10: =Policy!$B$2*H10+Policy!$B$3*J10+Policy!$B$4*L10+Policy!$B$5*N10+Policy!$B$6*P10 | R10: =IF(AND(C10=1,D10=1,E10=1,A10<>Scoring_Prod!$U$3),Q10,-1) | S10: =IF(R10<0,"",COUNTIF($R$4:$R$17,">"&R10)+1)
A11: =Capacity_Usage!B11 | B11: =Capacity_Usage!C11 | C11: =IF(Capacity_Usage!C11=Setup!$B$3,1,0) | D11: =IF(HC_Gate!K11="YES",1,0) | E11: =IF(OR(Capacity_Usage!V11="Standard",Capacity_Usage!B11=Setup!$B$8),1,0) | F11: =SUMIFS(Capacity_Usage!$U$4:$U$17,Capacity_Usage!$C$4:$C$17,Capacity_Usage!C11) | G11: =IFERROR(Capacity_Usage!N11/Capacity_Usage!L11,0) | H11: =MIN(MAX(G11,0),1) | I11: =IFERROR(Capacity_Usage!Q11/Capacity_Usage!O11,0) | J11: =MIN(MAX(I11,0),1) | K11: =IF(F11=0,Policy!$B$11,1-Capacity_Usage!U11/F11) | L11: =MIN(MAX(K11,0),1) | M11: =IFERROR(Capacity_Usage!N11/Capacity_Usage!L11,0) | N11: =MIN(MAX(M11,0),1) | O11: =Capacity_Usage!E11/3 | P11: =MIN(MAX(O11,0),1) | Q11: =Policy!$B$2*H11+Policy!$B$3*J11+Policy!$B$4*L11+Policy!$B$5*N11+Policy!$B$6*P11 | R11: =IF(AND(C11=1,D11=1,E11=1,A11<>Scoring_Prod!$U$3),Q11,-1) | S11: =IF(R11<0,"",COUNTIF($R$4:$R$17,">"&R11)+1)
A12: =Capacity_Usage!B12 | B12: =Capacity_Usage!C12 | C12: =IF(Capacity_Usage!C12=Setup!$B$3,1,0) | D12: =IF(HC_Gate!K12="YES",1,0) | E12: =IF(OR(Capacity_Usage!V12="Standard",Capacity_Usage!B12=Setup!$B$8),1,0) | F12: =SUMIFS(Capacity_Usage!$U$4:$U$17,Capacity_Usage!$C$4:$C$17,Capacity_Usage!C12) | G12: =IFERROR(Capacity_Usage!N12/Capacity_Usage!L12,0) | H12: =MIN(MAX(G12,0),1) | I12: =IFERROR(Capacity_Usage!Q12/Capacity_Usage!O12,0) | J12: =MIN(MAX(I12,0),1) | K12: =IF(F12=0,Policy!$B$11,1-Capacity_Usage!U12/F12) | L12: =MIN(MAX(K12,0),1) | M12: =IFERROR(Capacity_Usage!N12/Capacity_Usage!L12,0) | N12: =MIN(MAX(M12,0),1) | O12: =Capacity_Usage!E12/3 | P12: =MIN(MAX(O12,0),1) | Q12: =Policy!$B$2*H12+Policy!$B$3*J12+Policy!$B$4*L12+Policy!$B$5*N12+Policy!$B$6*P12 | R12: =IF(AND(C12=1,D12=1,E12=1,A12<>Scoring_Prod!$U$3),Q12,-1) | S12: =IF(R12<0,"",COUNTIF($R$4:$R$17,">"&R12)+1)
A13: =Capacity_Usage!B13 | B13: =Capacity_Usage!C13 | C13: =IF(Capacity_Usage!C13=Setup!$B$3,1,0) | D13: =IF(HC_Gate!K13="YES",1,0) | E13: =IF(OR(Capacity_Usage!V13="Standard",Capacity_Usage!B13=Setup!$B$8),1,0) | F13: =SUMIFS(Capacity_Usage!$U$4:$U$17,Capacity_Usage!$C$4:$C$17,Capacity_Usage!C13) | G13: =IFERROR(Capacity_Usage!N13/Capacity_Usage!L13,0) | H13: =MIN(MAX(G13,0),1) | I13: =IFERROR(Capacity_Usage!Q13/Capacity_Usage!O13,0) | J13: =MIN(MAX(I13,0),1) | K13: =IF(F13=0,Policy!$B$11,1-Capacity_Usage!U13/F13) | L13: =MIN(MAX(K13,0),1) | M13: =IFERROR(Capacity_Usage!N13/Capacity_Usage!L13,0) | N13: =MIN(MAX(M13,0),1) | O13: =Capacity_Usage!E13/3 | P13: =MIN(MAX(O13,0),1) | Q13: =Policy!$B$2*H13+Policy!$B$3*J13+Policy!$B$4*L13+Policy!$B$5*N13+Policy!$B$6*P13 | R13: =IF(AND(C13=1,D13=1,E13=1,A13<>Scoring_Prod!$U$3),Q13,-1) | S13: =IF(R13<0,"",COUNTIF($R$4:$R$17,">"&R13)+1)
A14: =Capacity_Usage!B14 | B14: =Capacity_Usage!C14 | C14: =IF(Capacity_Usage!C14=Setup!$B$3,1,0) | D14: =IF(HC_Gate!K14="YES",1,0) | E14: =IF(OR(Capacity_Usage!V14="Standard",Capacity_Usage!B14=Setup!$B$8),1,0) | F14: =SUMIFS(Capacity_Usage!$U$4:$U$17,Capacity_Usage!$C$4:$C$17,Capacity_Usage!C14) | G14: =IFERROR(Capacity_Usage!N14/Capacity_Usage!L14,0) | H14: =MIN(MAX(G14,0),1) | I14: =IFERROR(Capacity_Usage!Q14/Capacity_Usage!O14,0) | J14: =MIN(MAX(I14,0),1) | K14: =IF(F14=0,Policy!$B$11,1-Capacity_Usage!U14/F14) | L14: =MIN(MAX(K14,0),1) | M14: =IFERROR(Capacity_Usage!N14/Capacity_Usage!L14,0) | N14: =MIN(MAX(M14,0),1) | O14: =Capacity_Usage!E14/3 | P14: =MIN(MAX(O14,0),1) | Q14: =Policy!$B$2*H14+Policy!$B$3*J14+Policy!$B$4*L14+Policy!$B$5*N14+Policy!$B$6*P14 | R14: =IF(AND(C14=1,D14=1,E14=1,A14<>Scoring_Prod!$U$3),Q14,-1) | S14: =IF(R14<0,"",COUNTIF($R$4:$R$17,">"&R14)+1)
A15: =Capacity_Usage!B15 | B15: =Capacity_Usage!C15 | C15: =IF(Capacity_Usage!C15=Setup!$B$3,1,0) | D15: =IF(HC_Gate!K15="YES",1,0) | E15: =IF(OR(Capacity_Usage!V15="Standard",Capacity_Usage!B15=Setup!$B$8),1,0) | F15: =SUMIFS(Capacity_Usage!$U$4:$U$17,Capacity_Usage!$C$4:$C$17,Capacity_Usage!C15) | G15: =IFERROR(Capacity_Usage!N15/Capacity_Usage!L15,0) | H15: =MIN(MAX(G15,0),1) | I15: =IFERROR(Capacity_Usage!Q15/Capacity_Usage!O15,0) | J15: =MIN(MAX(I15,0),1) | K15: =IF(F15=0,Policy!$B$11,1-Capacity_Usage!U15/F15) | L15: =MIN(MAX(K15,0),1) | M15: =IFERROR(Capacity_Usage!N15/Capacity_Usage!L15,0) | N15: =MIN(MAX(M15,0),1) | O15: =Capacity_Usage!E15/3 | P15: =MIN(MAX(O15,0),1) | Q15: =Policy!$B$2*H15+Policy!$B$3*J15+Policy!$B$4*L15+Policy!$B$5*N15+Policy!$B$6*P15 | R15: =IF(AND(C15=1,D15=1,E15=1,A15<>Scoring_Prod!$U$3),Q15,-1) | S15: =IF(R15<0,"",COUNTIF($R$4:$R$17,">"&R15)+1)
... A17: =Capacity_Usage!B17 | B17: =Capacity_Usage!C17 | C17: =IF(Capacity_Usage!C17=Setup!$B$3,1,0) | D17: =IF(HC_Gate!K17="YES",1,0) | E17: =IF(OR(Capacity_Usage!V17="Standard",Capacity_Usage!B17=Setup!$B$8),1,0) | F17: =SUMIFS(Capacity_Usage!$U$4:$U$17,Capacity_Usage!$C$4:$C$17,Capacity_Usage!C17) | G17: =IFERROR(Capacity_Usage!N17/Capacity_Usage!L17,0) | H17: =MIN(MAX(G17,0),1) | I17: =IFERROR(Capacity_Usage!Q17/Capacity_Usage!O17,0) | J17: =MIN(MAX(I17,0),1) | K17: =IF(F17=0,Policy!$B$11,1-Capacity_Usage!U17/F17) | L17: =MIN(MAX(K17,0),1) | M17: =IFERROR(Capacity_Usage!N17/Capacity_Usage!L17,0) | N17: =MIN(MAX(M17,0),1) | O17: =Capacity_Usage!E17/3 | P17: =MIN(MAX(O17,0),1) | Q17: =Policy!$B$2*H17+Policy!$B$3*J17+Policy!$B$4*L17+Policy!$B$5*N17+Policy!$B$6*P17 | R17: =IF(AND(C17=1,D17=1,E17=1,A17<>Scoring_Prod!$U$3),Q17,-1) | S17: =IF(R17<0,"",COUNTIF($R$4:$R$17,">"&R17)+1)

Sheet Scoring_DR
A1: PS_DR — DR Placement Score (Middle East scores EU regions cross-geo) | T1: DR WINNER
T2: Region | U2: =IF(Setup!$B$10="2-region",Scoring_CVAL!$U$2,IF(MAX(R4:R17)<0,"NONE ELIGIBLE",INDEX(A4:A17,MATCH(MAX(R4:R17),R4:R17,0))))
A3: Region | B3: Geography | C3: InScope | D3: Eligible | E3: AutoSel | F3: total_cust | G3: α_raw | H3: α_c | I3: β_raw | J3: β_c | K3: γ_raw | L3: γ_c | M3: δ_raw | N3: δ_c | O3: ε_raw | P3: ε_c | Q3: PS | R3: Candidate | S3: Rank | T3: Score | U3: =IF(Setup!$B$10="2-region",Scoring_CVAL!$U$3,IF(MAX(R4:R17)<0,"",MAX(R4:R17)))
A4: =Capacity_Usage!B4 | B4: =Capacity_Usage!C4 | C4: =IF(Capacity_Usage!C4=Setup!$B$11,1,0) | D4: =IF(HC_Gate!L4="YES",1,0) | E4: =IF(OR(Capacity_Usage!V4="Standard",Capacity_Usage!B4=Setup!$B$8),1,0) | F4: =SUMIFS(Capacity_Usage!$U$4:$U$17,Capacity_Usage!$C$4:$C$17,Capacity_Usage!C4) | G4: =IFERROR(Capacity_Usage!S4/Capacity_Usage!R4,0) | H4: =MIN(MAX(G4,0),1) | I4: =IFERROR(Capacity_Usage!Q4/Capacity_Usage!O4,0) | J4: =MIN(MAX(I4,0),1) | K4: =IF(F4=0,Policy!$B$11,1-Capacity_Usage!U4/F4) | L4: =MIN(MAX(K4,0),1) | M4: =IFERROR(Capacity_Usage!T4/Policy!$B$14,0) | N4: =MIN(MAX(M4,0),1) | O4: =Capacity_Usage!E4/3 | P4: =MIN(MAX(O4,0),1) | Q4: =Policy!$B$2*H4+Policy!$B$3*J4+Policy!$B$4*L4+Policy!$B$5*N4+Policy!$B$6*P4 | R4: =IF(AND(C4=1,D4=1,E4=1,A4<>Scoring_Prod!$U$3),Q4,-1) | S4: =IF(R4<0,"",COUNTIF($R$4:$R$17,">"&R4)+1)
A5: =Capacity_Usage!B5 | B5: =Capacity_Usage!C5 | C5: =IF(Capacity_Usage!C5=Setup!$B$11,1,0) | D5: =IF(HC_Gate!L5="YES",1,0) | E5: =IF(OR(Capacity_Usage!V5="Standard",Capacity_Usage!B5=Setup!$B$8),1,0) | F5: =SUMIFS(Capacity_Usage!$U$4:$U$17,Capacity_Usage!$C$4:$C$17,Capacity_Usage!C5) | G5: =IFERROR(Capacity_Usage!S5/Capacity_Usage!R5,0) | H5: =MIN(MAX(G5,0),1) | I5: =IFERROR(Capacity_Usage!Q5/Capacity_Usage!O5,0) | J5: =MIN(MAX(I5,0),1) | K5: =IF(F5=0,Policy!$B$11,1-Capacity_Usage!U5/F5) | L5: =MIN(MAX(K5,0),1) | M5: =IFERROR(Capacity_Usage!T5/Policy!$B$14,0) | N5: =MIN(MAX(M5,0),1) | O5: =Capacity_Usage!E5/3 | P5: =MIN(MAX(O5,0),1) | Q5: =Policy!$B$2*H5+Policy!$B$3*J5+Policy!$B$4*L5+Policy!$B$5*N5+Policy!$B$6*P5 | R5: =IF(AND(C5=1,D5=1,E5=1,A5<>Scoring_Prod!$U$3),Q5,-1) | S5: =IF(R5<0,"",COUNTIF($R$4:$R$17,">"&R5)+1)
A6: =Capacity_Usage!B6 | B6: =Capacity_Usage!C6 | C6: =IF(Capacity_Usage!C6=Setup!$B$11,1,0) | D6: =IF(HC_Gate!L6="YES",1,0) | E6: =IF(OR(Capacity_Usage!V6="Standard",Capacity_Usage!B6=Setup!$B$8),1,0) | F6: =SUMIFS(Capacity_Usage!$U$4:$U$17,Capacity_Usage!$C$4:$C$17,Capacity_Usage!C6) | G6: =IFERROR(Capacity_Usage!S6/Capacity_Usage!R6,0) | H6: =MIN(MAX(G6,0),1) | I6: =IFERROR(Capacity_Usage!Q6/Capacity_Usage!O6,0) | J6: =MIN(MAX(I6,0),1) | K6: =IF(F6=0,Policy!$B$11,1-Capacity_Usage!U6/F6) | L6: =MIN(MAX(K6,0),1) | M6: =IFERROR(Capacity_Usage!T6/Policy!$B$14,0) | N6: =MIN(MAX(M6,0),1) | O6: =Capacity_Usage!E6/3 | P6: =MIN(MAX(O6,0),1) | Q6: =Policy!$B$2*H6+Policy!$B$3*J6+Policy!$B$4*L6+Policy!$B$5*N6+Policy!$B$6*P6 | R6: =IF(AND(C6=1,D6=1,E6=1,A6<>Scoring_Prod!$U$3),Q6,-1) | S6: =IF(R6<0,"",COUNTIF($R$4:$R$17,">"&R6)+1)
A7: =Capacity_Usage!B7 | B7: =Capacity_Usage!C7 | C7: =IF(Capacity_Usage!C7=Setup!$B$11,1,0) | D7: =IF(HC_Gate!L7="YES",1,0) | E7: =IF(OR(Capacity_Usage!V7="Standard",Capacity_Usage!B7=Setup!$B$8),1,0) | F7: =SUMIFS(Capacity_Usage!$U$4:$U$17,Capacity_Usage!$C$4:$C$17,Capacity_Usage!C7) | G7: =IFERROR(Capacity_Usage!S7/Capacity_Usage!R7,0) | H7: =MIN(MAX(G7,0),1) | I7: =IFERROR(Capacity_Usage!Q7/Capacity_Usage!O7,0) | J7: =MIN(MAX(I7,0),1) | K7: =IF(F7=0,Policy!$B$11,1-Capacity_Usage!U7/F7) | L7: =MIN(MAX(K7,0),1) | M7: =IFERROR(Capacity_Usage!T7/Policy!$B$14,0) | N7: =MIN(MAX(M7,0),1) | O7: =Capacity_Usage!E7/3 | P7: =MIN(MAX(O7,0),1) | Q7: =Policy!$B$2*H7+Policy!$B$3*J7+Policy!$B$4*L7+Policy!$B$5*N7+Policy!$B$6*P7 | R7: =IF(AND(C7=1,D7=1,E7=1,A7<>Scoring_Prod!$U$3),Q7,-1) | S7: =IF(R7<0,"",COUNTIF($R$4:$R$17,">"&R7)+1)
A8: =Capacity_Usage!B8 | B8: =Capacity_Usage!C8 | C8: =IF(Capacity_Usage!C8=Setup!$B$11,1,0) | D8: =IF(HC_Gate!L8="YES",1,0) | E8: =IF(OR(Capacity_Usage!V8="Standard",Capacity_Usage!B8=Setup!$B$8),1,0) | F8: =SUMIFS(Capacity_Usage!$U$4:$U$17,Capacity_Usage!$C$4:$C$17,Capacity_Usage!C8) | G8: =IFERROR(Capacity_Usage!S8/Capacity_Usage!R8,0) | H8: =MIN(MAX(G8,0),1) | I8: =IFERROR(Capacity_Usage!Q8/Capacity_Usage!O8,0) | J8: =MIN(MAX(I8,0),1) | K8: =IF(F8=0,Policy!$B$11,1-Capacity_Usage!U8/F8) | L8: =MIN(MAX(K8,0),1) | M8: =IFERROR(Capacity_Usage!T8/Policy!$B$14,0) | N8: =MIN(MAX(M8,0),1) | O8: =Capacity_Usage!E8/3 | P8: =MIN(MAX(O8,0),1) | Q8: =Policy!$B$2*H8+Policy!$B$3*J8+Policy!$B$4*L8+Policy!$B$5*N8+Policy!$B$6*P8 | R8: =IF(AND(C8=1,D8=1,E8=1,A8<>Scoring_Prod!$U$3),Q8,-1) | S8: =IF(R8<0,"",COUNTIF($R$4:$R$17,">"&R8)+1)
A9: =Capacity_Usage!B9 | B9: =Capacity_Usage!C9 | C9: =IF(Capacity_Usage!C9=Setup!$B$11,1,0) | D9: =IF(HC_Gate!L9="YES",1,0) | E9: =IF(OR(Capacity_Usage!V9="Standard",Capacity_Usage!B9=Setup!$B$8),1,0) | F9: =SUMIFS(Capacity_Usage!$U$4:$U$17,Capacity_Usage!$C$4:$C$17,Capacity_Usage!C9) | G9: =IFERROR(Capacity_Usage!S9/Capacity_Usage!R9,0) | H9: =MIN(MAX(G9,0),1) | I9: =IFERROR(Capacity_Usage!Q9/Capacity_Usage!O9,0) | J9: =MIN(MAX(I9,0),1) | K9: =IF(F9=0,Policy!$B$11,1-Capacity_Usage!U9/F9) | L9: =MIN(MAX(K9,0),1) | M9: =IFERROR(Capacity_Usage!T9/Policy!$B$14,0) | N9: =MIN(MAX(M9,0),1) | O9: =Capacity_Usage!E9/3 | P9: =MIN(MAX(O9,0),1) | Q9: =Policy!$B$2*H9+Policy!$B$3*J9+Policy!$B$4*L9+Policy!$B$5*N9+Policy!$B$6*P9 | R9: =IF(AND(C9=1,D9=1,E9=1,A9<>Scoring_Prod!$U$3),Q9,-1) | S9: =IF(R9<0,"",COUNTIF($R$4:$R$17,">"&R9)+1)
A10: =Capacity_Usage!B10 | B10: =Capacity_Usage!C10 | C10: =IF(Capacity_Usage!C10=Setup!$B$11,1,0) | D10: =IF(HC_Gate!L10="YES",1,0) | E10: =IF(OR(Capacity_Usage!V10="Standard",Capacity_Usage!B10=Setup!$B$8),1,0) | F10: =SUMIFS(Capacity_Usage!$U$4:$U$17,Capacity_Usage!$C$4:$C$17,Capacity_Usage!C10) | G10: =IFERROR(Capacity_Usage!S10/Capacity_Usage!R10,0) | H10: =MIN(MAX(G10,0),1) | I10: =IFERROR(Capacity_Usage!Q10/Capacity_Usage!O10,0) | J10: =MIN(MAX(I10,0),1) | K10: =IF(F10=0,Policy!$B$11,1-Capacity_Usage!U10/F10) | L10: =MIN(MAX(K10,0),1) | M10: =IFERROR(Capacity_Usage!T10/Policy!$B$14,0) | N10: =MIN(MAX(M10,0),1) | O10: =Capacity_Usage!E10/3 | P10: =MIN(MAX(O10,0),1) | Q10: =Policy!$B$2*H10+Policy!$B$3*J10+Policy!$B$4*L10+Policy!$B$5*N10+Policy!$B$6*P10 | R10: =IF(AND(C10=1,D10=1,E10=1,A10<>Scoring_Prod!$U$3),Q10,-1) | S10: =IF(R10<0,"",COUNTIF($R$4:$R$17,">"&R10)+1)
A11: =Capacity_Usage!B11 | B11: =Capacity_Usage!C11 | C11: =IF(Capacity_Usage!C11=Setup!$B$11,1,0) | D11: =IF(HC_Gate!L11="YES",1,0) | E11: =IF(OR(Capacity_Usage!V11="Standard",Capacity_Usage!B11=Setup!$B$8),1,0) | F11: =SUMIFS(Capacity_Usage!$U$4:$U$17,Capacity_Usage!$C$4:$C$17,Capacity_Usage!C11) | G11: =IFERROR(Capacity_Usage!S11/Capacity_Usage!R11,0) | H11: =MIN(MAX(G11,0),1) | I11: =IFERROR(Capacity_Usage!Q11/Capacity_Usage!O11,0) | J11: =MIN(MAX(I11,0),1) | K11: =IF(F11=0,Policy!$B$11,1-Capacity_Usage!U11/F11) | L11: =MIN(MAX(K11,0),1) | M11: =IFERROR(Capacity_Usage!T11/Policy!$B$14,0) | N11: =MIN(MAX(M11,0),1) | O11: =Capacity_Usage!E11/3 | P11: =MIN(MAX(O11,0),1) | Q11: =Policy!$B$2*H11+Policy!$B$3*J11+Policy!$B$4*L11+Policy!$B$5*N11+Policy!$B$6*P11 | R11: =IF(AND(C11=1,D11=1,E11=1,A11<>Scoring_Prod!$U$3),Q11,-1) | S11: =IF(R11<0,"",COUNTIF($R$4:$R$17,">"&R11)+1)
A12: =Capacity_Usage!B12 | B12: =Capacity_Usage!C12 | C12: =IF(Capacity_Usage!C12=Setup!$B$11,1,0) | D12: =IF(HC_Gate!L12="YES",1,0) | E12: =IF(OR(Capacity_Usage!V12="Standard",Capacity_Usage!B12=Setup!$B$8),1,0) | F12: =SUMIFS(Capacity_Usage!$U$4:$U$17,Capacity_Usage!$C$4:$C$17,Capacity_Usage!C12) | G12: =IFERROR(Capacity_Usage!S12/Capacity_Usage!R12,0) | H12: =MIN(MAX(G12,0),1) | I12: =IFERROR(Capacity_Usage!Q12/Capacity_Usage!O12,0) | J12: =MIN(MAX(I12,0),1) | K12: =IF(F12=0,Policy!$B$11,1-Capacity_Usage!U12/F12) | L12: =MIN(MAX(K12,0),1) | M12: =IFERROR(Capacity_Usage!T12/Policy!$B$14,0) | N12: =MIN(MAX(M12,0),1) | O12: =Capacity_Usage!E12/3 | P12: =MIN(MAX(O12,0),1) | Q12: =Policy!$B$2*H12+Policy!$B$3*J12+Policy!$B$4*L12+Policy!$B$5*N12+Policy!$B$6*P12 | R12: =IF(AND(C12=1,D12=1,E12=1,A12<>Scoring_Prod!$U$3),Q12,-1) | S12: =IF(R12<0,"",COUNTIF($R$4:$R$17,">"&R12)+1)
A13: =Capacity_Usage!B13 | B13: =Capacity_Usage!C13 | C13: =IF(Capacity_Usage!C13=Setup!$B$11,1,0) | D13: =IF(HC_Gate!L13="YES",1,0) | E13: =IF(OR(Capacity_Usage!V13="Standard",Capacity_Usage!B13=Setup!$B$8),1,0) | F13: =SUMIFS(Capacity_Usage!$U$4:$U$17,Capacity_Usage!$C$4:$C$17,Capacity_Usage!C13) | G13: =IFERROR(Capacity_Usage!S13/Capacity_Usage!R13,0) | H13: =MIN(MAX(G13,0),1) | I13: =IFERROR(Capacity_Usage!Q13/Capacity_Usage!O13,0) | J13: =MIN(MAX(I13,0),1) | K13: =IF(F13=0,Policy!$B$11,1-Capacity_Usage!U13/F13) | L13: =MIN(MAX(K13,0),1) | M13: =IFERROR(Capacity_Usage!T13/Policy!$B$14,0) | N13: =MIN(MAX(M13,0),1) | O13: =Capacity_Usage!E13/3 | P13: =MIN(MAX(O13,0),1) | Q13: =Policy!$B$2*H13+Policy!$B$3*J13+Policy!$B$4*L13+Policy!$B$5*N13+Policy!$B$6*P13 | R13: =IF(AND(C13=1,D13=1,E13=1,A13<>Scoring_Prod!$U$3),Q13,-1) | S13: =IF(R13<0,"",COUNTIF($R$4:$R$17,">"&R13)+1)
A14: =Capacity_Usage!B14 | B14: =Capacity_Usage!C14 | C14: =IF(Capacity_Usage!C14=Setup!$B$11,1,0) | D14: =IF(HC_Gate!L14="YES",1,0) | E14: =IF(OR(Capacity_Usage!V14="Standard",Capacity_Usage!B14=Setup!$B$8),1,0) | F14: =SUMIFS(Capacity_Usage!$U$4:$U$17,Capacity_Usage!$C$4:$C$17,Capacity_Usage!C14) | G14: =IFERROR(Capacity_Usage!S14/Capacity_Usage!R14,0) | H14: =MIN(MAX(G14,0),1) | I14: =IFERROR(Capacity_Usage!Q14/Capacity_Usage!O14,0) | J14: =MIN(MAX(I14,0),1) | K14: =IF(F14=0,Policy!$B$11,1-Capacity_Usage!U14/F14) | L14: =MIN(MAX(K14,0),1) | M14: =IFERROR(Capacity_Usage!T14/Policy!$B$14,0) | N14: =MIN(MAX(M14,0),1) | O14: =Capacity_Usage!E14/3 | P14: =MIN(MAX(O14,0),1) | Q14: =Policy!$B$2*H14+Policy!$B$3*J14+Policy!$B$4*L14+Policy!$B$5*N14+Policy!$B$6*P14 | R14: =IF(AND(C14=1,D14=1,E14=1,A14<>Scoring_Prod!$U$3),Q14,-1) | S14: =IF(R14<0,"",COUNTIF($R$4:$R$17,">"&R14)+1)
A15: =Capacity_Usage!B15 | B15: =Capacity_Usage!C15 | C15: =IF(Capacity_Usage!C15=Setup!$B$11,1,0) | D15: =IF(HC_Gate!L15="YES",1,0) | E15: =IF(OR(Capacity_Usage!V15="Standard",Capacity_Usage!B15=Setup!$B$8),1,0) | F15: =SUMIFS(Capacity_Usage!$U$4:$U$17,Capacity_Usage!$C$4:$C$17,Capacity_Usage!C15) | G15: =IFERROR(Capacity_Usage!S15/Capacity_Usage!R15,0) | H15: =MIN(MAX(G15,0),1) | I15: =IFERROR(Capacity_Usage!Q15/Capacity_Usage!O15,0) | J15: =MIN(MAX(I15,0),1) | K15: =IF(F15=0,Policy!$B$11,1-Capacity_Usage!U15/F15) | L15: =MIN(MAX(K15,0),1) | M15: =IFERROR(Capacity_Usage!T15/Policy!$B$14,0) | N15: =MIN(MAX(M15,0),1) | O15: =Capacity_Usage!E15/3 | P15: =MIN(MAX(O15,0),1) | Q15: =Policy!$B$2*H15+Policy!$B$3*J15+Policy!$B$4*L15+Policy!$B$5*N15+Policy!$B$6*P15 | R15: =IF(AND(C15=1,D15=1,E15=1,A15<>Scoring_Prod!$U$3),Q15,-1) | S15: =IF(R15<0,"",COUNTIF($R$4:$R$17,">"&R15)+1)
... A17: =Capacity_Usage!B17 | B17: =Capacity_Usage!C17 | C17: =IF(Capacity_Usage!C17=Setup!$B$11,1,0) | D17: =IF(HC_Gate!L17="YES",1,0) | E17: =IF(OR(Capacity_Usage!V17="Standard",Capacity_Usage!B17=Setup!$B$8),1,0) | F17: =SUMIFS(Capacity_Usage!$U$4:$U$17,Capacity_Usage!$C$4:$C$17,Capacity_Usage!C17) | G17: =IFERROR(Capacity_Usage!S17/Capacity_Usage!R17,0) | H17: =MIN(MAX(G17,0),1) | I17: =IFERROR(Capacity_Usage!Q17/Capacity_Usage!O17,0) | J17: =MIN(MAX(I17,0),1) | K17: =IF(F17=0,Policy!$B$11,1-Capacity_Usage!U17/F17) | L17: =MIN(MAX(K17,0),1) | M17: =IFERROR(Capacity_Usage!T17/Policy!$B$14,0) | N17: =MIN(MAX(M17,0),1) | O17: =Capacity_Usage!E17/3 | P17: =MIN(MAX(O17,0),1) | Q17: =Policy!$B$2*H17+Policy!$B$3*J17+Policy!$B$4*L17+Policy!$B$5*N17+Policy!$B$6*P17 | R17: =IF(AND(C17=1,D17=1,E17=1,A17<>Scoring_Prod!$U$3),Q17,-1) | S17: =IF(R17<0,"",COUNTIF($R$4:$R$17,">"&R17)+1)

Sheet Result
A1: RESULT — Region Selection (What-If, ACRME catalogue)
A3: Customer ID | B3: =Setup!B9 | E3: DR SIZING (max-not-sum, A.6 / DR-017) | H3: RANKED CANDIDATE REGIONS (Rank 1 = highest PS; blank = not a candidate for this mode)
A4: Geography | B4: =Setup!B3 | H4: Prod | K4: CVAL | N4: DR
A5: SKU | B5: =Setup!B4 | E5: DR region | F5: =B11 | H5: Rank | I5: Region | J5: PS | K5: Rank | L5: Region | M5: PS | N5: Rank | O5: Region | P5: PS
A6: Requested vCPU | B6: =Setup!B7 | E6: Max source customers | F6: =SUMPRODUCT(MAX((Capacity_Usage!$C$4:$C$17=Setup!$B$11)*Capacity_Usage!$U$4:$U$17)) | H6: =IFERROR(IF(INDEX(Scoring_Prod!$S$4:$S$17,MATCH(1,Scoring_Prod!$S$4:$S$17,0))="","",1),"") | I6: =IFERROR(INDEX(Scoring_Prod!$A$4:$A$17,MATCH(1,Scoring_Prod!$S$4:$S$17,0)),"") | J6: =IFERROR(INDEX(Scoring_Prod!$Q$4:$Q$17,MATCH(1,Scoring_Prod!$S$4:$S$17,0)),"") | K6: =IFERROR(IF(INDEX(Scoring_CVAL!$S$4:$S$17,MATCH(1,Scoring_CVAL!$S$4:$S$17,0))="","",1),"") | L6: =IFERROR(INDEX(Scoring_CVAL!$A$4:$A$17,MATCH(1,Scoring_CVAL!$S$4:$S$17,0)),"") | M6: =IFERROR(INDEX(Scoring_CVAL!$Q$4:$Q$17,MATCH(1,Scoring_CVAL!$S$4:$S$17,0)),"") | N6: =IFERROR(IF(INDEX(Scoring_DR!$S$4:$S$17,MATCH(1,Scoring_DR!$S$4:$S$17,0))="","",1),"") | O6: =IFERROR(INDEX(Scoring_DR!$A$4:$A$17,MATCH(1,Scoring_DR!$S$4:$S$17,0)),"") | P6: =IFERROR(INDEX(Scoring_DR!$Q$4:$Q$17,MATCH(1,Scoring_DR!$S$4:$S$17,0)),"")
E7: × Requested vCPU | F7: =Setup!B7 | H7: =IFERROR(IF(INDEX(Scoring_Prod!$S$4:$S$17,MATCH(2,Scoring_Prod!$S$4:$S$17,0))="","",2),"") | I7: =IFERROR(INDEX(Scoring_Prod!$A$4:$A$17,MATCH(2,Scoring_Prod!$S$4:$S$17,0)),"") | J7: =IFERROR(INDEX(Scoring_Prod!$Q$4:$Q$17,MATCH(2,Scoring_Prod!$S$4:$S$17,0)),"") | K7: =IFERROR(IF(INDEX(Scoring_CVAL!$S$4:$S$17,MATCH(2,Scoring_CVAL!$S$4:$S$17,0))="","",2),"") | L7: =IFERROR(INDEX(Scoring_CVAL!$A$4:$A$17,MATCH(2,Scoring_CVAL!$S$4:$S$17,0)),"") | M7: =IFERROR(INDEX(Scoring_CVAL!$Q$4:$Q$17,MATCH(2,Scoring_CVAL!$S$4:$S$17,0)),"") | N7: =IFERROR(IF(INDEX(Scoring_DR!$S$4:$S$17,MATCH(2,Scoring_DR!$S$4:$S$17,0))="","",2),"") | O7: =IFERROR(INDEX(Scoring_DR!$A$4:$A$17,MATCH(2,Scoring_DR!$S$4:$S$17,0)),"") | P7: =IFERROR(INDEX(Scoring_DR!$Q$4:$Q$17,MATCH(2,Scoring_DR!$S$4:$S$17,0)),"")
